<sdf version='1.4'>
  <world name='default'>
    <light name='sun' type='directional'>
      <cast_shadows>1</cast_shadows>
      <pose>0 0 10 0 -0 0</pose>
      <diffuse>0.8 0.8 0.8 1</diffuse>
      <specular>0.2 0.2 0.2 1</specular>
      <attenuation>
        <range>1000</range>
        <constant>0.9</constant>
        <linear>0.01</linear>
        <quadratic>0.001</quadratic>
      </attenuation>
      <direction>-0.5 0.1 -0.9</direction>
    </light>
    <model name='ground_plane'>
      <static>1</static>
      <link name='link'>
        <collision name='collision'>
          <geometry>
            <plane>
              <normal>0 0 1</normal>
              <size>100 100</size>
            </plane>
          </geometry>
          <surface>
            <friction>
              <ode>
                <mu>100</mu>
                <mu2>50</mu2>
              </ode>
            </friction>
            <bounce/>
            <contact>
              <ode/>
            </contact>
          </surface>
          <max_contacts>10</max_contacts>
        </collision>
        <visual name='visual'>
          <cast_shadows>0</cast_shadows>
          <geometry>
            <plane>
              <normal>0 0 1</normal>
              <size>100 100</size>
            </plane>
          </geometry>
          <material>
            <script>
              <uri>file://media/materials/scripts/gazebo.material</uri>
              <name>Gazebo/Grey</name>
            </script>
          </material>
        </visual>
        <velocity_decay>
          <linear>0</linear>
          <angular>0</angular>
        </velocity_decay>
        <self_collide>0</self_collide>
        <kinematic>0</kinematic>
        <gravity>1</gravity>
      </link>
    </model>
    <physics type='ode'>
      <max_step_size>0.001</max_step_size>
      <real_time_factor>1</real_time_factor>
      <real_time_update_rate>0</real_time_update_rate>
      <gravity>0 0 -9.8</gravity>
    </physics>
    <scene>
      <ambient>0.4 0.4 0.4 1</ambient>
      <background>0.7 0.7 0.7 1</background>
      <shadows>1</shadows>
    </scene>
    <spherical_coordinates>
      <surface_model>EARTH_WGS84</surface_model>
      <latitude_deg>0</latitude_deg>
      <longitude_deg>0</longitude_deg>
      <elevation>0</elevation>
      <heading_deg>0</heading_deg>
    </spherical_coordinates>
    <model name='grey_wall'>
      <static>1</static>
      <link name='link'>
        <pose>0 0 1.4 0 -0 0</pose>
        <collision name='collision'>
          <geometry>
            <box>
              <size>7.5 0.2 2.8</size>
            </box>
          </geometry>
          <max_contacts>10</max_contacts>
          <surface>
            <bounce/>
            <friction>
              <ode/>
            </friction>
            <contact>
              <ode/>
            </contact>
          </surface>
        </collision>
        <visual name='visual'>
          <cast_shadows>0</cast_shadows>
          <geometry>
            <box>
              <size>7.5 0.2 2.8</size>
            </box>
          </geometry>
          <material>
            <script>
              <uri>model://grey_wall/materials/scripts</uri>
              <uri>model://grey_wall/materials/textures</uri>
              <name>vrc/grey_wall</name>
            </script>
          </material>
        </visual>
        <velocity_decay>
          <linear>0</linear>
          <angular>0</angular>
        </velocity_decay>
        <self_collide>0</self_collide>
        <kinematic>0</kinematic>
        <gravity>1</gravity>
      </link>
      <pose>-5.45844 9 0 0 -0 0</pose>
    </model>
    <model name='grey_wall_0'>
      <static>1</static>
      <link name='link'>
        <pose>0 0 1.4 0 -0 0</pose>
        <collision name='collision'>
          <geometry>
            <box>
              <size>7.5 0.2 2.8</size>
            </box>
          </geometry>
          <max_contacts>10</max_contacts>
          <surface>
            <bounce/>
            <friction>
              <ode/>
            </friction>
            <contact>
              <ode/>
            </contact>
          </surface>
        </collision>
        <visual name='visual'>
          <cast_shadows>0</cast_shadows>
          <geometry>
            <box>
              <size>7.5 0.2 2.8</size>
            </box>
          </geometry>
          <material>
            <script>
              <uri>model://grey_wall/materials/scripts</uri>
              <uri>model://grey_wall/materials/textures</uri>
              <name>vrc/grey_wall</name>
            </script>
          </material>
        </visual>
        <velocity_decay>
          <linear>0</linear>
          <angular>0</angular>
        </velocity_decay>
        <self_collide>0</self_collide>
        <kinematic>0</kinematic>
        <gravity>1</gravity>
      </link>
      <pose>2 9 0 0 -0 0</pose>
    </model>
    <model name='grey_wall_1'>
      <static>1</static>
      <link name='link'>
        <pose>0 0 1.4 0 -0 0</pose>
        <collision name='collision'>
          <geometry>
            <box>
              <size>7.5 0.2 2.8</size>
            </box>
          </geometry>
          <max_contacts>10</max_contacts>
          <surface>
            <bounce/>
            <friction>
              <ode/>
            </friction>
            <contact>
              <ode/>
            </contact>
          </surface>
        </collision>
        <visual name='visual'>
          <cast_shadows>0</cast_shadows>
          <geometry>
            <box>
              <size>7.5 0.2 2.8</size>
            </box>
          </geometry>
          <material>
            <script>
              <uri>model://grey_wall/materials/scripts</uri>
              <uri>model://grey_wall/materials/textures</uri>
              <name>vrc/grey_wall</name>
            </script>
          </material>
        </visual>
        <velocity_decay>
          <linear>0</linear>
          <angular>0</angular>
        </velocity_decay>
        <self_collide>0</self_collide>
        <kinematic>0</kinematic>
        <gravity>1</gravity>
      </link>
      <pose>6.55945 9 0 0 -0 0</pose>
    </model>
    <model name='grey_wall_2'>
      <static>1</static>
      <link name='link'>
        <pose>0 0 1.4 0 -0 0</pose>
        <collision name='collision'>
          <geometry>
            <box>
              <size>7.5 0.2 2.8</size>
            </box>
          </geometry>
          <max_contacts>10</max_contacts>
          <surface>
            <bounce/>
            <friction>
              <ode/>
            </friction>
            <contact>
              <ode/>
            </contact>
          </surface>
        </collision>
        <visual name='visual'>
          <cast_shadows>0</cast_shadows>
          <geometry>
            <box>
              <size>7.5 0.2 2.8</size>
            </box>
          </geometry>
          <material>
            <script>
              <uri>model://grey_wall/materials/scripts</uri>
              <uri>model://grey_wall/materials/textures</uri>
              <name>vrc/grey_wall</name>
            </script>
          </material>
        </visual>
        <velocity_decay>
          <linear>0</linear>
          <angular>0</angular>
        </velocity_decay>
        <self_collide>0</self_collide>
        <kinematic>0</kinematic>
        <gravity>1</gravity>
      </link>
      <pose>-6.57172 -10 0 0 -0 0</pose>
    </model>
    <model name='grey_wall_3'>
      <static>1</static>
      <link name='link'>
        <pose>0 0 1.4 0 -0 0</pose>
        <collision name='collision'>
          <geometry>
            <box>
              <size>7.5 0.2 2.8</size>
            </box>
          </geometry>
          <max_contacts>10</max_contacts>
          <surface>
            <bounce/>
            <friction>
              <ode/>
            </friction>
            <contact>
              <ode/>
            </contact>
          </surface>
        </collision>
        <visual name='visual'>
          <cast_shadows>0</cast_shadows>
          <geometry>
            <box>
              <size>7.5 0.2 2.8</size>
            </box>
          </geometry>
          <material>
            <script>
              <uri>model://grey_wall/materials/scripts</uri>
              <uri>model://grey_wall/materials/textures</uri>
              <name>vrc/grey_wall</name>
            </script>
          </material>
        </visual>
        <velocity_decay>
          <linear>0</linear>
          <angular>0</angular>
        </velocity_decay>
        <self_collide>0</self_collide>
        <kinematic>0</kinematic>
        <gravity>1</gravity>
      </link>
      <pose>0.502464 -10 0 0 -0 0</pose>
    </model>
    <model name='grey_wall_4'>
      <static>1</static>
      <link name='link'>
        <pose>0 0 1.4 0 -0 0</pose>
        <collision name='collision'>
          <geometry>
            <box>
              <size>7.5 0.2 2.8</size>
            </box>
          </geometry>
          <max_contacts>10</max_contacts>
          <surface>
            <bounce/>
            <friction>
              <ode/>
            </friction>
            <contact>
              <ode/>
            </contact>
          </surface>
        </collision>
        <visual name='visual'>
          <cast_shadows>0</cast_shadows>
          <geometry>
            <box>
              <size>7.5 0.2 2.8</size>
            </box>
          </geometry>
          <material>
            <script>
              <uri>model://grey_wall/materials/scripts</uri>
              <uri>model://grey_wall/materials/textures</uri>
              <name>vrc/grey_wall</name>
            </script>
          </material>
        </visual>
        <velocity_decay>
          <linear>0</linear>
          <angular>0</angular>
        </velocity_decay>
        <self_collide>0</self_collide>
        <kinematic>0</kinematic>
        <gravity>1</gravity>
      </link>
      <pose>6.46119 -10 0 0 -0 0</pose>
    </model>
    <model name='grey_wall_5'>
      <static>1</static>
      <link name='link'>
        <pose>0 0 1.4 0 -0 0</pose>
        <collision name='collision'>
          <geometry>
            <box>
              <size>7.5 0.2 2.8</size>
            </box>
          </geometry>
          <max_contacts>10</max_contacts>
          <surface>
            <bounce/>
            <friction>
              <ode/>
            </friction>
            <contact>
              <ode/>
            </contact>
          </surface>
        </collision>
        <visual name='visual'>
          <cast_shadows>0</cast_shadows>
          <geometry>
            <box>
              <size>7.5 0.2 2.8</size>
            </box>
          </geometry>
          <material>
            <script>
              <uri>model://grey_wall/materials/scripts</uri>
              <uri>model://grey_wall/materials/textures</uri>
              <name>vrc/grey_wall</name>
            </script>
          </material>
        </visual>
        <velocity_decay>
          <linear>0</linear>
          <angular>0</angular>
        </velocity_decay>
        <self_collide>0</self_collide>
        <kinematic>0</kinematic>
        <gravity>1</gravity>
      </link>
      <pose>7 5 0 0 -0 0</pose>
    </model>
    <model name='grey_wall_6'>
      <static>1</static>
      <link name='link'>
        <pose>0 0 1.4 0 -0 0</pose>
        <collision name='collision'>
          <geometry>
            <box>
              <size>7.5 0.2 2.8</size>
            </box>
          </geometry>
          <max_contacts>10</max_contacts>
          <surface>
            <bounce/>
            <friction>
              <ode/>
            </friction>
            <contact>
              <ode/>
            </contact>
          </surface>
        </collision>
        <visual name='visual'>
          <cast_shadows>0</cast_shadows>
          <geometry>
            <box>
              <size>7.5 0.2 2.8</size>
            </box>
          </geometry>
          <material>
            <script>
              <uri>model://grey_wall/materials/scripts</uri>
              <uri>model://grey_wall/materials/textures</uri>
              <name>vrc/grey_wall</name>
            </script>
          </material>
        </visual>
        <velocity_decay>
          <linear>0</linear>
          <angular>0</angular>
        </velocity_decay>
        <self_collide>0</self_collide>
        <kinematic>0</kinematic>
        <gravity>1</gravity>
      </link>
      <pose>7 0 0 0 -0 0</pose>
    </model>
    <model name='grey_wall_7'>
      <static>1</static>
      <link name='link'>
        <pose>0 0 1.4 0 -0 0</pose>
        <collision name='collision'>
          <geometry>
            <box>
              <size>7.5 0.2 2.8</size>
            </box>
          </geometry>
          <max_contacts>10</max_contacts>
          <surface>
            <bounce/>
            <friction>
              <ode/>
            </friction>
            <contact>
              <ode/>
            </contact>
          </surface>
        </collision>
        <visual name='visual'>
          <cast_shadows>0</cast_shadows>
          <geometry>
            <box>
              <size>7.5 0.2 2.8</size>
            </box>
          </geometry>
          <material>
            <script>
              <uri>model://grey_wall/materials/scripts</uri>
              <uri>model://grey_wall/materials/textures</uri>
              <name>vrc/grey_wall</name>
            </script>
          </material>
        </visual>
        <velocity_decay>
          <linear>0</linear>
          <angular>0</angular>
        </velocity_decay>
        <self_collide>0</self_collide>
        <kinematic>0</kinematic>
        <gravity>1</gravity>
      </link>
      <pose>7 -6 0 0 -0 0</pose>
    </model>
    <model name='grey_wall_8'>
      <static>1</static>
      <link name='link'>
        <pose>0 0 1.4 0 -0 0</pose>
        <collision name='collision'>
          <geometry>
            <box>
              <size>7.5 0.2 2.8</size>
            </box>
          </geometry>
          <max_contacts>10</max_contacts>
          <surface>
            <bounce/>
            <friction>
              <ode/>
            </friction>
            <contact>
              <ode/>
            </contact>
          </surface>
        </collision>
        <visual name='visual'>
          <cast_shadows>0</cast_shadows>
          <geometry>
            <box>
              <size>7.5 0.2 2.8</size>
            </box>
          </geometry>
          <material>
            <script>
              <uri>model://grey_wall/materials/scripts</uri>
              <uri>model://grey_wall/materials/textures</uri>
              <name>vrc/grey_wall</name>
            </script>
          </material>
        </visual>
        <velocity_decay>
          <linear>0</linear>
          <angular>0</angular>
        </velocity_decay>
        <self_collide>0</self_collide>
        <kinematic>0</kinematic>
        <gravity>1</gravity>
      </link>
      <pose>-7 5 0 0 -0 0</pose>
    </model>
    <model name='grey_wall_9'>
      <static>1</static>
      <link name='link'>
        <pose>0 0 1.4 0 -0 0</pose>
        <collision name='collision'>
          <geometry>
            <box>
              <size>7.5 0.2 2.8</size>
            </box>
          </geometry>
          <max_contacts>10</max_contacts>
          <surface>
            <bounce/>
            <friction>
              <ode/>
            </friction>
            <contact>
              <ode/>
            </contact>
          </surface>
        </collision>
        <visual name='visual'>
          <cast_shadows>0</cast_shadows>
          <geometry>
            <box>
              <size>7.5 0.2 2.8</size>
            </box>
          </geometry>
          <material>
            <script>
              <uri>model://grey_wall/materials/scripts</uri>
              <uri>model://grey_wall/materials/textures</uri>
              <name>vrc/grey_wall</name>
            </script>
          </material>
        </visual>
        <velocity_decay>
          <linear>0</linear>
          <angular>0</angular>
        </velocity_decay>
        <self_collide>0</self_collide>
        <kinematic>0</kinematic>
        <gravity>1</gravity>
      </link>
      <pose>-7 0 0 0 -0 0</pose>
    </model>
    <model name='grey_wall_10'>
      <static>1</static>
      <link name='link'>
        <pose>0 0 1.4 0 -0 0</pose>
        <collision name='collision'>
          <geometry>
            <box>
              <size>7.5 0.2 2.8</size>
            </box>
          </geometry>
          <max_contacts>10</max_contacts>
          <surface>
            <bounce/>
            <friction>
              <ode/>
            </friction>
            <contact>
              <ode/>
            </contact>
          </surface>
        </collision>
        <visual name='visual'>
          <cast_shadows>0</cast_shadows>
          <geometry>
            <box>
              <size>7.5 0.2 2.8</size>
            </box>
          </geometry>
          <material>
            <script>
              <uri>model://grey_wall/materials/scripts</uri>
              <uri>model://grey_wall/materials/textures</uri>
              <name>vrc/grey_wall</name>
            </script>
          </material>
        </visual>
        <velocity_decay>
          <linear>0</linear>
          <angular>0</angular>
        </velocity_decay>
        <self_collide>0</self_collide>
        <kinematic>0</kinematic>
        <gravity>1</gravity>
      </link>
      <pose>-7 -6 0 0 -0 0</pose>
    </model>
    <state world_name='default'>
      <sim_time>2755 647000000</sim_time>
      <real_time>759 67987493</real_time>
      <wall_time>1513861629 299770818</wall_time>
      <model name='drc_practice_white_jersey_barrier'>
        <pose>-6 1 0 0 -0 0</pose>
        <link name='link'>
          <pose>-6 1 0 0 -0 0</pose>
          <velocity>0 0 0 0 -0 0</velocity>
          <acceleration>0 0 0 0 -0 0</acceleration>
          <wrench>0 0 0 0 -0 0</wrench>
        </link>
      </model>
      <model name='first_2015_trash_can'>
        <pose>-6.81306 -0.057385 -1e-06 8e-06 1.6e-05 0.107319</pose>
        <link name='link'>
          <pose>-6.81306 -0.057385 -1e-06 8e-06 1.6e-05 0.107319</pose>
          <velocity>0 0 0 0 -0 0</velocity>
          <acceleration>-5.52924 3.88816 6.47005 -0.615273 -0.874962 -2e-06</acceleration>
          <wrench>-26.7104 18.7827 31.2553 0 -0 0</wrench>
        </link>
      </model>
      <model name='first_2015_trash_can_0'>
        <pose>6.00063 -0.000186 -2e-06 -7e-06 9e-06 -0.002987</pose>
        <link name='link'>
          <pose>6.00063 -0.000186 -2e-06 -7e-06 9e-06 -0.002987</pose>
          <velocity>0 0 0 0 -0 0</velocity>
          <acceleration>5.82381 -0.852362 4.09803 0.134916 0.921566 -1.4e-05</acceleration>
          <wrench>28.1334 -4.11755 19.7966 0 -0 0</wrench>
        </link>
      </model>
      <model name='first_2015_trash_can_1'>
        <pose>-1.05934 -4.99949 -1e-06 -2e-06 1.7e-05 -0.002576</pose>
        <link name='link'>
          <pose>-1.05934 -4.99949 -1e-06 -2e-06 1.7e-05 -0.002576</pose>
          <velocity>0 0 0 0 -0 0</velocity>
          <acceleration>-6.62638 -0.952658 6.34057 0.150756 -1.04856 1e-06</acceleration>
          <wrench>-32.0104 -4.60206 30.6298 0 -0 0</wrench>
        </link>
      </model>
      <model name='first_2015_trash_can_2'>
        <pose>3.00047 -7.0002 2e-06 2.6e-05 1.4e-05 -0.001965</pose>
        <link name='link'>
          <pose>3.00047 -7.0002 2e-06 2.6e-05 1.4e-05 -0.001965</pose>
          <velocity>0 0 0 0 -0 0</velocity>
          <acceleration>-1.37855 2.19888 -3.57964 -0.344799 -0.217656 0.000526</acceleration>
          <wrench>-6.65946 10.6223 -17.2924 0 -0 0</wrench>
        </link>
      </model>
      <model name='frc2016_drawbridge'>
        <pose>-2.00157 -0.002943 -4e-06 -3e-06 4e-06 -0.01347</pose>
        <link name='base'>
          <pose>-2.00157 -0.002943 -4e-06 -3e-06 4e-06 -0.01347</pose>
          <velocity>0.000167 -0.000368 -0.003854 -0.002803 0.004893 -0.000575</velocity>
          <acceleration>1.09503 0.523924 -7.68001 -0.209154 0.497603 -0.014604</acceleration>
          <wrench>10.9503 5.23924 -76.8001 0 -0 0</wrench>
        </link>
        <link name='bridge'>
          <pose>-1.99776 0.279483 0.505766 -3e-06 4e-06 -0.01347</pose>
          <velocity>0.002819 0.001055 -0.004661 -0.002842 0.004874 -0.000553</velocity>
          <acceleration>0.1856 0.089875 -7.67427 -0.032097 0.172821 -0.017367</acceleration>
          <wrench>0.3712 0.179749 -15.3485 0 -0 0</wrench>
        </link>
      </model>
      <model name='frc2016_drawbridge_0'>
        <pose>4.00091 -2.50737 -2e-06 -2e-06 2e-06 -0.013906</pose>
        <link name='base'>
          <pose>4.00091 -2.50737 -2e-06 -2e-06 2e-06 -0.013906</pose>
          <velocity>0.00015 -0.000332 -0.00315 -0.001746 0.004264 -0.000519</velocity>
          <acceleration>1.25798 0.579949 -7.41969 -0.242332 0.524059 -0.031961</acceleration>
          <wrench>12.5798 5.79949 -74.1969 0 -0 0</wrench>
        </link>
        <link name='bridge'>
          <pose>4.00483 -2.22495 0.505768 0 2e-06 -0.013907</pose>
          <velocity>0.002404 0.000754 -0.003646 -0.00215 0.004299 -0.00044</velocity>
          <acceleration>0.131902 0.23444 -7.45321 -0.024375 0.201101 0.016481</acceleration>
          <wrench>0.263805 0.46888 -14.9064 0 -0 0</wrench>
        </link>
      </model>
      <model name='frc2016_portcullis'>
        <pose>-5.9387 -5.08843 -1e-06 -3e-06 1e-06 0.636302</pose>
        <link name='base'>
          <pose>-5.9387 -5.08843 -1e-06 -3e-06 1e-06 0.636302</pose>
          <velocity>0.000358 -0.000252 -0.001681 -0.00336 0.001226 -0.000905</velocity>
          <acceleration>1.37793 2.07304 -3.66182 -0.157426 0.108445 -0.01032</acceleration>
          <wrench>68.8964 103.652 -183.091 0 -0 0</wrench>
        </link>
        <link name='gate'>
          <pose>-5.97893 -5.08228 0.933269 -3e-06 1e-06 0.636303</pose>
          <velocity>0.001468 0.002896 -0.001541 -0.003471 0.001434 -0.000963</velocity>
          <acceleration>1.24451 1.88541 -3.65448 -0.630957 0.100282 -2.99713</acceleration>
          <wrench>2.48901 3.77082 -7.30895 0 -0 0</wrench>
        </link>
      </model>
      <model name='grey_wall'>
        <pose>-6.37486 9.06322 0 0 -0 0</pose>
        <link name='link'>
          <pose>-6.37486 9.06322 1.4 0 -0 0</pose>
          <velocity>0 0 0 0 -0 0</velocity>
          <acceleration>0 0 0 0 -0 0</acceleration>
          <wrench>0 0 0 0 -0 0</wrench>
        </link>
      </model>
      <model name='grey_wall_0'>
        <pose>1.12463 9.06218 0 0 -0 0</pose>
        <link name='link'>
          <pose>1.12463 9.06218 1.4 0 -0 0</pose>
          <velocity>0 0 0 0 -0 0</velocity>
          <acceleration>0 0 0 0 -0 0</acceleration>
          <wrench>0 0 0 0 -0 0</wrench>
        </link>
      </model>
      <model name='grey_wall_1'>
        <pose>6.47505 9.08721 0 0 -0 0</pose>
        <link name='link'>
          <pose>6.47505 9.08721 1.4 0 -0 0</pose>
          <velocity>0 0 0 0 -0 0</velocity>
          <acceleration>0 0 0 0 -0 0</acceleration>
          <wrench>0 0 0 0 -0 0</wrench>
        </link>
      </model>
      <model name='grey_wall_10'>
        <pose>-10.2268 -6.36026 -0 0 0 -1.58184</pose>
        <link name='link'>
          <pose>-10.2268 -6.36026 1.4 0 0 -1.58184</pose>
          <velocity>0 0 0 0 -0 0</velocity>
          <acceleration>0 0 0 0 -0 0</acceleration>
          <wrench>0 0 0 0 -0 0</wrench>
        </link>
      </model>
      <model name='grey_wall_11'>
        <pose>-6.53777 4 0 0 -0 0</pose>
        <link name='link'>
          <pose>-6.53777 4 1.4 0 -0 0</pose>
          <velocity>0 0 0 0 -0 0</velocity>
          <acceleration>0 0 0 0 -0 0</acceleration>
          <wrench>0 0 0 0 -0 0</wrench>
        </link>
      </model>
      <model name='grey_wall_12'>
        <pose>6.50522 4 0 0 -0 0</pose>
        <link name='link'>
          <pose>6.50522 4 1.4 0 -0 0</pose>
          <velocity>0 0 0 0 -0 0</velocity>
          <acceleration>0 0 0 0 -0 0</acceleration>
          <wrench>0 0 0 0 -0 0</wrench>
        </link>
      </model>
      <model name='grey_wall_2'>
        <pose>-6.57172 -10 0 0 -0 0</pose>
        <link name='link'>
          <pose>-6.57172 -10 1.4 0 -0 0</pose>
          <velocity>0 0 0 0 -0 0</velocity>
          <acceleration>0 0 0 0 -0 0</acceleration>
          <wrench>0 0 0 0 -0 0</wrench>
        </link>
      </model>
      <model name='grey_wall_3'>
        <pose>0.502464 -10 0 0 -0 0</pose>
        <link name='link'>
          <pose>0.502464 -10 1.4 0 -0 0</pose>
          <velocity>0 0 0 0 -0 0</velocity>
          <acceleration>0 0 0 0 -0 0</acceleration>
          <wrench>0 0 0 0 -0 0</wrench>
        </link>
      </model>
      <model name='grey_wall_4'>
        <pose>6.46119 -10 0 0 -0 0</pose>
        <link name='link'>
          <pose>6.46119 -10 1.4 0 -0 0</pose>
          <velocity>0 0 0 0 -0 0</velocity>
          <acceleration>0 0 0 0 -0 0</acceleration>
          <wrench>0 0 0 0 -0 0</wrench>
        </link>
      </model>
      <model name='grey_wall_5'>
        <pose>10.1266 5.31585 0 0 0 -1.58058</pose>
        <link name='link'>
          <pose>10.1266 5.31585 1.4 0 0 -1.58058</pose>
          <velocity>0 0 0 0 -0 0</velocity>
          <acceleration>0 0 0 0 -0 0</acceleration>
          <wrench>0 0 0 0 -0 0</wrench>
        </link>
      </model>
      <model name='grey_wall_6'>
        <pose>10.1134 -2.21796 0 0 0 -1.566</pose>
        <link name='link'>
          <pose>10.1134 -2.21796 1.4 0 0 -1.566</pose>
          <velocity>0 0 0 0 -0 0</velocity>
          <acceleration>0 0 0 0 -0 0</acceleration>
          <wrench>0 0 0 0 -0 0</wrench>
        </link>
      </model>
      <model name='grey_wall_7'>
        <pose>10.161 -6.18012 0 0 -0 1.5699</pose>
        <link name='link'>
          <pose>10.161 -6.18012 1.4 0 -0 1.5699</pose>
          <velocity>0 0 0 0 -0 0</velocity>
          <acceleration>0 0 0 0 -0 0</acceleration>
          <wrench>0 0 0 0 -0 0</wrench>
        </link>
      </model>
      <model name='grey_wall_8'>
        <pose>-10.1642 5.26629 0 0 0 -1.57839</pose>
        <link name='link'>
          <pose>-10.1642 5.26629 1.4 0 0 -1.57839</pose>
          <velocity>0 0 0 0 -0 0</velocity>
          <acceleration>0 0 0 0 -0 0</acceleration>
          <wrench>0 0 0 0 -0 0</wrench>
        </link>
      </model>
      <model name='grey_wall_9'>
        <pose>-10.2248 -2.07732 0 0 0 -1.57362</pose>
        <link name='link'>
          <pose>-10.2248 -2.07732 1.4 0 0 -1.57362</pose>
          <velocity>0 0 0 0 -0 0</velocity>
          <acceleration>0 0 0 0 -0 0</acceleration>
          <wrench>0 0 0 0 -0 0</wrench>
        </link>
      </model>
      <model name='ground_plane'>
        <pose>0 0 0 0 -0 0</pose>
        <link name='link'>
          <pose>0 0 0 0 -0 0</pose>
          <velocity>0 0 0 0 -0 0</velocity>
          <acceleration>0 0 0 0 -0 0</acceleration>
          <wrench>0 0 0 0 -0 0</wrench>
        </link>
      </model>
      <model name='hinged_door'>
        <pose>-4 -3 6e-06 3e-06 -0 0</pose>
        <link name='door'>
          <pose>-4 -3.00001 2.04 3.14159 -0 1.74807</pose>
          <velocity>0.000467 2.3e-05 5e-06 -9e-06 0.000201 0.000564</velocity>
          <acceleration>0.13584 0.002778 0.004287 -0.007535 0.118723 0.045815</acceleration>
          <wrench>5.61365 0.114784 0.177156 0 -0 0</wrench>
        </link>
        <link name='frame'>
          <pose>-3.94 -3.0005 6e-06 3e-06 -0 0</pose>
          <velocity>1.2e-05 -2e-06 4e-06 3e-06 0.000319 2.06795e-25</velocity>
          <acceleration>0.023105 -0.003969 0.007989 0.005862 0.527613 0.000225</acceleration>
          <wrench>0.023105 -0.003969 0.007989 0 -0 0</wrench>
        </link>
        <link name='handles'>
          <pose>-4.1417 -2.21266 1.05 -3.14159 0.001592 -1.39352</pose>
          <velocity>-0.000175 -6.6e-05 2.5e-05 -9e-06 0.000198 0.000558</velocity>
          <acceleration>-0.062951 -0.055243 0.023126 -0.021112 0.277309 0.613482</acceleration>
          <wrench>-0.062951 -0.055243 0.023126 0 -0 0</wrench>
        </link>
      </model>
      <model name='unit_box_1'>
        <pose>-7 8.45126 0.5 0 -0 0</pose>
        <link name='link'>
          <pose>-7 8.45126 0.5 0 -0 0</pose>
          <velocity>0 0 0 0 -0 0</velocity>
          <acceleration>-0 0 0 0 -0 0</acceleration>
          <wrench>-0 0 0 0 -0 0</wrench>
        </link>
      </model>
      <model name='unit_box_1_0'>
        <pose>-2 2 0.5 0 -0 0</pose>
        <link name='link'>
          <pose>-2 2 0.5 0 -0 0</pose>
          <velocity>0 0 0 0 -0 0</velocity>
          <acceleration>0 0 0 0 -0 0</acceleration>
          <wrench>0 0 0 0 -0 0</wrench>
        </link>
      </model>
      <model name='unit_box_2'>
        <pose>4 5 0.5 0 -0 2e-06</pose>
        <link name='link'>
          <pose>4 5 0.5 0 -0 2e-06</pose>
          <velocity>0 0 0 0 -0 0</velocity>
          <acceleration>0 0 -0 0 -0 0</acceleration>
          <wrench>0 0 -0 0 -0 0</wrench>
        </link>
      </model>
      <model name='unit_box_2_0'>
        <pose>-6 -6.42643 0.5 0 -0 0</pose>
        <link name='link'>
          <pose>-6 -6.42643 0.5 0 -0 0</pose>
          <velocity>0 0 0 0 -0 0</velocity>
          <acceleration>-0 -0 0 0 -0 0</acceleration>
          <wrench>-0 -0 0 0 -0 0</wrench>
        </link>
      </model>
      <model name='unit_box_3'>
        <pose>7 -5 0.5 0 0 -3e-06</pose>
        <link name='link'>
          <pose>7 -5 0.5 0 0 -3e-06</pose>
          <velocity>0 0 0 0 -0 0</velocity>
          <acceleration>0 -0 0 0 -0 0</acceleration>
          <wrench>0 -0 0 0 -0 0</wrench>
        </link>
      </model>
      <model name='unit_box_4'>
        <pose>7 -6 0.5 0 0 -1e-06</pose>
        <link name='link'>
          <pose>7 -6 0.5 0 0 -1e-06</pose>
          <velocity>0 0 0 0 -0 0</velocity>
          <acceleration>-0 0 -0 0 -0 0</acceleration>
          <wrench>-0 0 -0 0 -0 0</wrench>
        </link>
      </model>
      <model name='unit_box_5'>
        <pose>6 -6.52642 0.5 0 -0 2e-06</pose>
        <link name='link'>
          <pose>6 -6.52642 0.5 0 -0 2e-06</pose>
          <velocity>0 0 0 0 -0 0</velocity>
          <acceleration>0 -0 -0 0 -0 0</acceleration>
          <wrench>0 -0 -0 0 -0 0</wrench>
        </link>
      </model>
      <model name='unit_box_6'>
        <pose>-3.43088 -3 0.5 0 -0 0</pose>
        <link name='link'>
          <pose>-3.43088 -3 0.5 0 -0 0</pose>
          <velocity>0 0 0 0 -0 0</velocity>
          <acceleration>-0 0 -0 -0 -0 -0</acceleration>
          <wrench>-0 0 -0 0 -0 0</wrench>
        </link>
      </model>
      <model name='unit_box_7'>
        <pose>-9.65855 -9.39624 0.5 0 0 -0.007544</pose>
        <link name='link'>
          <pose>-9.65855 -9.39624 0.5 0 0 -0.007544</pose>
          <velocity>0 0 0 0 -0 0</velocity>
          <acceleration>0 -0 0 0 -0 0</acceleration>
          <wrench>0 -0 0 0 -0 0</wrench>
        </link>
      </model>
      <model name='unit_box_8'>
        <pose>3.41973 0 0.5 0 -0 0</pose>
        <link name='link'>
          <pose>3.41973 0 0.5 0 -0 0</pose>
          <velocity>0 0 0 0 -0 0</velocity>
          <acceleration>0 -0 0 0 -0 0</acceleration>
          <wrench>0 -0 0 0 -0 0</wrench>
        </link>
      </model>
      <model name='unit_cylinder_1'>
        <pose>5.99999 -5.52642 0.499998 1e-06 -1e-06 -1e-06</pose>
        <link name='link'>
          <pose>5.99999 -5.52642 0.499998 1e-06 -1e-06 -1e-06</pose>
          <velocity>0 0 0 0 -0 0</velocity>
          <acceleration>0 0.000189 -9.8 -3.14159 -0.375222 3.14159</acceleration>
          <wrench>0 0.000189 -9.8 0 -0 0</wrench>
        </link>
      </model>
      <model name='unit_cylinder_2'>
        <pose>2 -7 0.499992 -1e-06 -0 0</pose>
        <link name='link'>
          <pose>2 -7 0.499992 -1e-06 -0 0</pose>
          <velocity>0 0 0 0 -0 0</velocity>
          <acceleration>0 0.000185 -9.8 -3.14159 -0.375222 3.14159</acceleration>
          <wrench>0 0.000185 -9.8 0 -0 0</wrench>
        </link>
      </model>
      <model name='unit_cylinder_3'>
        <pose>6.44555 1 0.499998 1e-06 -0 0</pose>
        <link name='link'>
          <pose>6.44555 1 0.499998 1e-06 -0 0</pose>
          <velocity>0 0 0 0 -0 0</velocity>
          <acceleration>0 0.000191 -9.8 0 -0 0</acceleration>
          <wrench>0 0.000191 -9.8 0 -0 0</wrench>
        </link>
      </model>
      <model name='unit_cylinder_4'>
        <pose>-0 4 0.499992 -1e-06 -0 0</pose>
        <link name='link'>
          <pose>-0 4 0.499992 -1e-06 -0 0</pose>
          <velocity>0 0 0 0 -0 0</velocity>
          <acceleration>0 0.000211 -9.8 -3.14159 -0.375222 -3.14159</acceleration>
          <wrench>0 0.000211 -9.8 0 -0 0</wrench>
        </link>
      </model>
      <model name='unit_cylinder_5'>
        <pose>-8.65243 -9.00172 0.499996 -1e-06 1e-06 -0.000389</pose>
        <link name='link'>
          <pose>-8.65243 -9.00172 0.499996 -1e-06 1e-06 -0.000389</pose>
          <velocity>0 0 0 0 -0 0</velocity>
          <acceleration>0 0.000288 -9.8 -3.14159 -0.375222 3.14159</acceleration>
          <wrench>0 0.000288 -9.8 0 -0 0</wrench>
        </link>
      </model>
      <model name='unit_cylinder_6'>
        <pose>4 6 0.499997 -0 -0 -0</pose>
        <link name='link'>
          <pose>4 6 0.499997 -0 -0 -0</pose>
          <velocity>0 0 0 0 -0 0</velocity>
          <acceleration>0 0.000225 -9.8 -3.14159 -0.375222 3.14159</acceleration>
          <wrench>0 0.000225 -9.8 0 -0 0</wrench>
        </link>
      </model>
      <model name='unit_cylinder_7'>
        <pose>7 9 0.499992 0 -0 0</pose>
        <link name='link'>
          <pose>7 9 0.499992 0 -0 0</pose>
          <velocity>0 0 0 0 -0 0</velocity>
          <acceleration>0 0.000224 426.407 -0.968765 1.22323 -1.63629</acceleration>
          <wrench>0 0.000224 426.407 0 -0 0</wrench>
        </link>
      </model>
      <model name='wheel_valve_large_wall'>
        <pose>1.59014 0 0 0 -0 0</pose>
        <link name='valve_0::handle'>
          <pose>2.50973 0.0208 0.285 0 -0.000358 0</pose>
          <velocity>0 0 -0 0 -0 0</velocity>
          <acceleration>0 0 -0 0 -0 0</acceleration>
          <wrench>0 0 -0 0 -0 0</wrench>
        </link>
        <link name='valve_10::handle'>
          <pose>1.89922 0.0208 2.1162 0 0.000358 0</pose>
          <velocity>-0 0 -0 0 -0 0</velocity>
          <acceleration>-0 -0 0 0 -0 0</acceleration>
          <wrench>-0 -0 0 0 -0 0</wrench>
        </link>
        <link name='valve_1::handle'>
          <pose>2.50973 0.0208 0.8954 0 -0.000358 0</pose>
          <velocity>0 0 -0 0 -0 0</velocity>
          <acceleration>0 0 0 0 -0 0</acceleration>
          <wrench>0 0 0 0 -0 0</wrench>
        </link>
        <link name='valve_2::handle'>
          <pose>2.50973 0.0208 1.5058 0 -0.000358 0</pose>
          <velocity>0 0 -0 0 -0 0</velocity>
          <acceleration>0 0 0 0 -0 0</acceleration>
          <wrench>0 0 0 0 -0 0</wrench>
        </link>
        <link name='valve_3::handle'>
          <pose>2.50973 0.0208 2.1162 0 -0.000358 0</pose>
          <velocity>0 0 -0 0 -0 0</velocity>
          <acceleration>0 -0 0 0 -0 0</acceleration>
          <wrench>0 -0 0 0 -0 0</wrench>
        </link>
        <link name='valve_4::handle'>
          <pose>2.20447 0.0208 0.5896 0 0.000597 0</pose>
          <velocity>-0 0 -0 0 -0 0</velocity>
          <acceleration>-0 -0 -0 0 -0 0</acceleration>
          <wrench>-0 -0 -0 0 -0 0</wrench>
        </link>
        <link name='valve_5::handle'>
          <pose>2.20447 0.0208 1.2 0 0.000597 0</pose>
          <velocity>-0 0 -0 0 -0 0</velocity>
          <acceleration>-0 -0 0 0 -0 0</acceleration>
          <wrench>-0 -0 0 0 -0 0</wrench>
        </link>
        <link name='valve_6::handle'>
          <pose>2.20447 0.0208 1.8104 0 0.000597 0</pose>
          <velocity>-0 0 -0 0 -0 0</velocity>
          <acceleration>-0 -0 0 0 -0 0</acceleration>
          <wrench>-0 -0 0 0 -0 0</wrench>
        </link>
        <link name='valve_7::handle'>
          <pose>1.89922 0.0208 0.285 0 0.000358 0</pose>
          <velocity>-0 0 -0 0 -0 0</velocity>
          <acceleration>-0 0 -0 0 -0 0</acceleration>
          <wrench>-0 0 -0 0 -0 0</wrench>
        </link>
        <link name='valve_8::handle'>
          <pose>1.89922 0.0208 0.8954 0 0.000358 0</pose>
          <velocity>-0 0 -0 0 -0 0</velocity>
          <acceleration>-0 0 0 0 -0 0</acceleration>
          <wrench>-0 0 0 0 -0 0</wrench>
        </link>
        <link name='valve_9::handle'>
          <pose>1.89922 0.0208 1.5058 0 0.000358 0</pose>
          <velocity>-0 0 -0 0 -0 0</velocity>
          <acceleration>-0 0 0 0 -0 0</acceleration>
          <wrench>-0 0 0 0 -0 0</wrench>
        </link>
        <link name='wall::link'>
          <pose>1.59014 0 0 0 -0 0</pose>
          <velocity>0 -0 -0 0 -0 0</velocity>
          <acceleration>0 0 0 0 -0 0</acceleration>
          <wrench>0 0 0 0 -0 0</wrench>
        </link>
      </model>
    </state>
    <model name='grey_wall_11'>
      <static>1</static>
      <link name='link'>
        <pose>0 0 1.4 0 -0 0</pose>
        <collision name='collision'>
          <geometry>
            <box>
              <size>7.5 0.2 2.8</size>
            </box>
          </geometry>
          <max_contacts>10</max_contacts>
          <surface>
            <bounce/>
            <friction>
              <ode/>
            </friction>
            <contact>
              <ode/>
            </contact>
          </surface>
        </collision>
        <visual name='visual'>
          <cast_shadows>0</cast_shadows>
          <geometry>
            <box>
              <size>7.5 0.2 2.8</size>
            </box>
          </geometry>
          <material>
            <script>
              <uri>model://grey_wall/materials/scripts</uri>
              <uri>model://grey_wall/materials/textures</uri>
              <name>vrc/grey_wall</name>
            </script>
          </material>
        </visual>
        <velocity_decay>
          <linear>0</linear>
          <angular>0</angular>
        </velocity_decay>
        <self_collide>0</self_collide>
        <kinematic>0</kinematic>
        <gravity>1</gravity>
      </link>
      <pose>-6.53777 4 0 0 -0 0</pose>
    </model>
    <model name='grey_wall_12'>
      <static>1</static>
      <link name='link'>
        <pose>0 0 1.4 0 -0 0</pose>
        <collision name='collision'>
          <geometry>
            <box>
              <size>7.5 0.2 2.8</size>
            </box>
          </geometry>
          <max_contacts>10</max_contacts>
          <surface>
            <bounce/>
            <friction>
              <ode/>
            </friction>
            <contact>
              <ode/>
            </contact>
          </surface>
        </collision>
        <visual name='visual'>
          <cast_shadows>0</cast_shadows>
          <geometry>
            <box>
              <size>7.5 0.2 2.8</size>
            </box>
          </geometry>
          <material>
            <script>
              <uri>model://grey_wall/materials/scripts</uri>
              <uri>model://grey_wall/materials/textures</uri>
              <name>vrc/grey_wall</name>
            </script>
          </material>
        </visual>
        <velocity_decay>
          <linear>0</linear>
          <angular>0</angular>
        </velocity_decay>
        <self_collide>0</self_collide>
        <kinematic>0</kinematic>
        <gravity>1</gravity>
      </link>
      <pose>6.50522 4 0 0 -0 0</pose>
    </model>
    <model name='first_2015_trash_can'>
      <link name='link'>
        <inertial>
          <pose>0 0 0.3683 0 -0 0</pose>
          <mass>4.83076</mass>
          <inertia>
            <ixx>0.281534</ixx>
            <ixy>0</ixy>
            <ixz>0</ixz>
            <iyy>0.281534</iyy>
            <iyz>0</iyz>
            <izz>0.126223</izz>
          </inertia>
        </inertial>
        <visual name='visual'>
          <geometry>
            <mesh>
              <uri>model://first_2015_trash_can/meshes/trash_can.dae</uri>
            </mesh>
          </geometry>
        </visual>
        <collision name='collision'>
          <geometry>
            <mesh>
              <uri>model://first_2015_trash_can/meshes/trash_can.dae</uri>
            </mesh>
          </geometry>
          <max_contacts>10</max_contacts>
          <surface>
            <bounce/>
            <friction>
              <ode/>
            </friction>
            <contact>
              <ode/>
            </contact>
          </surface>
        </collision>
        <velocity_decay>
          <linear>0</linear>
          <angular>0</angular>
        </velocity_decay>
        <self_collide>0</self_collide>
        <kinematic>0</kinematic>
        <gravity>1</gravity>
      </link>
      <pose>-6 0 0 0 -0 0</pose>
      <static>0</static>
    </model>
    <model name='frc2016_drawbridge'>
      <link name='base'>
        <inertial>
          <mass>10</mass>
          <pose>0 0 1 0 -0 0</pose>
          <inertia>
            <ixx>3.64907</ixx>
            <ixy>0</ixy>
            <ixz>0</ixz>
            <iyy>4.67075</iyy>
            <iyz>0</iyz>
            <izz>1.66649</izz>
          </inertia>
        </inertial>
        <visual name='platform'>
          <pose>0 0 0.0425 0 -0 0</pose>
          <geometry>
            <box>
              <size>1.27 0.5969 0.085</size>
            </box>
          </geometry>
        </visual>
        <collision name='platform'>
          <pose>0 0 0.0425 0 -0 0</pose>
          <geometry>
            <box>
              <size>1.27 0.5969 0.085</size>
            </box>
          </geometry>
          <max_contacts>10</max_contacts>
          <surface>
            <bounce/>
            <friction>
              <ode/>
            </friction>
            <contact>
              <ode/>
            </contact>
          </surface>
        </collision>
        <visual name='right_wall'>
          <pose>0.55879 0.04444 0.889 0 -0 0</pose>
          <geometry>
            <box>
              <size>0.05715 0.45698 1.77165</size>
            </box>
          </geometry>
        </visual>
        <collision name='right_wall'>
          <pose>0.55879 0.04444 0.889 0 -0 0</pose>
          <geometry>
            <box>
              <size>0.05715 0.45698 1.77165</size>
            </box>
          </geometry>
          <max_contacts>10</max_contacts>
          <surface>
            <bounce/>
            <friction>
              <ode/>
            </friction>
            <contact>
              <ode/>
            </contact>
          </surface>
        </collision>
        <visual name='left_wall'>
          <pose>-0.55879 0.04444 0.889 0 -0 0</pose>
          <geometry>
            <box>
              <size>0.05715 0.45698 1.77165</size>
            </box>
          </geometry>
        </visual>
        <collision name='left_wall'>
          <pose>-0.55879 0.04444 0.889 0 -0 0</pose>
          <geometry>
            <box>
              <size>0.05715 0.45698 1.77165</size>
            </box>
          </geometry>
          <max_contacts>10</max_contacts>
          <surface>
            <bounce/>
            <friction>
              <ode/>
            </friction>
            <contact>
              <ode/>
            </contact>
          </surface>
        </collision>
        <visual name='front_upper_wall'>
          <pose>0 0.27611 1.84286 0 -0 0</pose>
          <geometry>
            <box>
              <size>1.1557 0.006347 0.254</size>
            </box>
          </geometry>
        </visual>
        <collision name='front_upper_wall'>
          <pose>0 0.27611 1.84286 0 -0 0</pose>
          <geometry>
            <box>
              <size>1.1557 0.006347 0.254</size>
            </box>
          </geometry>
          <max_contacts>10</max_contacts>
          <surface>
            <bounce/>
            <friction>
              <ode/>
            </friction>
            <contact>
              <ode/>
            </contact>
          </surface>
        </collision>
        <visual name='back_upper_wall'>
          <pose>0 -0.18722 1.84286 0 -0 0</pose>
          <geometry>
            <box>
              <size>1.1557 0.006347 0.254</size>
            </box>
          </geometry>
        </visual>
        <collision name='back_upper_wall'>
          <pose>0 -0.18722 1.84286 0 -0 0</pose>
          <geometry>
            <box>
              <size>1.1557 0.006347 0.254</size>
            </box>
          </geometry>
          <max_contacts>10</max_contacts>
          <surface>
            <bounce/>
            <friction>
              <ode/>
            </friction>
            <contact>
              <ode/>
            </contact>
          </surface>
        </collision>
        <velocity_decay>
          <linear>0</linear>
          <angular>0</angular>
        </velocity_decay>
        <self_collide>0</self_collide>
        <kinematic>0</kinematic>
        <gravity>1</gravity>
      </link>
      <link name='bridge'>
        <pose>0 0.28245 0.50577 0 -0 0</pose>
        <inertial>
          <mass>2</mass>
          <pose>0 -0.28245 -0.50577 0 -0 0</pose>
          <inertia>
            <ixx>0.139361</ixx>
            <ixy>0</ixy>
            <ixz>0</ixz>
            <iyy>0.357088</iyy>
            <iyz>0</iyz>
            <izz>0.217741</izz>
          </inertia>
        </inertial>
        <visual name='visual'>
          <geometry>
            <box>
              <size>1.14298 0.006347 0.9144</size>
            </box>
          </geometry>
          <material>
            <script>
              <name>Gazebo/WoodFloor</name>
              <uri>__default__</uri>
            </script>
          </material>
        </visual>
        <collision name='collision'>
          <geometry>
            <box>
              <size>1.14298 0.006347 0.9144</size>
            </box>
          </geometry>
          <max_contacts>10</max_contacts>
          <surface>
            <bounce/>
            <friction>
              <ode/>
            </friction>
            <contact>
              <ode/>
            </contact>
          </surface>
        </collision>
        <velocity_decay>
          <linear>0</linear>
          <angular>0</angular>
        </velocity_decay>
        <self_collide>0</self_collide>
        <kinematic>0</kinematic>
        <gravity>1</gravity>
      </link>
      <joint name='bridge_joint' type='revolute'>
        <pose>0 0 -0.4172 0 -0 0</pose>
        <parent>base</parent>
        <child>bridge</child>
        <axis>
          <xyz>1 0 0</xyz>
          <limit>
            <lower>-2</lower>
            <upper>0</upper>
          </limit>
        </axis>
      </joint>
      <pose>-2 0 0 0 -0 0</pose>
      <static>0</static>
    </model>
    <model name='first_2015_trash_can_0'>
      <link name='link'>
        <inertial>
          <pose>0 0 0.3683 0 -0 0</pose>
          <mass>4.83076</mass>
          <inertia>
            <ixx>0.281534</ixx>
            <ixy>0</ixy>
            <ixz>0</ixz>
            <iyy>0.281534</iyy>
            <iyz>0</iyz>
            <izz>0.126223</izz>
          </inertia>
        </inertial>
        <visual name='visual'>
          <geometry>
            <mesh>
              <uri>model://first_2015_trash_can/meshes/trash_can.dae</uri>
            </mesh>
          </geometry>
        </visual>
        <collision name='collision'>
          <geometry>
            <mesh>
              <uri>model://first_2015_trash_can/meshes/trash_can.dae</uri>
            </mesh>
          </geometry>
          <max_contacts>10</max_contacts>
          <surface>
            <bounce/>
            <friction>
              <ode/>
            </friction>
            <contact>
              <ode/>
            </contact>
          </surface>
        </collision>
        <velocity_decay>
          <linear>0</linear>
          <angular>0</angular>
        </velocity_decay>
        <self_collide>0</self_collide>
        <kinematic>0</kinematic>
        <gravity>1</gravity>
      </link>
      <pose>6 0 0 0 -0 0</pose>
      <static>0</static>
    </model>
    <model name='hinged_door'>
      <link name='frame'>
        <pose>0.06 -0.0005 0 0 -0 0</pose>
        <collision name='collision_1'>
          <pose>-0.025145 -0.03429 1.0541 0 -0 0</pose>
          <geometry>
            <box>
              <size>0.05029 0.06858 2.1082</size>
            </box>
          </geometry>
          <max_contacts>10</max_contacts>
          <surface>
            <bounce/>
            <friction>
              <ode/>
            </friction>
            <contact>
              <ode/>
            </contact>
          </surface>
        </collision>
        <collision name='collision_2'>
          <pose>-0.025145 0.95631 1.0541 0 -0 0</pose>
          <geometry>
            <box>
              <size>0.05029 0.06858 2.1082</size>
            </box>
          </geometry>
          <max_contacts>10</max_contacts>
          <surface>
            <bounce/>
            <friction>
              <ode/>
            </friction>
            <contact>
              <ode/>
            </contact>
          </surface>
        </collision>
        <collision name='collision_3'>
          <pose>-0.025145 0.46482 2.07137 0 -0 0</pose>
          <geometry>
            <box>
              <size>0.05029 0.92964 0.07366</size>
            </box>
          </geometry>
          <max_contacts>10</max_contacts>
          <surface>
            <bounce/>
            <friction>
              <ode/>
            </friction>
            <contact>
              <ode/>
            </contact>
          </surface>
        </collision>
        <visual name='visual'>
          <pose>0 -0.06858 0 0 -0 0</pose>
          <geometry>
            <mesh>
              <uri>model://hinged_door/meshes/frame.dae</uri>
            </mesh>
          </geometry>
        </visual>
        <velocity_decay>
          <linear>0</linear>
          <angular>0</angular>
        </velocity_decay>
        <self_collide>0</self_collide>
        <inertial>
          <inertia>
            <ixx>1</ixx>
            <ixy>0</ixy>
            <ixz>0</ixz>
            <iyy>1</iyy>
            <iyz>0</iyz>
            <izz>1</izz>
          </inertia>
          <mass>1</mass>
        </inertial>
        <kinematic>0</kinematic>
        <gravity>1</gravity>
      </link>
      <link name='door'>
        <pose>-0 0 2.04 3.14159 -0 1.57</pose>
        <inertial>
          <mass>41.3256</mass>
          <pose>0.4569 0.0349 1.016 0 -0 0</pose>
          <inertia>
            <ixx>14.2053</ixx>
            <ixy>0.0004</ixy>
            <ixz>0</ixz>
            <iyy>17.1997</iyy>
            <iyz>0</iyz>
            <izz>3.0298</izz>
          </inertia>
        </inertial>
        <collision name='collision'>
          <pose>0.4569 0.0349 1.016 0 -0 0</pose>
          <geometry>
            <box>
              <size>0.9144 0.04445 2.032</size>
            </box>
          </geometry>
          <max_contacts>10</max_contacts>
          <surface>
            <bounce/>
            <friction>
              <ode/>
            </friction>
            <contact>
              <ode/>
            </contact>
          </surface>
        </collision>
        <visual name='visual'>
          <pose>0 -0.06858 0 0 -0 0</pose>
          <geometry>
            <mesh>
              <uri>model://hinged_door/meshes/door.dae</uri>
            </mesh>
          </geometry>
        </visual>
        <velocity_decay>
          <linear>0</linear>
          <angular>0</angular>
        </velocity_decay>
        <self_collide>0</self_collide>
        <kinematic>0</kinematic>
        <gravity>1</gravity>
      </link>
      <link name='handles'>
        <pose>0 0.8 1.05 -3.14159 0.00159265 -1.57159</pose>
        <collision name='handle1_collision'>
          <pose>0.015 -0.015 0 -1.57 0 0</pose>
          <geometry>
            <mesh>
              <uri>model://door_handle/meshes/handle.dae</uri>
            </mesh>
          </geometry>
          <max_contacts>10</max_contacts>
          <surface>
            <bounce/>
            <friction>
              <ode/>
            </friction>
            <contact>
              <ode/>
            </contact>
          </surface>
        </collision>
        <visual name='handle1_visual'>
          <pose>0.015 -0.015 0 -1.57 0 0</pose>
          <geometry>
            <mesh>
              <uri>model://door_handle/meshes/handle.dae</uri>
            </mesh>
          </geometry>
        </visual>
        <collision name='handle2_collision'>
          <pose>0.015 -0.055 0 1.57 -0 0</pose>
          <geometry>
            <mesh>
              <uri>model://door_handle/meshes/handle.dae</uri>
            </mesh>
          </geometry>
          <max_contacts>10</max_contacts>
          <surface>
            <bounce/>
            <friction>
              <ode/>
            </friction>
            <contact>
              <ode/>
            </contact>
          </surface>
        </collision>
        <visual name='handle2_visual'>
          <pose>0.015 -0.055 0 1.57 -0 0</pose>
          <geometry>
            <mesh>
              <uri>model://door_handle/meshes/handle.dae</uri>
            </mesh>
          </geometry>
        </visual>
        <velocity_decay>
          <linear>0</linear>
          <angular>0</angular>
        </velocity_decay>
        <self_collide>0</self_collide>
        <inertial>
          <inertia>
            <ixx>1</ixx>
            <ixy>0</ixy>
            <ixz>0</ixz>
            <iyy>1</iyy>
            <iyz>0</iyz>
            <izz>1</izz>
          </inertia>
          <mass>1</mass>
        </inertial>
        <kinematic>0</kinematic>
        <gravity>1</gravity>
      </link>
      <joint name='handle' type='revolute'>
        <parent>door</parent>
        <child>handles</child>
        <pose>0.015 0 0 0 -0 0</pose>
        <axis>
          <xyz>1 0 0</xyz>
          <limit>
            <lower>0</lower>
            <upper>1.58</upper>
          </limit>
          <dynamics>
            <damping>1</damping>
            <friction>10</friction>
          </dynamics>
        </axis>
        <physics>
          <ode>
            <cfm_damping>1</cfm_damping>
            <limit>
              <cfm>0</cfm>
              <erp>0.2</erp>
            </limit>
          </ode>
        </physics>
      </joint>
      <joint name='hinge' type='revolute'>
        <parent>frame</parent>
        <child>door</child>
        <axis>
          <xyz>0 0 1</xyz>
          <limit>
            <lower>0</lower>
            <upper>1.58</upper>
          </limit>
          <dynamics>
            <damping>1</damping>
            <friction>1</friction>
          </dynamics>
        </axis>
        <physics>
          <ode>
            <cfm_damping>1</cfm_damping>
            <limit>
              <cfm>0</cfm>
              <erp>0.2</erp>
            </limit>
          </ode>
        </physics>
      </joint>
      <joint name='world_joint' type='revolute'>
        <child>frame</child>
        <parent>world</parent>
        <axis>
          <limit>
            <lower>0</lower>
            <upper>0</upper>
          </limit>
          <xyz>0 1 0</xyz>
          <dynamics>
            <damping>1</damping>
          </dynamics>
        </axis>
        <physics>
          <ode>
            <cfm_damping>1</cfm_damping>
            <limit>
              <cfm>0</cfm>
              <erp>0.2</erp>
            </limit>
          </ode>
        </physics>
      </joint>
      <pose>-4 -3 0 0 -0 0</pose>
      <static>0</static>
    </model>
    <model name='frc2016_drawbridge_0'>
      <link name='base'>
        <inertial>
          <mass>10</mass>
          <pose>0 0 1 0 -0 0</pose>
          <inertia>
            <ixx>3.64907</ixx>
            <ixy>0</ixy>
            <ixz>0</ixz>
            <iyy>4.67075</iyy>
            <iyz>0</iyz>
            <izz>1.66649</izz>
          </inertia>
        </inertial>
        <visual name='platform'>
          <pose>0 0 0.0425 0 -0 0</pose>
          <geometry>
            <box>
              <size>1.27 0.5969 0.085</size>
            </box>
          </geometry>
        </visual>
        <collision name='platform'>
          <pose>0 0 0.0425 0 -0 0</pose>
          <geometry>
            <box>
              <size>1.27 0.5969 0.085</size>
            </box>
          </geometry>
          <max_contacts>10</max_contacts>
          <surface>
            <bounce/>
            <friction>
              <ode/>
            </friction>
            <contact>
              <ode/>
            </contact>
          </surface>
        </collision>
        <visual name='right_wall'>
          <pose>0.55879 0.04444 0.889 0 -0 0</pose>
          <geometry>
            <box>
              <size>0.05715 0.45698 1.77165</size>
            </box>
          </geometry>
        </visual>
        <collision name='right_wall'>
          <pose>0.55879 0.04444 0.889 0 -0 0</pose>
          <geometry>
            <box>
              <size>0.05715 0.45698 1.77165</size>
            </box>
          </geometry>
          <max_contacts>10</max_contacts>
          <surface>
            <bounce/>
            <friction>
              <ode/>
            </friction>
            <contact>
              <ode/>
            </contact>
          </surface>
        </collision>
        <visual name='left_wall'>
          <pose>-0.55879 0.04444 0.889 0 -0 0</pose>
          <geometry>
            <box>
              <size>0.05715 0.45698 1.77165</size>
            </box>
          </geometry>
        </visual>
        <collision name='left_wall'>
          <pose>-0.55879 0.04444 0.889 0 -0 0</pose>
          <geometry>
            <box>
              <size>0.05715 0.45698 1.77165</size>
            </box>
          </geometry>
          <max_contacts>10</max_contacts>
          <surface>
            <bounce/>
            <friction>
              <ode/>
            </friction>
            <contact>
              <ode/>
            </contact>
          </surface>
        </collision>
        <visual name='front_upper_wall'>
          <pose>0 0.27611 1.84286 0 -0 0</pose>
          <geometry>
            <box>
              <size>1.1557 0.006347 0.254</size>
            </box>
          </geometry>
        </visual>
        <collision name='front_upper_wall'>
          <pose>0 0.27611 1.84286 0 -0 0</pose>
          <geometry>
            <box>
              <size>1.1557 0.006347 0.254</size>
            </box>
          </geometry>
          <max_contacts>10</max_contacts>
          <surface>
            <bounce/>
            <friction>
              <ode/>
            </friction>
            <contact>
              <ode/>
            </contact>
          </surface>
        </collision>
        <visual name='back_upper_wall'>
          <pose>0 -0.18722 1.84286 0 -0 0</pose>
          <geometry>
            <box>
              <size>1.1557 0.006347 0.254</size>
            </box>
          </geometry>
        </visual>
        <collision name='back_upper_wall'>
          <pose>0 -0.18722 1.84286 0 -0 0</pose>
          <geometry>
            <box>
              <size>1.1557 0.006347 0.254</size>
            </box>
          </geometry>
          <max_contacts>10</max_contacts>
          <surface>
            <bounce/>
            <friction>
              <ode/>
            </friction>
            <contact>
              <ode/>
            </contact>
          </surface>
        </collision>
        <velocity_decay>
          <linear>0</linear>
          <angular>0</angular>
        </velocity_decay>
        <self_collide>0</self_collide>
        <kinematic>0</kinematic>
        <gravity>1</gravity>
      </link>
      <link name='bridge'>
        <pose>0 0.28245 0.50577 0 -0 0</pose>
        <inertial>
          <mass>2</mass>
          <pose>0 -0.28245 -0.50577 0 -0 0</pose>
          <inertia>
            <ixx>0.139361</ixx>
            <ixy>0</ixy>
            <ixz>0</ixz>
            <iyy>0.357088</iyy>
            <iyz>0</iyz>
            <izz>0.217741</izz>
          </inertia>
        </inertial>
        <visual name='visual'>
          <geometry>
            <box>
              <size>1.14298 0.006347 0.9144</size>
            </box>
          </geometry>
          <material>
            <script>
              <name>Gazebo/WoodFloor</name>
              <uri>__default__</uri>
            </script>
          </material>
        </visual>
        <collision name='collision'>
          <geometry>
            <box>
              <size>1.14298 0.006347 0.9144</size>
            </box>
          </geometry>
          <max_contacts>10</max_contacts>
          <surface>
            <bounce/>
            <friction>
              <ode/>
            </friction>
            <contact>
              <ode/>
            </contact>
          </surface>
        </collision>
        <velocity_decay>
          <linear>0</linear>
          <angular>0</angular>
        </velocity_decay>
        <self_collide>0</self_collide>
        <kinematic>0</kinematic>
        <gravity>1</gravity>
      </link>
      <joint name='bridge_joint' type='revolute'>
        <pose>0 0 -0.4172 0 -0 0</pose>
        <parent>base</parent>
        <child>bridge</child>
        <axis>
          <xyz>1 0 0</xyz>
          <limit>
            <lower>-2</lower>
            <upper>0</upper>
          </limit>
        </axis>
      </joint>
      <pose>4 -2.50326 0 0 -0 0</pose>
      <static>0</static>
    </model>
    <model name='frc2016_portcullis'>
      <link name='base'>
        <inertial>
          <mass>50</mass>
          <pose>0 0 1.02941 0 -0 0</pose>
          <inertia>
            <ixx>3.81711</ixx>
            <ixy>0</ixy>
            <ixz>0</ixz>
            <iyy>4.87698</iyy>
            <iyz>0</iyz>
            <izz>1.6283</izz>
          </inertia>
        </inertial>
        <visual name='platform'>
          <pose>0 0 0.07284 0 -0 0</pose>
          <geometry>
            <box>
              <size>1.27 0.5842 0.003175</size>
            </box>
          </geometry>
        </visual>
        <collision name='platform'>
          <pose>0 0 0.07284 0 -0 0</pose>
          <geometry>
            <box>
              <size>1.27 0.5842 0.003175</size>
            </box>
          </geometry>
          <max_contacts>10</max_contacts>
          <surface>
            <bounce/>
            <friction>
              <ode/>
            </friction>
            <contact>
              <ode/>
            </contact>
          </surface>
        </collision>
        <visual name='left_column'>
          <pose>0.59284 0 0.99042 0 -0 0</pose>
          <geometry>
            <box>
              <size>0.08375 0.28575 1.83198</size>
            </box>
          </geometry>
        </visual>
        <collision name='left_column'>
          <pose>0.59284 0 0.99042 0 -0 0</pose>
          <geometry>
            <box>
              <size>0.08375 0.28575 1.83198</size>
            </box>
          </geometry>
          <max_contacts>10</max_contacts>
          <surface>
            <bounce/>
            <friction>
              <ode/>
            </friction>
            <contact>
              <ode/>
            </contact>
          </surface>
        </collision>
        <visual name='right_column'>
          <pose>-0.57759 0 0.99042 0 -0 0</pose>
          <geometry>
            <box>
              <size>0.08375 0.28575 1.83198</size>
            </box>
          </geometry>
        </visual>
        <collision name='right_column'>
          <pose>-0.57759 0 0.99042 0 -0 0</pose>
          <geometry>
            <box>
              <size>0.08375 0.28575 1.83198</size>
            </box>
          </geometry>
          <max_contacts>10</max_contacts>
          <surface>
            <bounce/>
            <friction>
              <ode/>
            </friction>
            <contact>
              <ode/>
            </contact>
          </surface>
        </collision>
        <visual name='top'>
          <pose>-0.00034 0 1.77722 0 -0 0</pose>
          <geometry>
            <box>
              <size>1.22962 0.28575 0.26657</size>
            </box>
          </geometry>
        </visual>
        <collision name='top'>
          <pose>-0.00034 0 1.77722 0 -0 0</pose>
          <geometry>
            <box>
              <size>1.22962 0.28575 0.26657</size>
            </box>
          </geometry>
          <max_contacts>10</max_contacts>
          <surface>
            <bounce/>
            <friction>
              <ode/>
            </friction>
            <contact>
              <ode/>
            </contact>
          </surface>
        </collision>
        <visual name='castor1'>
          <pose>-0.45651 -0.16234 0.03272 0 -0 0</pose>
          <geometry>
            <sphere>
              <radius>0.03272</radius>
            </sphere>
          </geometry>
        </visual>
        <collision name='castor1'>
          <pose>-0.45651 -0.16234 0.03272 0 -0 0</pose>
          <geometry>
            <sphere>
              <radius>0.03272</radius>
            </sphere>
          </geometry>
          <max_contacts>10</max_contacts>
          <surface>
            <bounce/>
            <friction>
              <ode/>
            </friction>
            <contact>
              <ode/>
            </contact>
          </surface>
        </collision>
        <visual name='castor2'>
          <pose>-0.27883 0.21836 0.03272 0 -0 0</pose>
          <geometry>
            <sphere>
              <radius>0.03272</radius>
            </sphere>
          </geometry>
        </visual>
        <collision name='castor2'>
          <pose>-0.27883 0.21836 0.03272 0 -0 0</pose>
          <geometry>
            <sphere>
              <radius>0.03272</radius>
            </sphere>
          </geometry>
          <max_contacts>10</max_contacts>
          <surface>
            <bounce/>
            <friction>
              <ode/>
            </friction>
            <contact>
              <ode/>
            </contact>
          </surface>
        </collision>
        <visual name='castor3'>
          <pose>0.28083 0.21906 0.03272 0 -0 0</pose>
          <geometry>
            <sphere>
              <radius>0.03272</radius>
            </sphere>
          </geometry>
        </visual>
        <collision name='castor3'>
          <pose>0.28083 0.21906 0.03272 0 -0 0</pose>
          <geometry>
            <sphere>
              <radius>0.03272</radius>
            </sphere>
          </geometry>
          <max_contacts>10</max_contacts>
          <surface>
            <bounce/>
            <friction>
              <ode/>
            </friction>
            <contact>
              <ode/>
            </contact>
          </surface>
        </collision>
        <visual name='castor4'>
          <pose>0.45871 -0.16186 0.03272 0 -0 0</pose>
          <geometry>
            <sphere>
              <radius>0.03272</radius>
            </sphere>
          </geometry>
        </visual>
        <collision name='castor4'>
          <pose>0.45871 -0.16186 0.03272 0 -0 0</pose>
          <geometry>
            <sphere>
              <radius>0.03272</radius>
            </sphere>
          </geometry>
          <max_contacts>10</max_contacts>
          <surface>
            <bounce/>
            <friction>
              <ode/>
            </friction>
            <contact>
              <ode/>
            </contact>
          </surface>
        </collision>
        <velocity_decay>
          <linear>0</linear>
          <angular>0</angular>
        </velocity_decay>
        <self_collide>0</self_collide>
        <kinematic>0</kinematic>
        <gravity>1</gravity>
      </link>
      <link name='gate'>
        <pose>-0.0287 0.02885 0.93327 0 -0 0</pose>
        <inertial>
          <mass>2</mass>
          <pose>0 0 0 0 -0 0</pose>
          <inertia>
            <ixx>3.81711</ixx>
            <ixy>0</ixy>
            <ixz>0</ixz>
            <iyy>4.87698</iyy>
            <iyz>0</iyz>
            <izz>1.6283</izz>
          </inertia>
        </inertial>
        <collision name='collision'>
          <geometry>
            <box>
              <size>1.1938 0.02496 1.45732</size>
            </box>
          </geometry>
          <max_contacts>10</max_contacts>
          <surface>
            <bounce/>
            <friction>
              <ode/>
            </friction>
            <contact>
              <ode/>
            </contact>
          </surface>
        </collision>
        <visual name='horz_1'>
          <pose>0 0 -0.70326 0 -0 0</pose>
          <geometry>
            <box>
              <size>1.1938 0.02496 0.0508</size>
            </box>
          </geometry>
          <material>
            <ambient>0.4 0.4 0.4 1</ambient>
            <diffuse>0.4 0.4 0.4 1</diffuse>
          </material>
        </visual>
        <visual name='horz_2'>
          <pose>0 0 -0.44926 0 -0 0</pose>
          <geometry>
            <box>
              <size>1.1938 0.02496 0.0508</size>
            </box>
          </geometry>
          <material>
            <ambient>0.4 0.4 0.4 1</ambient>
            <diffuse>0.4 0.4 0.4 1</diffuse>
          </material>
        </visual>
        <visual name='horz_3'>
          <pose>0 0 -0.14517 0 -0 0</pose>
          <geometry>
            <box>
              <size>1.1938 0.02496 0.0508</size>
            </box>
          </geometry>
          <material>
            <ambient>0.4 0.4 0.4 1</ambient>
            <diffuse>0.4 0.4 0.4 1</diffuse>
          </material>
        </visual>
        <visual name='horz_4'>
          <pose>0 0 0.16034 0 -0 0</pose>
          <geometry>
            <box>
              <size>1.1938 0.02496 0.0508</size>
            </box>
          </geometry>
          <material>
            <ambient>0.4 0.4 0.4 1</ambient>
            <diffuse>0.4 0.4 0.4 1</diffuse>
          </material>
        </visual>
        <visual name='horz_5'>
          <pose>0 0 0.46514 0 -0 0</pose>
          <geometry>
            <box>
              <size>1.1938 0.02496 0.0508</size>
            </box>
          </geometry>
          <material>
            <ambient>0.4 0.4 0.4 1</ambient>
            <diffuse>0.4 0.4 0.4 1</diffuse>
          </material>
        </visual>
        <visual name='horz_6'>
          <pose>0 0 0.72994 0 -0 0</pose>
          <geometry>
            <box>
              <size>1.1938 0.02496 0.0508</size>
            </box>
          </geometry>
          <material>
            <ambient>0.4 0.4 0.4 1</ambient>
            <diffuse>0.4 0.4 0.4 1</diffuse>
          </material>
        </visual>
        <visual name='vert_1'>
          <pose>-0.58448 0 0 0 -0 0</pose>
          <geometry>
            <box>
              <size>0.02495 0.02496 1.45732</size>
            </box>
          </geometry>
          <material>
            <ambient>0.4 0.4 0.4 1</ambient>
            <diffuse>0.4 0.4 0.4 1</diffuse>
          </material>
        </visual>
        <visual name='vert_2'>
          <pose>-0.38128 0 0 0 -0 0</pose>
          <geometry>
            <box>
              <size>0.0508 0.02496 1.45732</size>
            </box>
          </geometry>
          <material>
            <ambient>0.4 0.4 0.4 1</ambient>
            <diffuse>0.4 0.4 0.4 1</diffuse>
          </material>
        </visual>
        <visual name='vert_3'>
          <pose>-0.12728 0 0 0 -0 0</pose>
          <geometry>
            <box>
              <size>0.0508 0.02496 1.45732</size>
            </box>
          </geometry>
          <material>
            <ambient>0.4 0.4 0.4 1</ambient>
            <diffuse>0.4 0.4 0.4 1</diffuse>
          </material>
        </visual>
        <visual name='vert_4'>
          <pose>0.12672 0 0 0 -0 0</pose>
          <geometry>
            <box>
              <size>0.0508 0.02496 1.45732</size>
            </box>
          </geometry>
          <material>
            <ambient>0.4 0.4 0.4 1</ambient>
            <diffuse>0.4 0.4 0.4 1</diffuse>
          </material>
        </visual>
        <visual name='vert_5'>
          <pose>0.38072 0 0 0 -0 0</pose>
          <geometry>
            <box>
              <size>0.0508 0.02496 1.45732</size>
            </box>
          </geometry>
          <material>
            <ambient>0.4 0.4 0.4 1</ambient>
            <diffuse>0.4 0.4 0.4 1</diffuse>
          </material>
        </visual>
        <visual name='vert_6'>
          <pose>0.58392 0 0 0 -0 0</pose>
          <geometry>
            <box>
              <size>0.02495 0.02496 1.45732</size>
            </box>
          </geometry>
          <material>
            <ambient>0.4 0.4 0.4 1</ambient>
            <diffuse>0.4 0.4 0.4 1</diffuse>
          </material>
        </visual>
        <velocity_decay>
          <linear>0</linear>
          <angular>0</angular>
        </velocity_decay>
        <self_collide>0</self_collide>
        <kinematic>0</kinematic>
        <gravity>1</gravity>
      </link>
      <joint name='joint' type='prismatic'>
        <parent>base</parent>
        <child>gate</child>
        <axis>
          <xyz>0 0 1</xyz>
          <limit>
            <lower>0</lower>
            <upper>1</upper>
          </limit>
        </axis>
      </joint>
      <pose>-6 -5 0 0 -0 0</pose>
      <static>0</static>
    </model>
    <model name='first_2015_trash_can_1'>
      <link name='link'>
        <inertial>
          <pose>0 0 0.3683 0 -0 0</pose>
          <mass>4.83076</mass>
          <inertia>
            <ixx>0.281534</ixx>
            <ixy>0</ixy>
            <ixz>0</ixz>
            <iyy>0.281534</iyy>
            <iyz>0</iyz>
            <izz>0.126223</izz>
          </inertia>
        </inertial>
        <visual name='visual'>
          <geometry>
            <mesh>
              <uri>model://first_2015_trash_can/meshes/trash_can.dae</uri>
            </mesh>
          </geometry>
        </visual>
        <collision name='collision'>
          <geometry>
            <mesh>
              <uri>model://first_2015_trash_can/meshes/trash_can.dae</uri>
            </mesh>
          </geometry>
          <max_contacts>10</max_contacts>
          <surface>
            <bounce/>
            <friction>
              <ode/>
            </friction>
            <contact>
              <ode/>
            </contact>
          </surface>
        </collision>
        <velocity_decay>
          <linear>0</linear>
          <angular>0</angular>
        </velocity_decay>
        <self_collide>0</self_collide>
        <kinematic>0</kinematic>
        <gravity>1</gravity>
      </link>
      <pose>0 -5 0 0 -0 0</pose>
      <static>0</static>
    </model>
    <model name='first_2015_trash_can_2'>
      <link name='link'>
        <inertial>
          <pose>0 0 0.3683 0 -0 0</pose>
          <mass>4.83076</mass>
          <inertia>
            <ixx>0.281534</ixx>
            <ixy>0</ixy>
            <ixz>0</ixz>
            <iyy>0.281534</iyy>
            <iyz>0</iyz>
            <izz>0.126223</izz>
          </inertia>
        </inertial>
        <visual name='visual'>
          <geometry>
            <mesh>
              <uri>model://first_2015_trash_can/meshes/trash_can.dae</uri>
            </mesh>
          </geometry>
        </visual>
        <collision name='collision'>
          <geometry>
            <mesh>
              <uri>model://first_2015_trash_can/meshes/trash_can.dae</uri>
            </mesh>
          </geometry>
          <max_contacts>10</max_contacts>
          <surface>
            <bounce/>
            <friction>
              <ode/>
            </friction>
            <contact>
              <ode/>
            </contact>
          </surface>
        </collision>
        <velocity_decay>
          <linear>0</linear>
          <angular>0</angular>
        </velocity_decay>
        <self_collide>0</self_collide>
        <kinematic>0</kinematic>
        <gravity>1</gravity>
      </link>
      <pose>3 -7 0 0 -0 0</pose>
      <static>0</static>
    </model>
    <model name='wheel_valve_large_wall'>
      <static>0</static>
      <link name='wall::link'>
        <collision name='collision'>
          <pose>0.6096 0.00476 1.2192 0 -0 0</pose>
          <geometry>
            <box>
              <size>1.2192 0.00952 2.4384</size>
            </box>
          </geometry>
          <max_contacts>10</max_contacts>
          <surface>
            <bounce/>
            <friction>
              <ode/>
            </friction>
            <contact>
              <ode/>
            </contact>
          </surface>
        </collision>
        <visual name='visual'>
          <pose>-0.00453619 -0.00357175 0 0 -0 0</pose>
          <geometry>
            <mesh>
              <uri>model://drc_practice_valve_wall/meshes/five_dice_wall.dae</uri>
            </mesh>
          </geometry>
        </visual>
        <velocity_decay>
          <linear>0</linear>
          <angular>0</angular>
        </velocity_decay>
        <pose>0 0 0 0 -0 0</pose>
        <self_collide>0</self_collide>
        <inertial>
          <inertia>
            <ixx>1</ixx>
            <ixy>0</ixy>
            <ixz>0</ixz>
            <iyy>1</iyy>
            <iyz>0</iyz>
            <izz>1</izz>
          </inertia>
          <mass>1</mass>
        </inertial>
        <kinematic>0</kinematic>
        <gravity>1</gravity>
      </link>
      <joint name='wall-joint' type='revolute'>
        <parent>world</parent>
        <child>wall::link</child>
        <axis>
          <xyz>0 0 1</xyz>
          <limit>
            <lower>0</lower>
            <upper>0</upper>
          </limit>
        </axis>
      </joint>
      <link name='valve_0::handle'>
        <pose>0.919587 0.0208 0.285 0 -0 0</pose>
        <inertial>
          <mass>7.8219</mass>
          <pose>0 -0.0615 0 0 -0 0</pose>
          <inertia>
            <ixx>0.0695</ixx>
            <ixy>0</ixy>
            <ixz>0</ixz>
            <iyy>0.1349</iyy>
            <iyz>0</iyz>
            <izz>0.0695</izz>
          </inertia>
        </inertial>
        <collision name='collision'>
          <geometry>
            <mesh>
              <uri>model://drc_practice_wheel_valve_large/meshes/wheel_valve_large.dae</uri>
            </mesh>
          </geometry>
          <surface>
            <bounce>
              <restitution_coefficient>0.01</restitution_coefficient>
              <threshold>5</threshold>
            </bounce>
            <friction>
              <ode>
                <mu>5</mu>
                <mu2>5</mu2>
              </ode>
            </friction>
            <contact>
              <ode>
                <soft_cfm>0.01</soft_cfm>
                <kp>1e+06</kp>
                <kd>100000</kd>
                <max_vel>0.01</max_vel>
                <min_depth>0.001</min_depth>
              </ode>
            </contact>
          </surface>
          <max_contacts>10</max_contacts>
        </collision>
        <visual name='visual'>
          <geometry>
            <mesh>
              <uri>model://drc_practice_wheel_valve_large/meshes/wheel_valve_large.dae</uri>
            </mesh>
          </geometry>
        </visual>
        <velocity_decay>
          <linear>0</linear>
          <angular>0</angular>
        </velocity_decay>
        <self_collide>0</self_collide>
        <kinematic>0</kinematic>
        <gravity>1</gravity>
      </link>
      <joint name='valve_0::joint' type='revolute'>
        <parent>world</parent>
        <child>valve_0::handle</child>
        <axis>
          <xyz>0 1 0</xyz>
          <limit>
            <lower>-12.56</lower>
            <upper>12.56</upper>
          </limit>
          <dynamics>
            <damping>1000</damping>
            <friction>100</friction>
          </dynamics>
        </axis>
        <physics>
          <ode>
            <cfm_damping>1</cfm_damping>
            <limit>
              <cfm>0</cfm>
              <erp>0.2</erp>
            </limit>
          </ode>
        </physics>
      </joint>
      <link name='valve_1::handle'>
        <pose>0.919587 0.0208 0.8954 0 -0 0</pose>
        <inertial>
          <mass>7.8219</mass>
          <pose>0 -0.0615 0 0 -0 0</pose>
          <inertia>
            <ixx>0.0695</ixx>
            <ixy>0</ixy>
            <ixz>0</ixz>
            <iyy>0.1349</iyy>
            <iyz>0</iyz>
            <izz>0.0695</izz>
          </inertia>
        </inertial>
        <collision name='collision'>
          <geometry>
            <mesh>
              <uri>model://drc_practice_wheel_valve_large/meshes/wheel_valve_large.dae</uri>
            </mesh>
          </geometry>
          <surface>
            <bounce>
              <restitution_coefficient>0.01</restitution_coefficient>
              <threshold>5</threshold>
            </bounce>
            <friction>
              <ode>
                <mu>5</mu>
                <mu2>5</mu2>
              </ode>
            </friction>
            <contact>
              <ode>
                <soft_cfm>0.01</soft_cfm>
                <kp>1e+06</kp>
                <kd>100000</kd>
                <max_vel>0.01</max_vel>
                <min_depth>0.001</min_depth>
              </ode>
            </contact>
          </surface>
          <max_contacts>10</max_contacts>
        </collision>
        <visual name='visual'>
          <geometry>
            <mesh>
              <uri>model://drc_practice_wheel_valve_large/meshes/wheel_valve_large.dae</uri>
            </mesh>
          </geometry>
        </visual>
        <velocity_decay>
          <linear>0</linear>
          <angular>0</angular>
        </velocity_decay>
        <self_collide>0</self_collide>
        <kinematic>0</kinematic>
        <gravity>1</gravity>
      </link>
      <joint name='valve_1::joint' type='revolute'>
        <parent>world</parent>
        <child>valve_1::handle</child>
        <axis>
          <xyz>0 1 0</xyz>
          <limit>
            <lower>-12.56</lower>
            <upper>12.56</upper>
          </limit>
          <dynamics>
            <damping>1000</damping>
            <friction>100</friction>
          </dynamics>
        </axis>
        <physics>
          <ode>
            <cfm_damping>1</cfm_damping>
            <limit>
              <cfm>0</cfm>
              <erp>0.2</erp>
            </limit>
          </ode>
        </physics>
      </joint>
      <link name='valve_2::handle'>
        <pose>0.919587 0.0208 1.5058 0 -0 0</pose>
        <inertial>
          <mass>7.8219</mass>
          <pose>0 -0.0615 0 0 -0 0</pose>
          <inertia>
            <ixx>0.0695</ixx>
            <ixy>0</ixy>
            <ixz>0</ixz>
            <iyy>0.1349</iyy>
            <iyz>0</iyz>
            <izz>0.0695</izz>
          </inertia>
        </inertial>
        <collision name='collision'>
          <geometry>
            <mesh>
              <uri>model://drc_practice_wheel_valve_large/meshes/wheel_valve_large.dae</uri>
            </mesh>
          </geometry>
          <surface>
            <bounce>
              <restitution_coefficient>0.01</restitution_coefficient>
              <threshold>5</threshold>
            </bounce>
            <friction>
              <ode>
                <mu>5</mu>
                <mu2>5</mu2>
              </ode>
            </friction>
            <contact>
              <ode>
                <soft_cfm>0.01</soft_cfm>
                <kp>1e+06</kp>
                <kd>100000</kd>
                <max_vel>0.01</max_vel>
                <min_depth>0.001</min_depth>
              </ode>
            </contact>
          </surface>
          <max_contacts>10</max_contacts>
        </collision>
        <visual name='visual'>
          <geometry>
            <mesh>
              <uri>model://drc_practice_wheel_valve_large/meshes/wheel_valve_large.dae</uri>
            </mesh>
          </geometry>
        </visual>
        <velocity_decay>
          <linear>0</linear>
          <angular>0</angular>
        </velocity_decay>
        <self_collide>0</self_collide>
        <kinematic>0</kinematic>
        <gravity>1</gravity>
      </link>
      <joint name='valve_2::joint' type='revolute'>
        <parent>world</parent>
        <child>valve_2::handle</child>
        <axis>
          <xyz>0 1 0</xyz>
          <limit>
            <lower>-12.56</lower>
            <upper>12.56</upper>
          </limit>
          <dynamics>
            <damping>1000</damping>
            <friction>100</friction>
          </dynamics>
        </axis>
        <physics>
          <ode>
            <cfm_damping>1</cfm_damping>
            <limit>
              <cfm>0</cfm>
              <erp>0.2</erp>
            </limit>
          </ode>
        </physics>
      </joint>
      <link name='valve_3::handle'>
        <pose>0.919587 0.0208 2.1162 0 -0 0</pose>
        <inertial>
          <mass>7.8219</mass>
          <pose>0 -0.0615 0 0 -0 0</pose>
          <inertia>
            <ixx>0.0695</ixx>
            <ixy>0</ixy>
            <ixz>0</ixz>
            <iyy>0.1349</iyy>
            <iyz>0</iyz>
            <izz>0.0695</izz>
          </inertia>
        </inertial>
        <collision name='collision'>
          <geometry>
            <mesh>
              <uri>model://drc_practice_wheel_valve_large/meshes/wheel_valve_large.dae</uri>
            </mesh>
          </geometry>
          <surface>
            <bounce>
              <restitution_coefficient>0.01</restitution_coefficient>
              <threshold>5</threshold>
            </bounce>
            <friction>
              <ode>
                <mu>5</mu>
                <mu2>5</mu2>
              </ode>
            </friction>
            <contact>
              <ode>
                <soft_cfm>0.01</soft_cfm>
                <kp>1e+06</kp>
                <kd>100000</kd>
                <max_vel>0.01</max_vel>
                <min_depth>0.001</min_depth>
              </ode>
            </contact>
          </surface>
          <max_contacts>10</max_contacts>
        </collision>
        <visual name='visual'>
          <geometry>
            <mesh>
              <uri>model://drc_practice_wheel_valve_large/meshes/wheel_valve_large.dae</uri>
            </mesh>
          </geometry>
        </visual>
        <velocity_decay>
          <linear>0</linear>
          <angular>0</angular>
        </velocity_decay>
        <self_collide>0</self_collide>
        <kinematic>0</kinematic>
        <gravity>1</gravity>
      </link>
      <joint name='valve_3::joint' type='revolute'>
        <parent>world</parent>
        <child>valve_3::handle</child>
        <axis>
          <xyz>0 1 0</xyz>
          <limit>
            <lower>-12.56</lower>
            <upper>12.56</upper>
          </limit>
          <dynamics>
            <damping>1000</damping>
            <friction>100</friction>
          </dynamics>
        </axis>
        <physics>
          <ode>
            <cfm_damping>1</cfm_damping>
            <limit>
              <cfm>0</cfm>
              <erp>0.2</erp>
            </limit>
          </ode>
        </physics>
      </joint>
      <link name='valve_4::handle'>
        <pose>0.614335 0.0208 0.5896 0 -0 0</pose>
        <inertial>
          <mass>7.8219</mass>
          <pose>0 -0.0615 0 0 -0 0</pose>
          <inertia>
            <ixx>0.0695</ixx>
            <ixy>0</ixy>
            <ixz>0</ixz>
            <iyy>0.1349</iyy>
            <iyz>0</iyz>
            <izz>0.0695</izz>
          </inertia>
        </inertial>
        <collision name='collision'>
          <geometry>
            <mesh>
              <uri>model://drc_practice_wheel_valve_large/meshes/wheel_valve_large.dae</uri>
            </mesh>
          </geometry>
          <surface>
            <bounce>
              <restitution_coefficient>0.01</restitution_coefficient>
              <threshold>5</threshold>
            </bounce>
            <friction>
              <ode>
                <mu>5</mu>
                <mu2>5</mu2>
              </ode>
            </friction>
            <contact>
              <ode>
                <soft_cfm>0.01</soft_cfm>
                <kp>1e+06</kp>
                <kd>100000</kd>
                <max_vel>0.01</max_vel>
                <min_depth>0.001</min_depth>
              </ode>
            </contact>
          </surface>
          <max_contacts>10</max_contacts>
        </collision>
        <visual name='visual'>
          <geometry>
            <mesh>
              <uri>model://drc_practice_wheel_valve_large/meshes/wheel_valve_large.dae</uri>
            </mesh>
          </geometry>
        </visual>
        <velocity_decay>
          <linear>0</linear>
          <angular>0</angular>
        </velocity_decay>
        <self_collide>0</self_collide>
        <kinematic>0</kinematic>
        <gravity>1</gravity>
      </link>
      <joint name='valve_4::joint' type='revolute'>
        <parent>world</parent>
        <child>valve_4::handle</child>
        <axis>
          <xyz>0 1 0</xyz>
          <limit>
            <lower>-12.56</lower>
            <upper>12.56</upper>
          </limit>
          <dynamics>
            <damping>1000</damping>
            <friction>100</friction>
          </dynamics>
        </axis>
        <physics>
          <ode>
            <cfm_damping>1</cfm_damping>
            <limit>
              <cfm>0</cfm>
              <erp>0.2</erp>
            </limit>
          </ode>
        </physics>
      </joint>
      <link name='valve_5::handle'>
        <pose>0.614335 0.0208 1.2 0 -0 0</pose>
        <inertial>
          <mass>7.8219</mass>
          <pose>0 -0.0615 0 0 -0 0</pose>
          <inertia>
            <ixx>0.0695</ixx>
            <ixy>0</ixy>
            <ixz>0</ixz>
            <iyy>0.1349</iyy>
            <iyz>0</iyz>
            <izz>0.0695</izz>
          </inertia>
        </inertial>
        <collision name='collision'>
          <geometry>
            <mesh>
              <uri>model://drc_practice_wheel_valve_large/meshes/wheel_valve_large.dae</uri>
            </mesh>
          </geometry>
          <surface>
            <bounce>
              <restitution_coefficient>0.01</restitution_coefficient>
              <threshold>5</threshold>
            </bounce>
            <friction>
              <ode>
                <mu>5</mu>
                <mu2>5</mu2>
              </ode>
            </friction>
            <contact>
              <ode>
                <soft_cfm>0.01</soft_cfm>
                <kp>1e+06</kp>
                <kd>100000</kd>
                <max_vel>0.01</max_vel>
                <min_depth>0.001</min_depth>
              </ode>
            </contact>
          </surface>
          <max_contacts>10</max_contacts>
        </collision>
        <visual name='visual'>
          <geometry>
            <mesh>
              <uri>model://drc_practice_wheel_valve_large/meshes/wheel_valve_large.dae</uri>
            </mesh>
          </geometry>
        </visual>
        <velocity_decay>
          <linear>0</linear>
          <angular>0</angular>
        </velocity_decay>
        <self_collide>0</self_collide>
        <kinematic>0</kinematic>
        <gravity>1</gravity>
      </link>
      <joint name='valve_5::joint' type='revolute'>
        <parent>world</parent>
        <child>valve_5::handle</child>
        <axis>
          <xyz>0 1 0</xyz>
          <limit>
            <lower>-12.56</lower>
            <upper>12.56</upper>
          </limit>
          <dynamics>
            <damping>1000</damping>
            <friction>100</friction>
          </dynamics>
        </axis>
        <physics>
          <ode>
            <cfm_damping>1</cfm_damping>
            <limit>
              <cfm>0</cfm>
              <erp>0.2</erp>
            </limit>
          </ode>
        </physics>
      </joint>
      <link name='valve_6::handle'>
        <pose>0.614335 0.0208 1.8104 0 -0 0</pose>
        <inertial>
          <mass>7.8219</mass>
          <pose>0 -0.0615 0 0 -0 0</pose>
          <inertia>
            <ixx>0.0695</ixx>
            <ixy>0</ixy>
            <ixz>0</ixz>
            <iyy>0.1349</iyy>
            <iyz>0</iyz>
            <izz>0.0695</izz>
          </inertia>
        </inertial>
        <collision name='collision'>
          <geometry>
            <mesh>
              <uri>model://drc_practice_wheel_valve_large/meshes/wheel_valve_large.dae</uri>
            </mesh>
          </geometry>
          <surface>
            <bounce>
              <restitution_coefficient>0.01</restitution_coefficient>
              <threshold>5</threshold>
            </bounce>
            <friction>
              <ode>
                <mu>5</mu>
                <mu2>5</mu2>
              </ode>
            </friction>
            <contact>
              <ode>
                <soft_cfm>0.01</soft_cfm>
                <kp>1e+06</kp>
                <kd>100000</kd>
                <max_vel>0.01</max_vel>
                <min_depth>0.001</min_depth>
              </ode>
            </contact>
          </surface>
          <max_contacts>10</max_contacts>
        </collision>
        <visual name='visual'>
          <geometry>
            <mesh>
              <uri>model://drc_practice_wheel_valve_large/meshes/wheel_valve_large.dae</uri>
            </mesh>
          </geometry>
        </visual>
        <velocity_decay>
          <linear>0</linear>
          <angular>0</angular>
        </velocity_decay>
        <self_collide>0</self_collide>
        <kinematic>0</kinematic>
        <gravity>1</gravity>
      </link>
      <joint name='valve_6::joint' type='revolute'>
        <parent>world</parent>
        <child>valve_6::handle</child>
        <axis>
          <xyz>0 1 0</xyz>
          <limit>
            <lower>-12.56</lower>
            <upper>12.56</upper>
          </limit>
          <dynamics>
            <damping>1000</damping>
            <friction>100</friction>
          </dynamics>
        </axis>
        <physics>
          <ode>
            <cfm_damping>1</cfm_damping>
            <limit>
              <cfm>0</cfm>
              <erp>0.2</erp>
            </limit>
          </ode>
        </physics>
      </joint>
      <link name='valve_7::handle'>
        <pose>0.309083 0.0208 0.285 0 -0 0</pose>
        <inertial>
          <mass>7.8219</mass>
          <pose>0 -0.0615 0 0 -0 0</pose>
          <inertia>
            <ixx>0.0695</ixx>
            <ixy>0</ixy>
            <ixz>0</ixz>
            <iyy>0.1349</iyy>
            <iyz>0</iyz>
            <izz>0.0695</izz>
          </inertia>
        </inertial>
        <collision name='collision'>
          <geometry>
            <mesh>
              <uri>model://drc_practice_wheel_valve_large/meshes/wheel_valve_large.dae</uri>
            </mesh>
          </geometry>
          <surface>
            <bounce>
              <restitution_coefficient>0.01</restitution_coefficient>
              <threshold>5</threshold>
            </bounce>
            <friction>
              <ode>
                <mu>5</mu>
                <mu2>5</mu2>
              </ode>
            </friction>
            <contact>
              <ode>
                <soft_cfm>0.01</soft_cfm>
                <kp>1e+06</kp>
                <kd>100000</kd>
                <max_vel>0.01</max_vel>
                <min_depth>0.001</min_depth>
              </ode>
            </contact>
          </surface>
          <max_contacts>10</max_contacts>
        </collision>
        <visual name='visual'>
          <geometry>
            <mesh>
              <uri>model://drc_practice_wheel_valve_large/meshes/wheel_valve_large.dae</uri>
            </mesh>
          </geometry>
        </visual>
        <velocity_decay>
          <linear>0</linear>
          <angular>0</angular>
        </velocity_decay>
        <self_collide>0</self_collide>
        <kinematic>0</kinematic>
        <gravity>1</gravity>
      </link>
      <joint name='valve_7::joint' type='revolute'>
        <parent>world</parent>
        <child>valve_7::handle</child>
        <axis>
          <xyz>0 1 0</xyz>
          <limit>
            <lower>-12.56</lower>
            <upper>12.56</upper>
          </limit>
          <dynamics>
            <damping>1000</damping>
            <friction>100</friction>
          </dynamics>
        </axis>
        <physics>
          <ode>
            <cfm_damping>1</cfm_damping>
            <limit>
              <cfm>0</cfm>
              <erp>0.2</erp>
            </limit>
          </ode>
        </physics>
      </joint>
      <link name='valve_8::handle'>
        <pose>0.309083 0.0208 0.8954 0 -0 0</pose>
        <inertial>
          <mass>7.8219</mass>
          <pose>0 -0.0615 0 0 -0 0</pose>
          <inertia>
            <ixx>0.0695</ixx>
            <ixy>0</ixy>
            <ixz>0</ixz>
            <iyy>0.1349</iyy>
            <iyz>0</iyz>
            <izz>0.0695</izz>
          </inertia>
        </inertial>
        <collision name='collision'>
          <geometry>
            <mesh>
              <uri>model://drc_practice_wheel_valve_large/meshes/wheel_valve_large.dae</uri>
            </mesh>
          </geometry>
          <surface>
            <bounce>
              <restitution_coefficient>0.01</restitution_coefficient>
              <threshold>5</threshold>
            </bounce>
            <friction>
              <ode>
                <mu>5</mu>
                <mu2>5</mu2>
              </ode>
            </friction>
            <contact>
              <ode>
                <soft_cfm>0.01</soft_cfm>
                <kp>1e+06</kp>
                <kd>100000</kd>
                <max_vel>0.01</max_vel>
                <min_depth>0.001</min_depth>
              </ode>
            </contact>
          </surface>
          <max_contacts>10</max_contacts>
        </collision>
        <visual name='visual'>
          <geometry>
            <mesh>
              <uri>model://drc_practice_wheel_valve_large/meshes/wheel_valve_large.dae</uri>
            </mesh>
          </geometry>
        </visual>
        <velocity_decay>
          <linear>0</linear>
          <angular>0</angular>
        </velocity_decay>
        <self_collide>0</self_collide>
        <kinematic>0</kinematic>
        <gravity>1</gravity>
      </link>
      <joint name='valve_8::joint' type='revolute'>
        <parent>world</parent>
        <child>valve_8::handle</child>
        <axis>
          <xyz>0 1 0</xyz>
          <limit>
            <lower>-12.56</lower>
            <upper>12.56</upper>
          </limit>
          <dynamics>
            <damping>1000</damping>
            <friction>100</friction>
          </dynamics>
        </axis>
        <physics>
          <ode>
            <cfm_damping>1</cfm_damping>
            <limit>
              <cfm>0</cfm>
              <erp>0.2</erp>
            </limit>
          </ode>
        </physics>
      </joint>
      <link name='valve_9::handle'>
        <pose>0.309083 0.0208 1.5058 0 -0 0</pose>
        <inertial>
          <mass>7.8219</mass>
          <pose>0 -0.0615 0 0 -0 0</pose>
          <inertia>
            <ixx>0.0695</ixx>
            <ixy>0</ixy>
            <ixz>0</ixz>
            <iyy>0.1349</iyy>
            <iyz>0</iyz>
            <izz>0.0695</izz>
          </inertia>
        </inertial>
        <collision name='collision'>
          <geometry>
            <mesh>
              <uri>model://drc_practice_wheel_valve_large/meshes/wheel_valve_large.dae</uri>
            </mesh>
          </geometry>
          <surface>
            <bounce>
              <restitution_coefficient>0.01</restitution_coefficient>
              <threshold>5</threshold>
            </bounce>
            <friction>
              <ode>
                <mu>5</mu>
                <mu2>5</mu2>
              </ode>
            </friction>
            <contact>
              <ode>
                <soft_cfm>0.01</soft_cfm>
                <kp>1e+06</kp>
                <kd>100000</kd>
                <max_vel>0.01</max_vel>
                <min_depth>0.001</min_depth>
              </ode>
            </contact>
          </surface>
          <max_contacts>10</max_contacts>
        </collision>
        <visual name='visual'>
          <geometry>
            <mesh>
              <uri>model://drc_practice_wheel_valve_large/meshes/wheel_valve_large.dae</uri>
            </mesh>
          </geometry>
        </visual>
        <velocity_decay>
          <linear>0</linear>
          <angular>0</angular>
        </velocity_decay>
        <self_collide>0</self_collide>
        <kinematic>0</kinematic>
        <gravity>1</gravity>
      </link>
      <joint name='valve_9::joint' type='revolute'>
        <parent>world</parent>
        <child>valve_9::handle</child>
        <axis>
          <xyz>0 1 0</xyz>
          <limit>
            <lower>-12.56</lower>
            <upper>12.56</upper>
          </limit>
          <dynamics>
            <damping>1000</damping>
            <friction>100</friction>
          </dynamics>
        </axis>
        <physics>
          <ode>
            <cfm_damping>1</cfm_damping>
            <limit>
              <cfm>0</cfm>
              <erp>0.2</erp>
            </limit>
          </ode>
        </physics>
      </joint>
      <link name='valve_10::handle'>
        <pose>0.309083 0.0208 2.1162 0 -0 0</pose>
        <inertial>
          <mass>7.8219</mass>
          <pose>0 -0.0615 0 0 -0 0</pose>
          <inertia>
            <ixx>0.0695</ixx>
            <ixy>0</ixy>
            <ixz>0</ixz>
            <iyy>0.1349</iyy>
            <iyz>0</iyz>
            <izz>0.0695</izz>
          </inertia>
        </inertial>
        <collision name='collision'>
          <geometry>
            <mesh>
              <uri>model://drc_practice_wheel_valve_large/meshes/wheel_valve_large.dae</uri>
            </mesh>
          </geometry>
          <surface>
            <bounce>
              <restitution_coefficient>0.01</restitution_coefficient>
              <threshold>5</threshold>
            </bounce>
            <friction>
              <ode>
                <mu>5</mu>
                <mu2>5</mu2>
              </ode>
            </friction>
            <contact>
              <ode>
                <soft_cfm>0.01</soft_cfm>
                <kp>1e+06</kp>
                <kd>100000</kd>
                <max_vel>0.01</max_vel>
                <min_depth>0.001</min_depth>
              </ode>
            </contact>
          </surface>
          <max_contacts>10</max_contacts>
        </collision>
        <visual name='visual'>
          <geometry>
            <mesh>
              <uri>model://drc_practice_wheel_valve_large/meshes/wheel_valve_large.dae</uri>
            </mesh>
          </geometry>
        </visual>
        <velocity_decay>
          <linear>0</linear>
          <angular>0</angular>
        </velocity_decay>
        <self_collide>0</self_collide>
        <kinematic>0</kinematic>
        <gravity>1</gravity>
      </link>
      <joint name='valve_10::joint' type='revolute'>
        <parent>world</parent>
        <child>valve_10::handle</child>
        <axis>
          <xyz>0 1 0</xyz>
          <limit>
            <lower>-12.56</lower>
            <upper>12.56</upper>
          </limit>
          <dynamics>
            <damping>1000</damping>
            <friction>100</friction>
          </dynamics>
        </axis>
        <physics>
          <ode>
            <cfm_damping>1</cfm_damping>
            <limit>
              <cfm>0</cfm>
              <erp>0.2</erp>
            </limit>
          </ode>
        </physics>
      </joint>
      <pose>1.59014 0 0 0 -0 0</pose>
    </model>
    <model name='drc_practice_white_jersey_barrier'>
      <static>1</static>
      <link name='link'>
        <visual name='visual'>
          <geometry>
            <mesh>
              <uri>model://drc_practice_white_jersey_barrier/meshes/jersey_barrier.dae</uri>
            </mesh>
          </geometry>
        </visual>
        <collision name='collision'>
          <geometry>
            <mesh>
              <uri>model://drc_practice_white_jersey_barrier/meshes/jersey_barrier.dae</uri>
            </mesh>
          </geometry>
          <max_contacts>10</max_contacts>
          <surface>
            <bounce/>
            <friction>
              <ode/>
            </friction>
            <contact>
              <ode/>
            </contact>
          </surface>
        </collision>
        <velocity_decay>
          <linear>0</linear>
          <angular>0</angular>
        </velocity_decay>
        <self_collide>0</self_collide>
        <kinematic>0</kinematic>
        <gravity>1</gravity>
      </link>
      <pose>-6 1 0 0 -0 0</pose>
    </model>
    <model name='unit_box_1'>
      <pose>-7 8.45126 0.5 0 -0 0</pose>
      <link name='link'>
        <inertial>
          <mass>1</mass>
          <inertia>
            <ixx>1</ixx>
            <ixy>0</ixy>
            <ixz>0</ixz>
            <iyy>1</iyy>
            <iyz>0</iyz>
            <izz>1</izz>
          </inertia>
        </inertial>
        <collision name='collision'>
          <geometry>
            <box>
              <size>1 1 1</size>
            </box>
          </geometry>
          <max_contacts>10</max_contacts>
          <surface>
            <bounce/>
            <friction>
              <ode/>
            </friction>
            <contact>
              <ode/>
            </contact>
          </surface>
        </collision>
        <visual name='visual'>
          <geometry>
            <box>
              <size>1 1 1</size>
            </box>
          </geometry>
          <material>
            <script>
              <uri>file://media/materials/scripts/gazebo.material</uri>
              <name>Gazebo/Grey</name>
            </script>
          </material>
        </visual>
        <velocity_decay>
          <linear>0</linear>
          <angular>0</angular>
        </velocity_decay>
        <self_collide>0</self_collide>
        <kinematic>0</kinematic>
        <gravity>1</gravity>
      </link>
      <static>0</static>
    </model>
    <model name='unit_box_2'>
      <pose>4 5 0.5 0 -0 0</pose>
      <link name='link'>
        <inertial>
          <mass>1</mass>
          <inertia>
            <ixx>1</ixx>
            <ixy>0</ixy>
            <ixz>0</ixz>
            <iyy>1</iyy>
            <iyz>0</iyz>
            <izz>1</izz>
          </inertia>
        </inertial>
        <collision name='collision'>
          <geometry>
            <box>
              <size>1 1 1</size>
            </box>
          </geometry>
          <max_contacts>10</max_contacts>
          <surface>
            <bounce/>
            <friction>
              <ode/>
            </friction>
            <contact>
              <ode/>
            </contact>
          </surface>
        </collision>
        <visual name='visual'>
          <geometry>
            <box>
              <size>1 1 1</size>
            </box>
          </geometry>
          <material>
            <script>
              <uri>file://media/materials/scripts/gazebo.material</uri>
              <name>Gazebo/Grey</name>
            </script>
          </material>
        </visual>
        <velocity_decay>
          <linear>0</linear>
          <angular>0</angular>
        </velocity_decay>
        <self_collide>0</self_collide>
        <kinematic>0</kinematic>
        <gravity>1</gravity>
      </link>
      <static>0</static>
    </model>
    <gui fullscreen='0'>
      <camera name='user_camera'>
        <pose>-0.983105 -11.6717 44.3608 0 1.3058 1.56743</pose>
        <view_controller>orbit</view_controller>
      </camera>
    </gui>
    <model name='unit_box_1_0'>
      <pose>-2 2 0.5 0 -0 0</pose>
      <link name='link'>
        <inertial>
          <mass>1</mass>
          <inertia>
            <ixx>1</ixx>
            <ixy>0</ixy>
            <ixz>0</ixz>
            <iyy>1</iyy>
            <iyz>0</iyz>
            <izz>1</izz>
          </inertia>
        </inertial>
        <collision name='collision'>
          <geometry>
            <box>
              <size>1 1 1</size>
            </box>
          </geometry>
          <max_contacts>10</max_contacts>
          <surface>
            <bounce/>
            <friction>
              <ode/>
            </friction>
            <contact>
              <ode/>
            </contact>
          </surface>
        </collision>
        <visual name='visual'>
          <geometry>
            <box>
              <size>1 1 1</size>
            </box>
          </geometry>
          <material>
            <script>
              <uri>file://media/materials/scripts/gazebo.material</uri>
              <name>Gazebo/Grey</name>
            </script>
          </material>
        </visual>
        <velocity_decay>
          <linear>0</linear>
          <angular>0</angular>
        </velocity_decay>
        <self_collide>0</self_collide>
        <kinematic>0</kinematic>
        <gravity>1</gravity>
      </link>
      <static>0</static>
    </model>
    <model name='unit_box_2_0'>
      <pose>-6 -6.42643 0.5 0 -0 0</pose>
      <link name='link'>
        <inertial>
          <mass>1</mass>
          <inertia>
            <ixx>1</ixx>
            <ixy>0</ixy>
            <ixz>0</ixz>
            <iyy>1</iyy>
            <iyz>0</iyz>
            <izz>1</izz>
          </inertia>
        </inertial>
        <collision name='collision'>
          <geometry>
            <box>
              <size>1 1 1</size>
            </box>
          </geometry>
          <max_contacts>10</max_contacts>
          <surface>
            <bounce/>
            <friction>
              <ode/>
            </friction>
            <contact>
              <ode/>
            </contact>
          </surface>
        </collision>
        <visual name='visual'>
          <geometry>
            <box>
              <size>1 1 1</size>
            </box>
          </geometry>
          <material>
            <script>
              <uri>file://media/materials/scripts/gazebo.material</uri>
              <name>Gazebo/Grey</name>
            </script>
          </material>
        </visual>
        <velocity_decay>
          <linear>0</linear>
          <angular>0</angular>
        </velocity_decay>
        <self_collide>0</self_collide>
        <kinematic>0</kinematic>
        <gravity>1</gravity>
      </link>
      <static>0</static>
    </model>
    <model name='unit_box_3'>
      <pose>7 -5 0.5 0 -0 0</pose>
      <link name='link'>
        <inertial>
          <mass>1</mass>
          <inertia>
            <ixx>1</ixx>
            <ixy>0</ixy>
            <ixz>0</ixz>
            <iyy>1</iyy>
            <iyz>0</iyz>
            <izz>1</izz>
          </inertia>
        </inertial>
        <collision name='collision'>
          <geometry>
            <box>
              <size>1 1 1</size>
            </box>
          </geometry>
          <max_contacts>10</max_contacts>
          <surface>
            <bounce/>
            <friction>
              <ode/>
            </friction>
            <contact>
              <ode/>
            </contact>
          </surface>
        </collision>
        <visual name='visual'>
          <geometry>
            <box>
              <size>1 1 1</size>
            </box>
          </geometry>
          <material>
            <script>
              <uri>file://media/materials/scripts/gazebo.material</uri>
              <name>Gazebo/Grey</name>
            </script>
          </material>
        </visual>
        <velocity_decay>
          <linear>0</linear>
          <angular>0</angular>
        </velocity_decay>
        <self_collide>0</self_collide>
        <kinematic>0</kinematic>
        <gravity>1</gravity>
      </link>
      <static>0</static>
    </model>
    <model name='unit_cylinder_1'>
      <pose>6 -5.58512 0.5 0 -0 0</pose>
      <link name='link'>
        <inertial>
          <mass>1</mass>
          <inertia>
            <ixx>1</ixx>
            <ixy>0</ixy>
            <ixz>0</ixz>
            <iyy>1</iyy>
            <iyz>0</iyz>
            <izz>1</izz>
          </inertia>
        </inertial>
        <collision name='collision'>
          <geometry>
            <cylinder>
              <radius>0.5</radius>
              <length>1</length>
            </cylinder>
          </geometry>
          <max_contacts>10</max_contacts>
          <surface>
            <bounce/>
            <friction>
              <ode/>
            </friction>
            <contact>
              <ode/>
            </contact>
          </surface>
        </collision>
        <visual name='visual'>
          <geometry>
            <cylinder>
              <radius>0.5</radius>
              <length>1</length>
            </cylinder>
          </geometry>
          <material>
            <script>
              <uri>file://media/materials/scripts/gazebo.material</uri>
              <name>Gazebo/Grey</name>
            </script>
          </material>
        </visual>
        <velocity_decay>
          <linear>0</linear>
          <angular>0</angular>
        </velocity_decay>
        <self_collide>0</self_collide>
        <kinematic>0</kinematic>
        <gravity>1</gravity>
      </link>
      <static>0</static>
    </model>
    <model name='unit_box_4'>
      <pose>7 -6 0.5 0 -0 0</pose>
      <link name='link'>
        <inertial>
          <mass>1</mass>
          <inertia>
            <ixx>1</ixx>
            <ixy>0</ixy>
            <ixz>0</ixz>
            <iyy>1</iyy>
            <iyz>0</iyz>
            <izz>1</izz>
          </inertia>
        </inertial>
        <collision name='collision'>
          <geometry>
            <box>
              <size>1 1 1</size>
            </box>
          </geometry>
          <max_contacts>10</max_contacts>
          <surface>
            <bounce/>
            <friction>
              <ode/>
            </friction>
            <contact>
              <ode/>
            </contact>
          </surface>
        </collision>
        <visual name='visual'>
          <geometry>
            <box>
              <size>1 1 1</size>
            </box>
          </geometry>
          <material>
            <script>
              <uri>file://media/materials/scripts/gazebo.material</uri>
              <name>Gazebo/Grey</name>
            </script>
          </material>
        </visual>
        <velocity_decay>
          <linear>0</linear>
          <angular>0</angular>
        </velocity_decay>
        <self_collide>0</self_collide>
        <kinematic>0</kinematic>
        <gravity>1</gravity>
      </link>
      <static>0</static>
    </model>
    <model name='unit_box_5'>
      <pose>6 -6.46772 0.5 0 -0 0</pose>
      <link name='link'>
        <inertial>
          <mass>1</mass>
          <inertia>
            <ixx>1</ixx>
            <ixy>0</ixy>
            <ixz>0</ixz>
            <iyy>1</iyy>
            <iyz>0</iyz>
            <izz>1</izz>
          </inertia>
        </inertial>
        <collision name='collision'>
          <geometry>
            <box>
              <size>1 1 1</size>
            </box>
          </geometry>
          <max_contacts>10</max_contacts>
          <surface>
            <bounce/>
            <friction>
              <ode/>
            </friction>
            <contact>
              <ode/>
            </contact>
          </surface>
        </collision>
        <visual name='visual'>
          <geometry>
            <box>
              <size>1 1 1</size>
            </box>
          </geometry>
          <material>
            <script>
              <uri>file://media/materials/scripts/gazebo.material</uri>
              <name>Gazebo/Grey</name>
            </script>
          </material>
        </visual>
        <velocity_decay>
          <linear>0</linear>
          <angular>0</angular>
        </velocity_decay>
        <self_collide>0</self_collide>
        <kinematic>0</kinematic>
        <gravity>1</gravity>
      </link>
      <static>0</static>
    </model>
    <model name='unit_cylinder_2'>
      <pose>2 -7 0.5 0 -0 0</pose>
      <link name='link'>
        <inertial>
          <mass>1</mass>
          <inertia>
            <ixx>1</ixx>
            <ixy>0</ixy>
            <ixz>0</ixz>
            <iyy>1</iyy>
            <iyz>0</iyz>
            <izz>1</izz>
          </inertia>
        </inertial>
        <collision name='collision'>
          <geometry>
            <cylinder>
              <radius>0.5</radius>
              <length>1</length>
            </cylinder>
          </geometry>
          <max_contacts>10</max_contacts>
          <surface>
            <bounce/>
            <friction>
              <ode/>
            </friction>
            <contact>
              <ode/>
            </contact>
          </surface>
        </collision>
        <visual name='visual'>
          <geometry>
            <cylinder>
              <radius>0.5</radius>
              <length>1</length>
            </cylinder>
          </geometry>
          <material>
            <script>
              <uri>file://media/materials/scripts/gazebo.material</uri>
              <name>Gazebo/Grey</name>
            </script>
          </material>
        </visual>
        <velocity_decay>
          <linear>0</linear>
          <angular>0</angular>
        </velocity_decay>
        <self_collide>0</self_collide>
        <kinematic>0</kinematic>
        <gravity>1</gravity>
      </link>
      <static>0</static>
    </model>
    <model name='unit_cylinder_3'>
      <pose>6.44555 1 0.5 0 -0 0</pose>
      <link name='link'>
        <inertial>
          <mass>1</mass>
          <inertia>
            <ixx>1</ixx>
            <ixy>0</ixy>
            <ixz>0</ixz>
            <iyy>1</iyy>
            <iyz>0</iyz>
            <izz>1</izz>
          </inertia>
        </inertial>
        <collision name='collision'>
          <geometry>
            <cylinder>
              <radius>0.5</radius>
              <length>1</length>
            </cylinder>
          </geometry>
          <max_contacts>10</max_contacts>
          <surface>
            <bounce/>
            <friction>
              <ode/>
            </friction>
            <contact>
              <ode/>
            </contact>
          </surface>
        </collision>
        <visual name='visual'>
          <geometry>
            <cylinder>
              <radius>0.5</radius>
              <length>1</length>
            </cylinder>
          </geometry>
          <material>
            <script>
              <uri>file://media/materials/scripts/gazebo.material</uri>
              <name>Gazebo/Grey</name>
            </script>
          </material>
        </visual>
        <velocity_decay>
          <linear>0</linear>
          <angular>0</angular>
        </velocity_decay>
        <self_collide>0</self_collide>
        <kinematic>0</kinematic>
        <gravity>1</gravity>
      </link>
      <static>0</static>
    </model>
    <model name='unit_cylinder_4'>
      <pose>0 4 0.5 0 -0 0</pose>
      <link name='link'>
        <inertial>
          <mass>1</mass>
          <inertia>
            <ixx>1</ixx>
            <ixy>0</ixy>
            <ixz>0</ixz>
            <iyy>1</iyy>
            <iyz>0</iyz>
            <izz>1</izz>
          </inertia>
        </inertial>
        <collision name='collision'>
          <geometry>
            <cylinder>
              <radius>0.5</radius>
              <length>1</length>
            </cylinder>
          </geometry>
          <max_contacts>10</max_contacts>
          <surface>
            <bounce/>
            <friction>
              <ode/>
            </friction>
            <contact>
              <ode/>
            </contact>
          </surface>
        </collision>
        <visual name='visual'>
          <geometry>
            <cylinder>
              <radius>0.5</radius>
              <length>1</length>
            </cylinder>
          </geometry>
          <material>
            <script>
              <uri>file://media/materials/scripts/gazebo.material</uri>
              <name>Gazebo/Grey</name>
            </script>
          </material>
        </visual>
        <velocity_decay>
          <linear>0</linear>
          <angular>0</angular>
        </velocity_decay>
        <self_collide>0</self_collide>
        <kinematic>0</kinematic>
        <gravity>1</gravity>
      </link>
      <static>0</static>
    </model>
    <model name='unit_box_6'>
      <pose>-3.43088 -3 0.5 0 -0 0</pose>
      <link name='link'>
        <inertial>
          <mass>1</mass>
          <inertia>
            <ixx>1</ixx>
            <ixy>0</ixy>
            <ixz>0</ixz>
            <iyy>1</iyy>
            <iyz>0</iyz>
            <izz>1</izz>
          </inertia>
        </inertial>
        <collision name='collision'>
          <geometry>
            <box>
              <size>1 1 1</size>
            </box>
          </geometry>
          <max_contacts>10</max_contacts>
          <surface>
            <bounce/>
            <friction>
              <ode/>
            </friction>
            <contact>
              <ode/>
            </contact>
          </surface>
        </collision>
        <visual name='visual'>
          <geometry>
            <box>
              <size>1 1 1</size>
            </box>
          </geometry>
          <material>
            <script>
              <uri>file://media/materials/scripts/gazebo.material</uri>
              <name>Gazebo/Grey</name>
            </script>
          </material>
        </visual>
        <velocity_decay>
          <linear>0</linear>
          <angular>0</angular>
        </velocity_decay>
        <self_collide>0</self_collide>
        <kinematic>0</kinematic>
        <gravity>1</gravity>
      </link>
      <static>0</static>
    </model>
    <model name='unit_box_7'>
      <pose>-10 -9.50943 0.5 0 -0 0</pose>
      <link name='link'>
        <inertial>
          <mass>1</mass>
          <inertia>
            <ixx>1</ixx>
            <ixy>0</ixy>
            <ixz>0</ixz>
            <iyy>1</iyy>
            <iyz>0</iyz>
            <izz>1</izz>
          </inertia>
        </inertial>
        <collision name='collision'>
          <geometry>
            <box>
              <size>1 1 1</size>
            </box>
          </geometry>
          <max_contacts>10</max_contacts>
          <surface>
            <bounce/>
            <friction>
              <ode/>
            </friction>
            <contact>
              <ode/>
            </contact>
          </surface>
        </collision>
        <visual name='visual'>
          <geometry>
            <box>
              <size>1 1 1</size>
            </box>
          </geometry>
          <material>
            <script>
              <uri>file://media/materials/scripts/gazebo.material</uri>
              <name>Gazebo/Grey</name>
            </script>
          </material>
        </visual>
        <velocity_decay>
          <linear>0</linear>
          <angular>0</angular>
        </velocity_decay>
        <self_collide>0</self_collide>
        <kinematic>0</kinematic>
        <gravity>1</gravity>
      </link>
      <static>0</static>
    </model>
    <model name='unit_cylinder_5'>
      <pose>-9 -9 0.5 0 -0 0</pose>
      <link name='link'>
        <inertial>
          <mass>1</mass>
          <inertia>
            <ixx>1</ixx>
            <ixy>0</ixy>
            <ixz>0</ixz>
            <iyy>1</iyy>
            <iyz>0</iyz>
            <izz>1</izz>
          </inertia>
        </inertial>
        <collision name='collision'>
          <geometry>
            <cylinder>
              <radius>0.5</radius>
              <length>1</length>
            </cylinder>
          </geometry>
          <max_contacts>10</max_contacts>
          <surface>
            <bounce/>
            <friction>
              <ode/>
            </friction>
            <contact>
              <ode/>
            </contact>
          </surface>
        </collision>
        <visual name='visual'>
          <geometry>
            <cylinder>
              <radius>0.5</radius>
              <length>1</length>
            </cylinder>
          </geometry>
          <material>
            <script>
              <uri>file://media/materials/scripts/gazebo.material</uri>
              <name>Gazebo/Grey</name>
            </script>
          </material>
        </visual>
        <velocity_decay>
          <linear>0</linear>
          <angular>0</angular>
        </velocity_decay>
        <self_collide>0</self_collide>
        <kinematic>0</kinematic>
        <gravity>1</gravity>
      </link>
      <static>0</static>
    </model>
    <model name='unit_box_8'>
      <pose>3.41973 0 0.5 0 -0 0</pose>
      <link name='link'>
        <inertial>
          <mass>1</mass>
          <inertia>
            <ixx>1</ixx>
            <ixy>0</ixy>
            <ixz>0</ixz>
            <iyy>1</iyy>
            <iyz>0</iyz>
            <izz>1</izz>
          </inertia>
        </inertial>
        <collision name='collision'>
          <geometry>
            <box>
              <size>1 1 1</size>
            </box>
          </geometry>
          <max_contacts>10</max_contacts>
          <surface>
            <bounce/>
            <friction>
              <ode/>
            </friction>
            <contact>
              <ode/>
            </contact>
          </surface>
        </collision>
        <visual name='visual'>
          <geometry>
            <box>
              <size>1 1 1</size>
            </box>
          </geometry>
          <material>
            <script>
              <uri>file://media/materials/scripts/gazebo.material</uri>
              <name>Gazebo/Grey</name>
            </script>
          </material>
        </visual>
        <velocity_decay>
          <linear>0</linear>
          <angular>0</angular>
        </velocity_decay>
        <self_collide>0</self_collide>
        <kinematic>0</kinematic>
        <gravity>1</gravity>
      </link>
      <static>0</static>
    </model>
    <model name='unit_cylinder_6'>
      <pose>4 6 0.5 0 -0 0</pose>
      <link name='link'>
        <inertial>
          <mass>1</mass>
          <inertia>
            <ixx>1</ixx>
            <ixy>0</ixy>
            <ixz>0</ixz>
            <iyy>1</iyy>
            <iyz>0</iyz>
            <izz>1</izz>
          </inertia>
        </inertial>
        <collision name='collision'>
          <geometry>
            <cylinder>
              <radius>0.5</radius>
              <length>1</length>
            </cylinder>
          </geometry>
          <max_contacts>10</max_contacts>
          <surface>
            <bounce/>
            <friction>
              <ode/>
            </friction>
            <contact>
              <ode/>
            </contact>
          </surface>
        </collision>
        <visual name='visual'>
          <geometry>
            <cylinder>
              <radius>0.5</radius>
              <length>1</length>
            </cylinder>
          </geometry>
          <material>
            <script>
              <uri>file://media/materials/scripts/gazebo.material</uri>
              <name>Gazebo/Grey</name>
            </script>
          </material>
        </visual>
        <velocity_decay>
          <linear>0</linear>
          <angular>0</angular>
        </velocity_decay>
        <self_collide>0</self_collide>
        <kinematic>0</kinematic>
        <gravity>1</gravity>
      </link>
      <static>0</static>
    </model>
    <model name='unit_cylinder_7'>
      <pose>7 9 0.5 0 -0 0</pose>
      <link name='link'>
        <inertial>
          <mass>1</mass>
          <inertia>
            <ixx>1</ixx>
            <ixy>0</ixy>
            <ixz>0</ixz>
            <iyy>1</iyy>
            <iyz>0</iyz>
            <izz>1</izz>
          </inertia>
        </inertial>
        <collision name='collision'>
          <geometry>
            <cylinder>
              <radius>0.5</radius>
              <length>1</length>
            </cylinder>
          </geometry>
          <max_contacts>10</max_contacts>
          <surface>
            <bounce/>
            <friction>
              <ode/>
            </friction>
            <contact>
              <ode/>
            </contact>
          </surface>
        </collision>
        <visual name='visual'>
          <geometry>
            <cylinder>
              <radius>0.5</radius>
              <length>1</length>
            </cylinder>
          </geometry>
          <material>
            <script>
              <uri>file://media/materials/scripts/gazebo.material</uri>
              <name>Gazebo/Grey</name>
            </script>
          </material>
        </visual>
        <velocity_decay>
          <linear>0</linear>
          <angular>0</angular>
        </velocity_decay>
        <self_collide>0</self_collide>
        <kinematic>0</kinematic>
        <gravity>1</gravity>
      </link>
      <static>0</static>
    </model>
  </world>
</sdf>
