<sdf version='1.4'>
  <world name='default'>
    <light name='sun' type='directional'>
      <cast_shadows>1</cast_shadows>
      <pose>0 0 10 0 -0 0</pose>
      <diffuse>0.8 0.8 0.8 1</diffuse>
      <specular>0.2 0.2 0.2 1</specular>
      <attenuation>
        <range>1000</range>
        <constant>0.9</constant>
        <linear>0.01</linear>
        <quadratic>0.001</quadratic>
      </attenuation>
      <direction>-0.5 0.1 -0.9</direction>
    </light>
    <model name='ground_plane'>
      <static>1</static>
      <link name='link'>
        <collision name='collision'>
          <geometry>
            <plane>
              <normal>0 0 1</normal>
              <size>100 100</size>
            </plane>
          </geometry>
          <surface>
            <friction>
              <ode>
                <mu>100</mu>
                <mu2>50</mu2>
              </ode>
            </friction>
            <bounce/>
            <contact>
              <ode/>
            </contact>
          </surface>
          <max_contacts>10</max_contacts>
        </collision>
        <visual name='visual'>
          <cast_shadows>0</cast_shadows>
          <geometry>
            <plane>
              <normal>0 0 1</normal>
              <size>100 100</size>
            </plane>
          </geometry>
          <material>
            <script>
              <uri>file://media/materials/scripts/gazebo.material</uri>
              <name>Gazebo/Grey</name>
            </script>
          </material>
        </visual>
        <velocity_decay>
          <linear>0</linear>
          <angular>0</angular>
        </velocity_decay>
        <self_collide>0</self_collide>
        <kinematic>0</kinematic>
        <gravity>1</gravity>
      </link>
    </model>
    <physics type='ode'>
      <max_step_size>0.001</max_step_size>
      <real_time_factor>1</real_time_factor>
      <real_time_update_rate>0</real_time_update_rate>
      <gravity>0 0 -9.8</gravity>
    </physics>
    <scene>
      <ambient>0.4 0.4 0.4 1</ambient>
      <background>0.7 0.7 0.7 1</background>
      <shadows>1</shadows>
    </scene>
    <spherical_coordinates>
      <surface_model>EARTH_WGS84</surface_model>
      <latitude_deg>0</latitude_deg>
      <longitude_deg>0</longitude_deg>
      <elevation>0</elevation>
      <heading_deg>0</heading_deg>
    </spherical_coordinates>
    <model name='grey_wall'>
      <static>1</static>
      <link name='link'>
        <pose>0 0 1.4 0 -0 0</pose>
        <collision name='collision'>
          <geometry>
            <box>
              <size>7.5 0.2 2.8</size>
            </box>
          </geometry>
          <max_contacts>10</max_contacts>
          <surface>
            <bounce/>
            <friction>
              <ode/>
            </friction>
            <contact>
              <ode/>
            </contact>
          </surface>
        </collision>
        <visual name='visual'>
          <cast_shadows>0</cast_shadows>
          <geometry>
            <box>
              <size>7.5 0.2 2.8</size>
            </box>
          </geometry>
          <material>
            <script>
              <uri>model://grey_wall/materials/scripts</uri>
              <uri>model://grey_wall/materials/textures</uri>
              <name>vrc/grey_wall</name>
            </script>
          </material>
        </visual>
        <velocity_decay>
          <linear>0</linear>
          <angular>0</angular>
        </velocity_decay>
        <self_collide>0</self_collide>
        <kinematic>0</kinematic>
        <gravity>1</gravity>
      </link>
      <pose>-5.45844 9 0 0 -0 0</pose>
    </model>
    <model name='grey_wall_0'>
      <static>1</static>
      <link name='link'>
        <pose>0 0 1.4 0 -0 0</pose>
        <collision name='collision'>
          <geometry>
            <box>
              <size>7.5 0.2 2.8</size>
            </box>
          </geometry>
          <max_contacts>10</max_contacts>
          <surface>
            <bounce/>
            <friction>
              <ode/>
            </friction>
            <contact>
              <ode/>
            </contact>
          </surface>
        </collision>
        <visual name='visual'>
          <cast_shadows>0</cast_shadows>
          <geometry>
            <box>
              <size>7.5 0.2 2.8</size>
            </box>
          </geometry>
          <material>
            <script>
              <uri>model://grey_wall/materials/scripts</uri>
              <uri>model://grey_wall/materials/textures</uri>
              <name>vrc/grey_wall</name>
            </script>
          </material>
        </visual>
        <velocity_decay>
          <linear>0</linear>
          <angular>0</angular>
        </velocity_decay>
        <self_collide>0</self_collide>
        <kinematic>0</kinematic>
        <gravity>1</gravity>
      </link>
      <pose>2 9 0 0 -0 0</pose>
    </model>
    <model name='grey_wall_1'>
      <static>1</static>
      <link name='link'>
        <pose>0 0 1.4 0 -0 0</pose>
        <collision name='collision'>
          <geometry>
            <box>
              <size>7.5 0.2 2.8</size>
            </box>
          </geometry>
          <max_contacts>10</max_contacts>
          <surface>
            <bounce/>
            <friction>
              <ode/>
            </friction>
            <contact>
              <ode/>
            </contact>
          </surface>
        </collision>
        <visual name='visual'>
          <cast_shadows>0</cast_shadows>
          <geometry>
            <box>
              <size>7.5 0.2 2.8</size>
            </box>
          </geometry>
          <material>
            <script>
              <uri>model://grey_wall/materials/scripts</uri>
              <uri>model://grey_wall/materials/textures</uri>
              <name>vrc/grey_wall</name>
            </script>
          </material>
        </visual>
        <velocity_decay>
          <linear>0</linear>
          <angular>0</angular>
        </velocity_decay>
        <self_collide>0</self_collide>
        <kinematic>0</kinematic>
        <gravity>1</gravity>
      </link>
      <pose>6.55945 9 0 0 -0 0</pose>
    </model>
    <model name='grey_wall_2'>
      <static>1</static>
      <link name='link'>
        <pose>0 0 1.4 0 -0 0</pose>
        <collision name='collision'>
          <geometry>
            <box>
              <size>7.5 0.2 2.8</size>
            </box>
          </geometry>
          <max_contacts>10</max_contacts>
          <surface>
            <bounce/>
            <friction>
              <ode/>
            </friction>
            <contact>
              <ode/>
            </contact>
          </surface>
        </collision>
        <visual name='visual'>
          <cast_shadows>0</cast_shadows>
          <geometry>
            <box>
              <size>7.5 0.2 2.8</size>
            </box>
          </geometry>
          <material>
            <script>
              <uri>model://grey_wall/materials/scripts</uri>
              <uri>model://grey_wall/materials/textures</uri>
              <name>vrc/grey_wall</name>
            </script>
          </material>
        </visual>
        <velocity_decay>
          <linear>0</linear>
          <angular>0</angular>
        </velocity_decay>
        <self_collide>0</self_collide>
        <kinematic>0</kinematic>
        <gravity>1</gravity>
      </link>
      <pose>-6.57172 -10 0 0 -0 0</pose>
    </model>
    <model name='grey_wall_3'>
      <static>1</static>
      <link name='link'>
        <pose>0 0 1.4 0 -0 0</pose>
        <collision name='collision'>
          <geometry>
            <box>
              <size>7.5 0.2 2.8</size>
            </box>
          </geometry>
          <max_contacts>10</max_contacts>
          <surface>
            <bounce/>
            <friction>
              <ode/>
            </friction>
            <contact>
              <ode/>
            </contact>
          </surface>
        </collision>
        <visual name='visual'>
          <cast_shadows>0</cast_shadows>
          <geometry>
            <box>
              <size>7.5 0.2 2.8</size>
            </box>
          </geometry>
          <material>
            <script>
              <uri>model://grey_wall/materials/scripts</uri>
              <uri>model://grey_wall/materials/textures</uri>
              <name>vrc/grey_wall</name>
            </script>
          </material>
        </visual>
        <velocity_decay>
          <linear>0</linear>
          <angular>0</angular>
        </velocity_decay>
        <self_collide>0</self_collide>
        <kinematic>0</kinematic>
        <gravity>1</gravity>
      </link>
      <pose>0.502464 -10 0 0 -0 0</pose>
    </model>
    <model name='grey_wall_4'>
      <static>1</static>
      <link name='link'>
        <pose>0 0 1.4 0 -0 0</pose>
        <collision name='collision'>
          <geometry>
            <box>
              <size>7.5 0.2 2.8</size>
            </box>
          </geometry>
          <max_contacts>10</max_contacts>
          <surface>
            <bounce/>
            <friction>
              <ode/>
            </friction>
            <contact>
              <ode/>
            </contact>
          </surface>
        </collision>
        <visual name='visual'>
          <cast_shadows>0</cast_shadows>
          <geometry>
            <box>
              <size>7.5 0.2 2.8</size>
            </box>
          </geometry>
          <material>
            <script>
              <uri>model://grey_wall/materials/scripts</uri>
              <uri>model://grey_wall/materials/textures</uri>
              <name>vrc/grey_wall</name>
            </script>
          </material>
        </visual>
        <velocity_decay>
          <linear>0</linear>
          <angular>0</angular>
        </velocity_decay>
        <self_collide>0</self_collide>
        <kinematic>0</kinematic>
        <gravity>1</gravity>
      </link>
      <pose>6.46119 -10 0 0 -0 0</pose>
    </model>
    <model name='grey_wall_5'>
      <static>1</static>
      <link name='link'>
        <pose>0 0 1.4 0 -0 0</pose>
        <collision name='collision'>
          <geometry>
            <box>
              <size>7.5 0.2 2.8</size>
            </box>
          </geometry>
          <max_contacts>10</max_contacts>
          <surface>
            <bounce/>
            <friction>
              <ode/>
            </friction>
            <contact>
              <ode/>
            </contact>
          </surface>
        </collision>
        <visual name='visual'>
          <cast_shadows>0</cast_shadows>
          <geometry>
            <box>
              <size>7.5 0.2 2.8</size>
            </box>
          </geometry>
          <material>
            <script>
              <uri>model://grey_wall/materials/scripts</uri>
              <uri>model://grey_wall/materials/textures</uri>
              <name>vrc/grey_wall</name>
            </script>
          </material>
        </visual>
        <velocity_decay>
          <linear>0</linear>
          <angular>0</angular>
        </velocity_decay>
        <self_collide>0</self_collide>
        <kinematic>0</kinematic>
        <gravity>1</gravity>
      </link>
      <pose>7 5 0 0 -0 0</pose>
    </model>
    <model name='grey_wall_6'>
      <static>1</static>
      <link name='link'>
        <pose>0 0 1.4 0 -0 0</pose>
        <collision name='collision'>
          <geometry>
            <box>
              <size>7.5 0.2 2.8</size>
            </box>
          </geometry>
          <max_contacts>10</max_contacts>
          <surface>
            <bounce/>
            <friction>
              <ode/>
            </friction>
            <contact>
              <ode/>
            </contact>
          </surface>
        </collision>
        <visual name='visual'>
          <cast_shadows>0</cast_shadows>
          <geometry>
            <box>
              <size>7.5 0.2 2.8</size>
            </box>
          </geometry>
          <material>
            <script>
              <uri>model://grey_wall/materials/scripts</uri>
              <uri>model://grey_wall/materials/textures</uri>
              <name>vrc/grey_wall</name>
            </script>
          </material>
        </visual>
        <velocity_decay>
          <linear>0</linear>
          <angular>0</angular>
        </velocity_decay>
        <self_collide>0</self_collide>
        <kinematic>0</kinematic>
        <gravity>1</gravity>
      </link>
      <pose>7 0 0 0 -0 0</pose>
    </model>
    <model name='grey_wall_7'>
      <static>1</static>
      <link name='link'>
        <pose>0 0 1.4 0 -0 0</pose>
        <collision name='collision'>
          <geometry>
            <box>
              <size>7.5 0.2 2.8</size>
            </box>
          </geometry>
          <max_contacts>10</max_contacts>
          <surface>
            <bounce/>
            <friction>
              <ode/>
            </friction>
            <contact>
              <ode/>
            </contact>
          </surface>
        </collision>
        <visual name='visual'>
          <cast_shadows>0</cast_shadows>
          <geometry>
            <box>
              <size>7.5 0.2 2.8</size>
            </box>
          </geometry>
          <material>
            <script>
              <uri>model://grey_wall/materials/scripts</uri>
              <uri>model://grey_wall/materials/textures</uri>
              <name>vrc/grey_wall</name>
            </script>
          </material>
        </visual>
        <velocity_decay>
          <linear>0</linear>
          <angular>0</angular>
        </velocity_decay>
        <self_collide>0</self_collide>
        <kinematic>0</kinematic>
        <gravity>1</gravity>
      </link>
      <pose>7 -6 0 0 -0 0</pose>
    </model>
    <model name='grey_wall_8'>
      <static>1</static>
      <link name='link'>
        <pose>0 0 1.4 0 -0 0</pose>
        <collision name='collision'>
          <geometry>
            <box>
              <size>7.5 0.2 2.8</size>
            </box>
          </geometry>
          <max_contacts>10</max_contacts>
          <surface>
            <bounce/>
            <friction>
              <ode/>
            </friction>
            <contact>
              <ode/>
            </contact>
          </surface>
        </collision>
        <visual name='visual'>
          <cast_shadows>0</cast_shadows>
          <geometry>
            <box>
              <size>7.5 0.2 2.8</size>
            </box>
          </geometry>
          <material>
            <script>
              <uri>model://grey_wall/materials/scripts</uri>
              <uri>model://grey_wall/materials/textures</uri>
              <name>vrc/grey_wall</name>
            </script>
          </material>
        </visual>
        <velocity_decay>
          <linear>0</linear>
          <angular>0</angular>
        </velocity_decay>
        <self_collide>0</self_collide>
        <kinematic>0</kinematic>
        <gravity>1</gravity>
      </link>
      <pose>-7 5 0 0 -0 0</pose>
    </model>
    <model name='grey_wall_9'>
      <static>1</static>
      <link name='link'>
        <pose>0 0 1.4 0 -0 0</pose>
        <collision name='collision'>
          <geometry>
            <box>
              <size>7.5 0.2 2.8</size>
            </box>
          </geometry>
          <max_contacts>10</max_contacts>
          <surface>
            <bounce/>
            <friction>
              <ode/>
            </friction>
            <contact>
              <ode/>
            </contact>
          </surface>
        </collision>
        <visual name='visual'>
          <cast_shadows>0</cast_shadows>
          <geometry>
            <box>
              <size>7.5 0.2 2.8</size>
            </box>
          </geometry>
          <material>
            <script>
              <uri>model://grey_wall/materials/scripts</uri>
              <uri>model://grey_wall/materials/textures</uri>
              <name>vrc/grey_wall</name>
            </script>
          </material>
        </visual>
        <velocity_decay>
          <linear>0</linear>
          <angular>0</angular>
        </velocity_decay>
        <self_collide>0</self_collide>
        <kinematic>0</kinematic>
        <gravity>1</gravity>
      </link>
      <pose>-7 0 0 0 -0 0</pose>
    </model>
    <model name='grey_wall_10'>
      <static>1</static>
      <link name='link'>
        <pose>0 0 1.4 0 -0 0</pose>
        <collision name='collision'>
          <geometry>
            <box>
              <size>7.5 0.2 2.8</size>
            </box>
          </geometry>
          <max_contacts>10</max_contacts>
          <surface>
            <bounce/>
            <friction>
              <ode/>
            </friction>
            <contact>
              <ode/>
            </contact>
          </surface>
        </collision>
        <visual name='visual'>
          <cast_shadows>0</cast_shadows>
          <geometry>
            <box>
              <size>7.5 0.2 2.8</size>
            </box>
          </geometry>
          <material>
            <script>
              <uri>model://grey_wall/materials/scripts</uri>
              <uri>model://grey_wall/materials/textures</uri>
              <name>vrc/grey_wall</name>
            </script>
          </material>
        </visual>
        <velocity_decay>
          <linear>0</linear>
          <angular>0</angular>
        </velocity_decay>
        <self_collide>0</self_collide>
        <kinematic>0</kinematic>
        <gravity>1</gravity>
      </link>
      <pose>-7 -6 0 0 -0 0</pose>
    </model>
    <state world_name='default'>
      <sim_time>1197 993000000</sim_time>
      <real_time>35 69782671</real_time>
      <wall_time>1513840051 504992879</wall_time>
      <model name='drc_practice_white_jersey_barrier'>
        <pose>-6 1 0 0 -0 0</pose>
        <link name='link'>
          <pose>-6 1 0 0 -0 0</pose>
          <velocity>0 0 0 0 -0 0</velocity>
          <acceleration>0 0 0 0 -0 0</acceleration>
          <wrench>0 0 0 0 -0 0</wrench>
        </link>
      </model>
      <model name='first_2015_trash_can'>
        <pose>-6.8133 -0.05734 -2e-06 2e-06 1.5e-05 0.108369</pose>
        <link name='link'>
          <pose>-6.8133 -0.05734 -2e-06 2e-06 1.5e-05 0.108369</pose>
          <velocity>0 0 0 0 -0 0</velocity>
          <acceleration>-6.42133 0.224649 5.69591 -0.035548 -1.01611 1.31749e-17</acceleration>
          <wrench>-31.0199 1.08523 27.5156 0 -0 0</wrench>
        </link>
      </model>
      <model name='first_2015_trash_can_0'>
        <pose>6.00035 -0.000133 -4e-06 -5e-06 -3e-06 -0.001646</pose>
        <link name='link'>
          <pose>6.00035 -0.000133 -4e-06 -5e-06 -3e-06 -0.001646</pose>
          <velocity>0 0 0 0 -0 0</velocity>
          <acceleration>0.402265 -4.67518 2.12364 0.742441 0.07144 0.01132</acceleration>
          <wrench>1.94325 -22.5847 10.2588 0 -0 0</wrench>
        </link>
      </model>
      <model name='first_2015_trash_can_1'>
        <pose>-1.05959 -4.9994 -4e-06 -3e-06 4e-06 -0.001401</pose>
        <link name='link'>
          <pose>-1.05959 -4.9994 -4e-06 -3e-06 4e-06 -0.001401</pose>
          <velocity>0 0 0 0 -0 0</velocity>
          <acceleration>-1.71481 0.793396 -5.24585 -0.125542 -0.271347 1e-06</acceleration>
          <wrench>-8.28385 3.83271 -25.3414 0 -0 0</wrench>
        </link>
      </model>
      <model name='first_2015_trash_can_2'>
        <pose>3.00023 -7.00009 -5e-06 1.3e-05 1.9e-05 -0.000817</pose>
        <link name='link'>
          <pose>3.00023 -7.00009 -5e-06 1.3e-05 1.9e-05 -0.000817</pose>
          <velocity>0 0 0 0 -0 0</velocity>
          <acceleration>2.51553 -0.363308 -3.80123 0.05708 0.397534 0.000139</acceleration>
          <wrench>12.1519 -1.75506 -18.3628 0 -0 0</wrench>
        </link>
      </model>
      <model name='frc2016_drawbridge'>
        <pose>-1.99989 -0.00078 1e-06 8.27181e-25 -1e-06 0.004125</pose>
        <link name='base'>
          <pose>-1.99989 -0.00078 1e-06 8.27181e-25 -1e-06 0.004125</pose>
          <velocity>2.3e-05 -0.000334 0.003902 -0.00123 0.003733 -0.000442</velocity>
          <acceleration>8.80394 2.3459 7.46037 2.03814 -0.88358 -3.12489</acceleration>
          <wrench>88.0394 23.459 74.6037 0 -0 0</wrench>
        </link>
        <link name='bridge'>
          <pose>-2.00106 0.281668 0.505771 8.27181e-25 -1e-06 0.004125</pose>
          <velocity>0.002131 6.6e-05 0.003491 -0.001535 0.003727 -0.000773</velocity>
          <acceleration>0.200575 -1.02348 7.46009 -0.226385 1.53637 -0.03337</acceleration>
          <wrench>0.40115 -2.04697 14.9202 0 -0 0</wrench>
        </link>
      </model>
      <model name='frc2016_drawbridge_0'>
        <pose>3.99908 -2.50384 0 -4.1359e-25 -1e-06 0.003646</pose>
        <link name='base'>
          <pose>3.99908 -2.50384 0 -4.1359e-25 -1e-06 0.003646</pose>
          <velocity>1.6e-05 -0.000242 0.003798 -0.002122 0.003835 -0.000282</velocity>
          <acceleration>8.8778 4.30895 7.62035 1.35236 -0.919638 -3.09603</acceleration>
          <wrench>88.778 43.0895 76.2035 0 -0 0</wrench>
        </link>
        <link name='bridge'>
          <pose>3.99805 -2.22139 0.50577 -4.1359e-25 -1e-06 0.003646</pose>
          <velocity>0.002073 0.000654 0.003152 -0.002346 0.003837 -0.000446</velocity>
          <acceleration>0.181342 -0.862327 7.61908 -0.354777 1.55185 0.01144</acceleration>
          <wrench>0.362683 -1.72465 15.2382 0 -0 0</wrench>
        </link>
      </model>
      <model name='frc2016_portcullis'>
        <pose>-5.98511 -5.00746 -1e-06 0 1e-06 0.174808</pose>
        <link name='base'>
          <pose>-5.98511 -5.00746 -1e-06 0 1e-06 0.174808</pose>
          <velocity>-2.1e-05 0.000136 -0.001338 0.000658 0.00388 0.000321</velocity>
          <acceleration>2.59281 0.068938 -0.935362 -0.053539 0.28749 -0.071764</acceleration>
          <wrench>129.64 3.4469 -46.7681 0 -0 0</wrench>
        </link>
        <link name='gate'>
          <pose>-6.01839 -4.98404 0.93327 1e-06 1e-06 0.17481</pose>
          <velocity>0.003594 -0.000474 -0.001191 0.000719 0.003881 0.00022</velocity>
          <acceleration>2.35496 0.086143 -0.850565 -1.10406 0.885368 -1.51717</acceleration>
          <wrench>4.70992 0.172285 -1.70113 0 -0 0</wrench>
        </link>
      </model>
      <model name='grey_wall'>
        <pose>-6.37486 9.06322 0 0 -0 0</pose>
        <link name='link'>
          <pose>-6.37486 9.06322 1.4 0 -0 0</pose>
          <velocity>0 0 0 0 -0 0</velocity>
          <acceleration>0 0 0 0 -0 0</acceleration>
          <wrench>0 0 0 0 -0 0</wrench>
        </link>
      </model>
      <model name='grey_wall_0'>
        <pose>1.12463 9.06218 0 0 -0 0</pose>
        <link name='link'>
          <pose>1.12463 9.06218 1.4 0 -0 0</pose>
          <velocity>0 0 0 0 -0 0</velocity>
          <acceleration>0 0 0 0 -0 0</acceleration>
          <wrench>0 0 0 0 -0 0</wrench>
        </link>
      </model>
      <model name='grey_wall_1'>
        <pose>6.47505 9.08721 0 0 -0 0</pose>
        <link name='link'>
          <pose>6.47505 9.08721 1.4 0 -0 0</pose>
          <velocity>0 0 0 0 -0 0</velocity>
          <acceleration>0 0 0 0 -0 0</acceleration>
          <wrench>0 0 0 0 -0 0</wrench>
        </link>
      </model>
      <model name='grey_wall_10'>
        <pose>-10.2268 -6.36026 -0 0 0 -1.58184</pose>
        <link name='link'>
          <pose>-10.2268 -6.36026 1.4 0 0 -1.58184</pose>
          <velocity>0 0 0 0 -0 0</velocity>
          <acceleration>0 0 0 0 -0 0</acceleration>
          <wrench>0 0 0 0 -0 0</wrench>
        </link>
      </model>
      <model name='grey_wall_11'>
        <pose>-6.53777 4 0 0 -0 0</pose>
        <link name='link'>
          <pose>-6.53777 4 1.4 0 -0 0</pose>
          <velocity>0 0 0 0 -0 0</velocity>
          <acceleration>0 0 0 0 -0 0</acceleration>
          <wrench>0 0 0 0 -0 0</wrench>
        </link>
      </model>
      <model name='grey_wall_12'>
        <pose>6.50522 4 0 0 -0 0</pose>
        <link name='link'>
          <pose>6.50522 4 1.4 0 -0 0</pose>
          <velocity>0 0 0 0 -0 0</velocity>
          <acceleration>0 0 0 0 -0 0</acceleration>
          <wrench>0 0 0 0 -0 0</wrench>
        </link>
      </model>
      <model name='grey_wall_2'>
        <pose>-6.57172 -10 0 0 -0 0</pose>
        <link name='link'>
          <pose>-6.57172 -10 1.4 0 -0 0</pose>
          <velocity>0 0 0 0 -0 0</velocity>
          <acceleration>0 0 0 0 -0 0</acceleration>
          <wrench>0 0 0 0 -0 0</wrench>
        </link>
      </model>
      <model name='grey_wall_3'>
        <pose>0.502464 -10 0 0 -0 0</pose>
        <link name='link'>
          <pose>0.502464 -10 1.4 0 -0 0</pose>
          <velocity>0 0 0 0 -0 0</velocity>
          <acceleration>0 0 0 0 -0 0</acceleration>
          <wrench>0 0 0 0 -0 0</wrench>
        </link>
      </model>
      <model name='grey_wall_4'>
        <pose>6.46119 -10 0 0 -0 0</pose>
        <link name='link'>
          <pose>6.46119 -10 1.4 0 -0 0</pose>
          <velocity>0 0 0 0 -0 0</velocity>
          <acceleration>0 0 0 0 -0 0</acceleration>
          <wrench>0 0 0 0 -0 0</wrench>
        </link>
      </model>
      <model name='grey_wall_5'>
        <pose>10.1266 5.31585 0 0 0 -1.58058</pose>
        <link name='link'>
          <pose>10.1266 5.31585 1.4 0 0 -1.58058</pose>
          <velocity>0 0 0 0 -0 0</velocity>
          <acceleration>0 0 0 0 -0 0</acceleration>
          <wrench>0 0 0 0 -0 0</wrench>
        </link>
      </model>
      <model name='grey_wall_6'>
        <pose>10.1134 -2.21796 0 0 0 -1.566</pose>
        <link name='link'>
          <pose>10.1134 -2.21796 1.4 0 0 -1.566</pose>
          <velocity>0 0 0 0 -0 0</velocity>
          <acceleration>0 0 0 0 -0 0</acceleration>
          <wrench>0 0 0 0 -0 0</wrench>
        </link>
      </model>
      <model name='grey_wall_7'>
        <pose>10.161 -6.18012 0 0 -0 1.5699</pose>
        <link name='link'>
          <pose>10.161 -6.18012 1.4 0 -0 1.5699</pose>
          <velocity>0 0 0 0 -0 0</velocity>
          <acceleration>0 0 0 0 -0 0</acceleration>
          <wrench>0 0 0 0 -0 0</wrench>
        </link>
      </model>
      <model name='grey_wall_8'>
        <pose>-10.1642 5.26629 0 0 0 -1.57839</pose>
        <link name='link'>
          <pose>-10.1642 5.26629 1.4 0 0 -1.57839</pose>
          <velocity>0 0 0 0 -0 0</velocity>
          <acceleration>0 0 0 0 -0 0</acceleration>
          <wrench>0 0 0 0 -0 0</wrench>
        </link>
      </model>
      <model name='grey_wall_9'>
        <pose>-10.2248 -2.07732 0 0 0 -1.57362</pose>
        <link name='link'>
          <pose>-10.2248 -2.07732 1.4 0 0 -1.57362</pose>
          <velocity>0 0 0 0 -0 0</velocity>
          <acceleration>0 0 0 0 -0 0</acceleration>
          <wrench>0 0 0 0 -0 0</wrench>
        </link>
      </model>
      <model name='ground_plane'>
        <pose>0 0 0 0 -0 0</pose>
        <link name='link'>
          <pose>0 0 0 0 -0 0</pose>
          <velocity>0 0 0 0 -0 0</velocity>
          <acceleration>0 0 0 0 -0 0</acceleration>
          <wrench>0 0 0 0 -0 0</wrench>
        </link>
      </model>
      <model name='hinged_door'>
        <pose>-4 -3 4e-06 2e-06 -0 0</pose>
        <link name='door'>
          <pose>-4 -3.00001 2.04 3.14159 1e-06 1.5769</pose>
          <velocity>-0.000512 1.1e-05 -1.5e-05 -3e-06 -0.000256 -0.000285</velocity>
          <acceleration>-0.017824 -0.004607 -0.008977 -0.001296 -0.048644 -0.005765</acceleration>
          <wrench>-0.736606 -0.190398 -0.370993 0 -0 0</wrench>
        </link>
        <link name='frame'>
          <pose>-3.94 -3.0005 4e-06 2e-06 -0 0</pose>
          <velocity>5e-06 -1e-06 0 1e-06 -0.000211 -2.58494e-26</velocity>
          <acceleration>0.015612 -0.000278 0.00212 0.001388 0.037046 7e-06</acceleration>
          <wrench>0.015612 -0.000278 0.00212 0 -0 0</wrench>
        </link>
        <link name='handles'>
          <pose>-4.00552 -2.20003 1.05 -3.14159 0.001591 -1.56469</pose>
          <velocity>-3.1e-05 1e-05 -1.9e-05 -3e-06 -0.000257 -0.000288</velocity>
          <acceleration>0.006852 -0.001566 -0.014856 -0.003661 -0.121719 -0.086514</acceleration>
          <wrench>0.006852 -0.001566 -0.014856 0 -0 0</wrench>
        </link>
      </model>
      <model name='number3'>
        <pose>8 -5 0.4 0 -0 0</pose>
        <link name='link'>
          <pose>8 -5 0.4 0 -0 0</pose>
          <velocity>0 0 0 0 -0 0</velocity>
          <acceleration>0 0 0 0 -0 0</acceleration>
          <wrench>0 0 0 0 -0 0</wrench>
        </link>
      </model>
      <model name='number5'>
        <pose>-3 -7 0.4 0 -0 0</pose>
        <link name='link'>
          <pose>-3 -7 0.4 0 -0 0</pose>
          <velocity>0 0 0 0 -0 0</velocity>
          <acceleration>0 0 0 0 -0 0</acceleration>
          <wrench>0 0 0 0 -0 0</wrench>
        </link>
      </model>
      <model name='number5_0'>
        <pose>3 3 0.4 0 -0 0</pose>
        <link name='link'>
          <pose>3 3 0.4 0 -0 0</pose>
          <velocity>0 0 0 0 -0 0</velocity>
          <acceleration>0 0 0 0 -0 0</acceleration>
          <wrench>0 0 0 0 -0 0</wrench>
        </link>
      </model>
      <model name='number7'>
        <pose>8 -6 0.4 0 -0 0</pose>
        <link name='link'>
          <pose>8 -6 0.4 0 -0 0</pose>
          <velocity>0 0 0 0 -0 0</velocity>
          <acceleration>0 0 0 0 -0 0</acceleration>
          <wrench>0 0 0 0 -0 0</wrench>
        </link>
      </model>
      <model name='number9'>
        <pose>8 -7 0.4 0 -0 0</pose>
        <link name='link'>
          <pose>8 -7 0.4 0 -0 0</pose>
          <velocity>0 0 0 0 -0 0</velocity>
          <acceleration>0 0 0 0 -0 0</acceleration>
          <wrench>0 0 0 0 -0 0</wrench>
        </link>
      </model>
      <model name='unit_box_1'>
        <pose>-7 8.45126 0.5 0 -0 0</pose>
        <link name='link'>
          <pose>-7 8.45126 0.5 0 -0 0</pose>
          <velocity>0 0 0 0 -0 0</velocity>
          <acceleration>0 0 0 0 -0 0</acceleration>
          <wrench>0 0 0 0 -0 0</wrench>
        </link>
      </model>
      <model name='unit_box_2'>
        <pose>4 5 0.5 0 -0 0</pose>
        <link name='link'>
          <pose>4 5 0.5 0 -0 0</pose>
          <velocity>0 0 0 0 -0 0</velocity>
          <acceleration>0 -0 0 0 -0 0</acceleration>
          <wrench>0 -0 0 0 -0 0</wrench>
        </link>
      </model>
      <model name='wheel_valve_large_wall'>
        <pose>1.59014 0 0 0 -0 0</pose>
        <link name='valve_0::handle'>
          <pose>2.50973 0.0208 0.285 0 -2.2e-05 0</pose>
          <velocity>0 0 -0 0 -0 0</velocity>
          <acceleration>0 -0 0 0 -0 0</acceleration>
          <wrench>0 -0 0 0 -0 0</wrench>
        </link>
        <link name='valve_10::handle'>
          <pose>1.89922 0.0208 2.1162 0 2.2e-05 0</pose>
          <velocity>-0 0 -0 0 -0 0</velocity>
          <acceleration>-0 -0 -0 0 -0 0</acceleration>
          <wrench>-0 -0 -0 0 -0 0</wrench>
        </link>
        <link name='valve_1::handle'>
          <pose>2.50973 0.0208 0.8954 0 -2.2e-05 0</pose>
          <velocity>0 0 -0 0 -0 0</velocity>
          <acceleration>0 0 0 0 -0 0</acceleration>
          <wrench>0 0 0 0 -0 0</wrench>
        </link>
        <link name='valve_2::handle'>
          <pose>2.50973 0.0208 1.5058 0 -2.2e-05 0</pose>
          <velocity>0 0 -0 0 -0 0</velocity>
          <acceleration>0 0 0 0 -0 0</acceleration>
          <wrench>0 0 0 0 -0 0</wrench>
        </link>
        <link name='valve_3::handle'>
          <pose>2.50973 0.0208 2.1162 0 -2.2e-05 0</pose>
          <velocity>0 0 -0 0 -0 0</velocity>
          <acceleration>0 -0 -0 0 -0 0</acceleration>
          <wrench>0 -0 -0 0 -0 0</wrench>
        </link>
        <link name='valve_4::handle'>
          <pose>2.20447 0.0208 0.5896 0 3.6e-05 0</pose>
          <velocity>-0 0 -0 0 -0 0</velocity>
          <acceleration>-0 0 0 0 -0 0</acceleration>
          <wrench>-0 0 0 0 -0 0</wrench>
        </link>
        <link name='valve_5::handle'>
          <pose>2.20447 0.0208 1.2 0 3.6e-05 0</pose>
          <velocity>-0 0 -0 0 -0 0</velocity>
          <acceleration>-0 0 -0 0 -0 0</acceleration>
          <wrench>-0 0 -0 0 -0 0</wrench>
        </link>
        <link name='valve_6::handle'>
          <pose>2.20447 0.0208 1.8104 0 3.6e-05 0</pose>
          <velocity>-0 0 -0 0 -0 0</velocity>
          <acceleration>-0 0 -0 0 -0 0</acceleration>
          <wrench>-0 0 -0 0 -0 0</wrench>
        </link>
        <link name='valve_7::handle'>
          <pose>1.89922 0.0208 0.285 0 2.2e-05 0</pose>
          <velocity>-0 0 -0 0 -0 0</velocity>
          <acceleration>-0 -0 0 0 -0 0</acceleration>
          <wrench>-0 -0 0 0 -0 0</wrench>
        </link>
        <link name='valve_8::handle'>
          <pose>1.89922 0.0208 0.8954 0 2.2e-05 0</pose>
          <velocity>-0 0 -0 0 -0 0</velocity>
          <acceleration>-0 0 0 0 -0 0</acceleration>
          <wrench>-0 0 0 0 -0 0</wrench>
        </link>
        <link name='valve_9::handle'>
          <pose>1.89922 0.0208 1.5058 0 2.2e-05 0</pose>
          <velocity>-0 0 -0 0 -0 0</velocity>
          <acceleration>-0 0 0 0 -0 0</acceleration>
          <wrench>-0 0 0 0 -0 0</wrench>
        </link>
        <link name='wall::link'>
          <pose>1.59014 0 0 0 -0 0</pose>
          <velocity>-0 -0 -0 0 -0 0</velocity>
          <acceleration>-0 0 0 0 -0 0</acceleration>
          <wrench>-0 0 0 0 -0 0</wrench>
        </link>
      </model>
    </state>
    <model name='grey_wall_11'>
      <static>1</static>
      <link name='link'>
        <pose>0 0 1.4 0 -0 0</pose>
        <collision name='collision'>
          <geometry>
            <box>
              <size>7.5 0.2 2.8</size>
            </box>
          </geometry>
          <max_contacts>10</max_contacts>
          <surface>
            <bounce/>
            <friction>
              <ode/>
            </friction>
            <contact>
              <ode/>
            </contact>
          </surface>
        </collision>
        <visual name='visual'>
          <cast_shadows>0</cast_shadows>
          <geometry>
            <box>
              <size>7.5 0.2 2.8</size>
            </box>
          </geometry>
          <material>
            <script>
              <uri>model://grey_wall/materials/scripts</uri>
              <uri>model://grey_wall/materials/textures</uri>
              <name>vrc/grey_wall</name>
            </script>
          </material>
        </visual>
        <velocity_decay>
          <linear>0</linear>
          <angular>0</angular>
        </velocity_decay>
        <self_collide>0</self_collide>
        <kinematic>0</kinematic>
        <gravity>1</gravity>
      </link>
      <pose>-6.53777 4 0 0 -0 0</pose>
    </model>
    <model name='grey_wall_12'>
      <static>1</static>
      <link name='link'>
        <pose>0 0 1.4 0 -0 0</pose>
        <collision name='collision'>
          <geometry>
            <box>
              <size>7.5 0.2 2.8</size>
            </box>
          </geometry>
          <max_contacts>10</max_contacts>
          <surface>
            <bounce/>
            <friction>
              <ode/>
            </friction>
            <contact>
              <ode/>
            </contact>
          </surface>
        </collision>
        <visual name='visual'>
          <cast_shadows>0</cast_shadows>
          <geometry>
            <box>
              <size>7.5 0.2 2.8</size>
            </box>
          </geometry>
          <material>
            <script>
              <uri>model://grey_wall/materials/scripts</uri>
              <uri>model://grey_wall/materials/textures</uri>
              <name>vrc/grey_wall</name>
            </script>
          </material>
        </visual>
        <velocity_decay>
          <linear>0</linear>
          <angular>0</angular>
        </velocity_decay>
        <self_collide>0</self_collide>
        <kinematic>0</kinematic>
        <gravity>1</gravity>
      </link>
      <pose>6.50522 4 0 0 -0 0</pose>
    </model>
    <model name='first_2015_trash_can'>
      <link name='link'>
        <inertial>
          <pose>0 0 0.3683 0 -0 0</pose>
          <mass>4.83076</mass>
          <inertia>
            <ixx>0.281534</ixx>
            <ixy>0</ixy>
            <ixz>0</ixz>
            <iyy>0.281534</iyy>
            <iyz>0</iyz>
            <izz>0.126223</izz>
          </inertia>
        </inertial>
        <visual name='visual'>
          <geometry>
            <mesh>
              <uri>model://first_2015_trash_can/meshes/trash_can.dae</uri>
            </mesh>
          </geometry>
        </visual>
        <collision name='collision'>
          <geometry>
            <mesh>
              <uri>model://first_2015_trash_can/meshes/trash_can.dae</uri>
            </mesh>
          </geometry>
          <max_contacts>10</max_contacts>
          <surface>
            <bounce/>
            <friction>
              <ode/>
            </friction>
            <contact>
              <ode/>
            </contact>
          </surface>
        </collision>
        <velocity_decay>
          <linear>0</linear>
          <angular>0</angular>
        </velocity_decay>
        <self_collide>0</self_collide>
        <kinematic>0</kinematic>
        <gravity>1</gravity>
      </link>
      <pose>-6 0 0 0 -0 0</pose>
      <static>0</static>
    </model>
    <model name='frc2016_drawbridge'>
      <link name='base'>
        <inertial>
          <mass>10</mass>
          <pose>0 0 1 0 -0 0</pose>
          <inertia>
            <ixx>3.64907</ixx>
            <ixy>0</ixy>
            <ixz>0</ixz>
            <iyy>4.67075</iyy>
            <iyz>0</iyz>
            <izz>1.66649</izz>
          </inertia>
        </inertial>
        <visual name='platform'>
          <pose>0 0 0.0425 0 -0 0</pose>
          <geometry>
            <box>
              <size>1.27 0.5969 0.085</size>
            </box>
          </geometry>
        </visual>
        <collision name='platform'>
          <pose>0 0 0.0425 0 -0 0</pose>
          <geometry>
            <box>
              <size>1.27 0.5969 0.085</size>
            </box>
          </geometry>
          <max_contacts>10</max_contacts>
          <surface>
            <bounce/>
            <friction>
              <ode/>
            </friction>
            <contact>
              <ode/>
            </contact>
          </surface>
        </collision>
        <visual name='right_wall'>
          <pose>0.55879 0.04444 0.889 0 -0 0</pose>
          <geometry>
            <box>
              <size>0.05715 0.45698 1.77165</size>
            </box>
          </geometry>
        </visual>
        <collision name='right_wall'>
          <pose>0.55879 0.04444 0.889 0 -0 0</pose>
          <geometry>
            <box>
              <size>0.05715 0.45698 1.77165</size>
            </box>
          </geometry>
          <max_contacts>10</max_contacts>
          <surface>
            <bounce/>
            <friction>
              <ode/>
            </friction>
            <contact>
              <ode/>
            </contact>
          </surface>
        </collision>
        <visual name='left_wall'>
          <pose>-0.55879 0.04444 0.889 0 -0 0</pose>
          <geometry>
            <box>
              <size>0.05715 0.45698 1.77165</size>
            </box>
          </geometry>
        </visual>
        <collision name='left_wall'>
          <pose>-0.55879 0.04444 0.889 0 -0 0</pose>
          <geometry>
            <box>
              <size>0.05715 0.45698 1.77165</size>
            </box>
          </geometry>
          <max_contacts>10</max_contacts>
          <surface>
            <bounce/>
            <friction>
              <ode/>
            </friction>
            <contact>
              <ode/>
            </contact>
          </surface>
        </collision>
        <visual name='front_upper_wall'>
          <pose>0 0.27611 1.84286 0 -0 0</pose>
          <geometry>
            <box>
              <size>1.1557 0.006347 0.254</size>
            </box>
          </geometry>
        </visual>
        <collision name='front_upper_wall'>
          <pose>0 0.27611 1.84286 0 -0 0</pose>
          <geometry>
            <box>
              <size>1.1557 0.006347 0.254</size>
            </box>
          </geometry>
          <max_contacts>10</max_contacts>
          <surface>
            <bounce/>
            <friction>
              <ode/>
            </friction>
            <contact>
              <ode/>
            </contact>
          </surface>
        </collision>
        <visual name='back_upper_wall'>
          <pose>0 -0.18722 1.84286 0 -0 0</pose>
          <geometry>
            <box>
              <size>1.1557 0.006347 0.254</size>
            </box>
          </geometry>
        </visual>
        <collision name='back_upper_wall'>
          <pose>0 -0.18722 1.84286 0 -0 0</pose>
          <geometry>
            <box>
              <size>1.1557 0.006347 0.254</size>
            </box>
          </geometry>
          <max_contacts>10</max_contacts>
          <surface>
            <bounce/>
            <friction>
              <ode/>
            </friction>
            <contact>
              <ode/>
            </contact>
          </surface>
        </collision>
        <velocity_decay>
          <linear>0</linear>
          <angular>0</angular>
        </velocity_decay>
        <self_collide>0</self_collide>
        <kinematic>0</kinematic>
        <gravity>1</gravity>
      </link>
      <link name='bridge'>
        <pose>0 0.28245 0.50577 0 -0 0</pose>
        <inertial>
          <mass>2</mass>
          <pose>0 -0.28245 -0.50577 0 -0 0</pose>
          <inertia>
            <ixx>0.139361</ixx>
            <ixy>0</ixy>
            <ixz>0</ixz>
            <iyy>0.357088</iyy>
            <iyz>0</iyz>
            <izz>0.217741</izz>
          </inertia>
        </inertial>
        <visual name='visual'>
          <geometry>
            <box>
              <size>1.14298 0.006347 0.9144</size>
            </box>
          </geometry>
          <material>
            <script>
              <name>Gazebo/WoodFloor</name>
              <uri>__default__</uri>
            </script>
          </material>
        </visual>
        <collision name='collision'>
          <geometry>
            <box>
              <size>1.14298 0.006347 0.9144</size>
            </box>
          </geometry>
          <max_contacts>10</max_contacts>
          <surface>
            <bounce/>
            <friction>
              <ode/>
            </friction>
            <contact>
              <ode/>
            </contact>
          </surface>
        </collision>
        <velocity_decay>
          <linear>0</linear>
          <angular>0</angular>
        </velocity_decay>
        <self_collide>0</self_collide>
        <kinematic>0</kinematic>
        <gravity>1</gravity>
      </link>
      <joint name='bridge_joint' type='revolute'>
        <pose>0 0 -0.4172 0 -0 0</pose>
        <parent>base</parent>
        <child>bridge</child>
        <axis>
          <xyz>1 0 0</xyz>
          <limit>
            <lower>-2</lower>
            <upper>0</upper>
          </limit>
        </axis>
      </joint>
      <pose>-2 0 0 0 -0 0</pose>
      <static>0</static>
    </model>
    <model name='first_2015_trash_can_0'>
      <link name='link'>
        <inertial>
          <pose>0 0 0.3683 0 -0 0</pose>
          <mass>4.83076</mass>
          <inertia>
            <ixx>0.281534</ixx>
            <ixy>0</ixy>
            <ixz>0</ixz>
            <iyy>0.281534</iyy>
            <iyz>0</iyz>
            <izz>0.126223</izz>
          </inertia>
        </inertial>
        <visual name='visual'>
          <geometry>
            <mesh>
              <uri>model://first_2015_trash_can/meshes/trash_can.dae</uri>
            </mesh>
          </geometry>
        </visual>
        <collision name='collision'>
          <geometry>
            <mesh>
              <uri>model://first_2015_trash_can/meshes/trash_can.dae</uri>
            </mesh>
          </geometry>
          <max_contacts>10</max_contacts>
          <surface>
            <bounce/>
            <friction>
              <ode/>
            </friction>
            <contact>
              <ode/>
            </contact>
          </surface>
        </collision>
        <velocity_decay>
          <linear>0</linear>
          <angular>0</angular>
        </velocity_decay>
        <self_collide>0</self_collide>
        <kinematic>0</kinematic>
        <gravity>1</gravity>
      </link>
      <pose>6 0 0 0 -0 0</pose>
      <static>0</static>
    </model>
    <model name='hinged_door'>
      <link name='frame'>
        <pose>0.06 -0.0005 0 0 -0 0</pose>
        <collision name='collision_1'>
          <pose>-0.025145 -0.03429 1.0541 0 -0 0</pose>
          <geometry>
            <box>
              <size>0.05029 0.06858 2.1082</size>
            </box>
          </geometry>
          <max_contacts>10</max_contacts>
          <surface>
            <bounce/>
            <friction>
              <ode/>
            </friction>
            <contact>
              <ode/>
            </contact>
          </surface>
        </collision>
        <collision name='collision_2'>
          <pose>-0.025145 0.95631 1.0541 0 -0 0</pose>
          <geometry>
            <box>
              <size>0.05029 0.06858 2.1082</size>
            </box>
          </geometry>
          <max_contacts>10</max_contacts>
          <surface>
            <bounce/>
            <friction>
              <ode/>
            </friction>
            <contact>
              <ode/>
            </contact>
          </surface>
        </collision>
        <collision name='collision_3'>
          <pose>-0.025145 0.46482 2.07137 0 -0 0</pose>
          <geometry>
            <box>
              <size>0.05029 0.92964 0.07366</size>
            </box>
          </geometry>
          <max_contacts>10</max_contacts>
          <surface>
            <bounce/>
            <friction>
              <ode/>
            </friction>
            <contact>
              <ode/>
            </contact>
          </surface>
        </collision>
        <visual name='visual'>
          <pose>0 -0.06858 0 0 -0 0</pose>
          <geometry>
            <mesh>
              <uri>model://hinged_door/meshes/frame.dae</uri>
            </mesh>
          </geometry>
        </visual>
        <velocity_decay>
          <linear>0</linear>
          <angular>0</angular>
        </velocity_decay>
        <self_collide>0</self_collide>
        <inertial>
          <inertia>
            <ixx>1</ixx>
            <ixy>0</ixy>
            <ixz>0</ixz>
            <iyy>1</iyy>
            <iyz>0</iyz>
            <izz>1</izz>
          </inertia>
          <mass>1</mass>
        </inertial>
        <kinematic>0</kinematic>
        <gravity>1</gravity>
      </link>
      <link name='door'>
        <pose>-0 0 2.04 3.14159 -0 1.57</pose>
        <inertial>
          <mass>41.3256</mass>
          <pose>0.4569 0.0349 1.016 0 -0 0</pose>
          <inertia>
            <ixx>14.2053</ixx>
            <ixy>0.0004</ixy>
            <ixz>0</ixz>
            <iyy>17.1997</iyy>
            <iyz>0</iyz>
            <izz>3.0298</izz>
          </inertia>
        </inertial>
        <collision name='collision'>
          <pose>0.4569 0.0349 1.016 0 -0 0</pose>
          <geometry>
            <box>
              <size>0.9144 0.04445 2.032</size>
            </box>
          </geometry>
          <max_contacts>10</max_contacts>
          <surface>
            <bounce/>
            <friction>
              <ode/>
            </friction>
            <contact>
              <ode/>
            </contact>
          </surface>
        </collision>
        <visual name='visual'>
          <pose>0 -0.06858 0 0 -0 0</pose>
          <geometry>
            <mesh>
              <uri>model://hinged_door/meshes/door.dae</uri>
            </mesh>
          </geometry>
        </visual>
        <velocity_decay>
          <linear>0</linear>
          <angular>0</angular>
        </velocity_decay>
        <self_collide>0</self_collide>
        <kinematic>0</kinematic>
        <gravity>1</gravity>
      </link>
      <link name='handles'>
        <pose>0 0.8 1.05 -3.14159 0.00159265 -1.57159</pose>
        <collision name='handle1_collision'>
          <pose>0.015 -0.015 0 -1.57 0 0</pose>
          <geometry>
            <mesh>
              <uri>model://door_handle/meshes/handle.dae</uri>
            </mesh>
          </geometry>
          <max_contacts>10</max_contacts>
          <surface>
            <bounce/>
            <friction>
              <ode/>
            </friction>
            <contact>
              <ode/>
            </contact>
          </surface>
        </collision>
        <visual name='handle1_visual'>
          <pose>0.015 -0.015 0 -1.57 0 0</pose>
          <geometry>
            <mesh>
              <uri>model://door_handle/meshes/handle.dae</uri>
            </mesh>
          </geometry>
        </visual>
        <collision name='handle2_collision'>
          <pose>0.015 -0.055 0 1.57 -0 0</pose>
          <geometry>
            <mesh>
              <uri>model://door_handle/meshes/handle.dae</uri>
            </mesh>
          </geometry>
          <max_contacts>10</max_contacts>
          <surface>
            <bounce/>
            <friction>
              <ode/>
            </friction>
            <contact>
              <ode/>
            </contact>
          </surface>
        </collision>
        <visual name='handle2_visual'>
          <pose>0.015 -0.055 0 1.57 -0 0</pose>
          <geometry>
            <mesh>
              <uri>model://door_handle/meshes/handle.dae</uri>
            </mesh>
          </geometry>
        </visual>
        <velocity_decay>
          <linear>0</linear>
          <angular>0</angular>
        </velocity_decay>
        <self_collide>0</self_collide>
        <inertial>
          <inertia>
            <ixx>1</ixx>
            <ixy>0</ixy>
            <ixz>0</ixz>
            <iyy>1</iyy>
            <iyz>0</iyz>
            <izz>1</izz>
          </inertia>
          <mass>1</mass>
        </inertial>
        <kinematic>0</kinematic>
        <gravity>1</gravity>
      </link>
      <joint name='handle' type='revolute'>
        <parent>door</parent>
        <child>handles</child>
        <pose>0.015 0 0 0 -0 0</pose>
        <axis>
          <xyz>1 0 0</xyz>
          <limit>
            <lower>0</lower>
            <upper>1.58</upper>
          </limit>
          <dynamics>
            <damping>1</damping>
            <friction>10</friction>
          </dynamics>
        </axis>
        <physics>
          <ode>
            <cfm_damping>1</cfm_damping>
            <limit>
              <cfm>0</cfm>
              <erp>0.2</erp>
            </limit>
          </ode>
        </physics>
      </joint>
      <joint name='hinge' type='revolute'>
        <parent>frame</parent>
        <child>door</child>
        <axis>
          <xyz>0 0 1</xyz>
          <limit>
            <lower>0</lower>
            <upper>1.58</upper>
          </limit>
          <dynamics>
            <damping>1</damping>
            <friction>1</friction>
          </dynamics>
        </axis>
        <physics>
          <ode>
            <cfm_damping>1</cfm_damping>
            <limit>
              <cfm>0</cfm>
              <erp>0.2</erp>
            </limit>
          </ode>
        </physics>
      </joint>
      <joint name='world_joint' type='revolute'>
        <child>frame</child>
        <parent>world</parent>
        <axis>
          <limit>
            <lower>0</lower>
            <upper>0</upper>
          </limit>
          <xyz>0 1 0</xyz>
          <dynamics>
            <damping>1</damping>
          </dynamics>
        </axis>
        <physics>
          <ode>
            <cfm_damping>1</cfm_damping>
            <limit>
              <cfm>0</cfm>
              <erp>0.2</erp>
            </limit>
          </ode>
        </physics>
      </joint>
      <pose>-4 -3 0 0 -0 0</pose>
      <static>0</static>
    </model>
    <model name='frc2016_drawbridge_0'>
      <link name='base'>
        <inertial>
          <mass>10</mass>
          <pose>0 0 1 0 -0 0</pose>
          <inertia>
            <ixx>3.64907</ixx>
            <ixy>0</ixy>
            <ixz>0</ixz>
            <iyy>4.67075</iyy>
            <iyz>0</iyz>
            <izz>1.66649</izz>
          </inertia>
        </inertial>
        <visual name='platform'>
          <pose>0 0 0.0425 0 -0 0</pose>
          <geometry>
            <box>
              <size>1.27 0.5969 0.085</size>
            </box>
          </geometry>
        </visual>
        <collision name='platform'>
          <pose>0 0 0.0425 0 -0 0</pose>
          <geometry>
            <box>
              <size>1.27 0.5969 0.085</size>
            </box>
          </geometry>
          <max_contacts>10</max_contacts>
          <surface>
            <bounce/>
            <friction>
              <ode/>
            </friction>
            <contact>
              <ode/>
            </contact>
          </surface>
        </collision>
        <visual name='right_wall'>
          <pose>0.55879 0.04444 0.889 0 -0 0</pose>
          <geometry>
            <box>
              <size>0.05715 0.45698 1.77165</size>
            </box>
          </geometry>
        </visual>
        <collision name='right_wall'>
          <pose>0.55879 0.04444 0.889 0 -0 0</pose>
          <geometry>
            <box>
              <size>0.05715 0.45698 1.77165</size>
            </box>
          </geometry>
          <max_contacts>10</max_contacts>
          <surface>
            <bounce/>
            <friction>
              <ode/>
            </friction>
            <contact>
              <ode/>
            </contact>
          </surface>
        </collision>
        <visual name='left_wall'>
          <pose>-0.55879 0.04444 0.889 0 -0 0</pose>
          <geometry>
            <box>
              <size>0.05715 0.45698 1.77165</size>
            </box>
          </geometry>
        </visual>
        <collision name='left_wall'>
          <pose>-0.55879 0.04444 0.889 0 -0 0</pose>
          <geometry>
            <box>
              <size>0.05715 0.45698 1.77165</size>
            </box>
          </geometry>
          <max_contacts>10</max_contacts>
          <surface>
            <bounce/>
            <friction>
              <ode/>
            </friction>
            <contact>
              <ode/>
            </contact>
          </surface>
        </collision>
        <visual name='front_upper_wall'>
          <pose>0 0.27611 1.84286 0 -0 0</pose>
          <geometry>
            <box>
              <size>1.1557 0.006347 0.254</size>
            </box>
          </geometry>
        </visual>
        <collision name='front_upper_wall'>
          <pose>0 0.27611 1.84286 0 -0 0</pose>
          <geometry>
            <box>
              <size>1.1557 0.006347 0.254</size>
            </box>
          </geometry>
          <max_contacts>10</max_contacts>
          <surface>
            <bounce/>
            <friction>
              <ode/>
            </friction>
            <contact>
              <ode/>
            </contact>
          </surface>
        </collision>
        <visual name='back_upper_wall'>
          <pose>0 -0.18722 1.84286 0 -0 0</pose>
          <geometry>
            <box>
              <size>1.1557 0.006347 0.254</size>
            </box>
          </geometry>
        </visual>
        <collision name='back_upper_wall'>
          <pose>0 -0.18722 1.84286 0 -0 0</pose>
          <geometry>
            <box>
              <size>1.1557 0.006347 0.254</size>
            </box>
          </geometry>
          <max_contacts>10</max_contacts>
          <surface>
            <bounce/>
            <friction>
              <ode/>
            </friction>
            <contact>
              <ode/>
            </contact>
          </surface>
        </collision>
        <velocity_decay>
          <linear>0</linear>
          <angular>0</angular>
        </velocity_decay>
        <self_collide>0</self_collide>
        <kinematic>0</kinematic>
        <gravity>1</gravity>
      </link>
      <link name='bridge'>
        <pose>0 0.28245 0.50577 0 -0 0</pose>
        <inertial>
          <mass>2</mass>
          <pose>0 -0.28245 -0.50577 0 -0 0</pose>
          <inertia>
            <ixx>0.139361</ixx>
            <ixy>0</ixy>
            <ixz>0</ixz>
            <iyy>0.357088</iyy>
            <iyz>0</iyz>
            <izz>0.217741</izz>
          </inertia>
        </inertial>
        <visual name='visual'>
          <geometry>
            <box>
              <size>1.14298 0.006347 0.9144</size>
            </box>
          </geometry>
          <material>
            <script>
              <name>Gazebo/WoodFloor</name>
              <uri>__default__</uri>
            </script>
          </material>
        </visual>
        <collision name='collision'>
          <geometry>
            <box>
              <size>1.14298 0.006347 0.9144</size>
            </box>
          </geometry>
          <max_contacts>10</max_contacts>
          <surface>
            <bounce/>
            <friction>
              <ode/>
            </friction>
            <contact>
              <ode/>
            </contact>
          </surface>
        </collision>
        <velocity_decay>
          <linear>0</linear>
          <angular>0</angular>
        </velocity_decay>
        <self_collide>0</self_collide>
        <kinematic>0</kinematic>
        <gravity>1</gravity>
      </link>
      <joint name='bridge_joint' type='revolute'>
        <pose>0 0 -0.4172 0 -0 0</pose>
        <parent>base</parent>
        <child>bridge</child>
        <axis>
          <xyz>1 0 0</xyz>
          <limit>
            <lower>-2</lower>
            <upper>0</upper>
          </limit>
        </axis>
      </joint>
      <pose>4 -2.50326 0 0 -0 0</pose>
      <static>0</static>
    </model>
    <model name='frc2016_portcullis'>
      <link name='base'>
        <inertial>
          <mass>50</mass>
          <pose>0 0 1.02941 0 -0 0</pose>
          <inertia>
            <ixx>3.81711</ixx>
            <ixy>0</ixy>
            <ixz>0</ixz>
            <iyy>4.87698</iyy>
            <iyz>0</iyz>
            <izz>1.6283</izz>
          </inertia>
        </inertial>
        <visual name='platform'>
          <pose>0 0 0.07284 0 -0 0</pose>
          <geometry>
            <box>
              <size>1.27 0.5842 0.003175</size>
            </box>
          </geometry>
        </visual>
        <collision name='platform'>
          <pose>0 0 0.07284 0 -0 0</pose>
          <geometry>
            <box>
              <size>1.27 0.5842 0.003175</size>
            </box>
          </geometry>
          <max_contacts>10</max_contacts>
          <surface>
            <bounce/>
            <friction>
              <ode/>
            </friction>
            <contact>
              <ode/>
            </contact>
          </surface>
        </collision>
        <visual name='left_column'>
          <pose>0.59284 0 0.99042 0 -0 0</pose>
          <geometry>
            <box>
              <size>0.08375 0.28575 1.83198</size>
            </box>
          </geometry>
        </visual>
        <collision name='left_column'>
          <pose>0.59284 0 0.99042 0 -0 0</pose>
          <geometry>
            <box>
              <size>0.08375 0.28575 1.83198</size>
            </box>
          </geometry>
          <max_contacts>10</max_contacts>
          <surface>
            <bounce/>
            <friction>
              <ode/>
            </friction>
            <contact>
              <ode/>
            </contact>
          </surface>
        </collision>
        <visual name='right_column'>
          <pose>-0.57759 0 0.99042 0 -0 0</pose>
          <geometry>
            <box>
              <size>0.08375 0.28575 1.83198</size>
            </box>
          </geometry>
        </visual>
        <collision name='right_column'>
          <pose>-0.57759 0 0.99042 0 -0 0</pose>
          <geometry>
            <box>
              <size>0.08375 0.28575 1.83198</size>
            </box>
          </geometry>
          <max_contacts>10</max_contacts>
          <surface>
            <bounce/>
            <friction>
              <ode/>
            </friction>
            <contact>
              <ode/>
            </contact>
          </surface>
        </collision>
        <visual name='top'>
          <pose>-0.00034 0 1.77722 0 -0 0</pose>
          <geometry>
            <box>
              <size>1.22962 0.28575 0.26657</size>
            </box>
          </geometry>
        </visual>
        <collision name='top'>
          <pose>-0.00034 0 1.77722 0 -0 0</pose>
          <geometry>
            <box>
              <size>1.22962 0.28575 0.26657</size>
            </box>
          </geometry>
          <max_contacts>10</max_contacts>
          <surface>
            <bounce/>
            <friction>
              <ode/>
            </friction>
            <contact>
              <ode/>
            </contact>
          </surface>
        </collision>
        <visual name='castor1'>
          <pose>-0.45651 -0.16234 0.03272 0 -0 0</pose>
          <geometry>
            <sphere>
              <radius>0.03272</radius>
            </sphere>
          </geometry>
        </visual>
        <collision name='castor1'>
          <pose>-0.45651 -0.16234 0.03272 0 -0 0</pose>
          <geometry>
            <sphere>
              <radius>0.03272</radius>
            </sphere>
          </geometry>
          <max_contacts>10</max_contacts>
          <surface>
            <bounce/>
            <friction>
              <ode/>
            </friction>
            <contact>
              <ode/>
            </contact>
          </surface>
        </collision>
        <visual name='castor2'>
          <pose>-0.27883 0.21836 0.03272 0 -0 0</pose>
          <geometry>
            <sphere>
              <radius>0.03272</radius>
            </sphere>
          </geometry>
        </visual>
        <collision name='castor2'>
          <pose>-0.27883 0.21836 0.03272 0 -0 0</pose>
          <geometry>
            <sphere>
              <radius>0.03272</radius>
            </sphere>
          </geometry>
          <max_contacts>10</max_contacts>
          <surface>
            <bounce/>
            <friction>
              <ode/>
            </friction>
            <contact>
              <ode/>
            </contact>
          </surface>
        </collision>
        <visual name='castor3'>
          <pose>0.28083 0.21906 0.03272 0 -0 0</pose>
          <geometry>
            <sphere>
              <radius>0.03272</radius>
            </sphere>
          </geometry>
        </visual>
        <collision name='castor3'>
          <pose>0.28083 0.21906 0.03272 0 -0 0</pose>
          <geometry>
            <sphere>
              <radius>0.03272</radius>
            </sphere>
          </geometry>
          <max_contacts>10</max_contacts>
          <surface>
            <bounce/>
            <friction>
              <ode/>
            </friction>
            <contact>
              <ode/>
            </contact>
          </surface>
        </collision>
        <visual name='castor4'>
          <pose>0.45871 -0.16186 0.03272 0 -0 0</pose>
          <geometry>
            <sphere>
              <radius>0.03272</radius>
            </sphere>
          </geometry>
        </visual>
        <collision name='castor4'>
          <pose>0.45871 -0.16186 0.03272 0 -0 0</pose>
          <geometry>
            <sphere>
              <radius>0.03272</radius>
            </sphere>
          </geometry>
          <max_contacts>10</max_contacts>
          <surface>
            <bounce/>
            <friction>
              <ode/>
            </friction>
            <contact>
              <ode/>
            </contact>
          </surface>
        </collision>
        <velocity_decay>
          <linear>0</linear>
          <angular>0</angular>
        </velocity_decay>
        <self_collide>0</self_collide>
        <kinematic>0</kinematic>
        <gravity>1</gravity>
      </link>
      <link name='gate'>
        <pose>-0.0287 0.02885 0.93327 0 -0 0</pose>
        <inertial>
          <mass>2</mass>
          <pose>0 0 0 0 -0 0</pose>
          <inertia>
            <ixx>3.81711</ixx>
            <ixy>0</ixy>
            <ixz>0</ixz>
            <iyy>4.87698</iyy>
            <iyz>0</iyz>
            <izz>1.6283</izz>
          </inertia>
        </inertial>
        <collision name='collision'>
          <geometry>
            <box>
              <size>1.1938 0.02496 1.45732</size>
            </box>
          </geometry>
          <max_contacts>10</max_contacts>
          <surface>
            <bounce/>
            <friction>
              <ode/>
            </friction>
            <contact>
              <ode/>
            </contact>
          </surface>
        </collision>
        <visual name='horz_1'>
          <pose>0 0 -0.70326 0 -0 0</pose>
          <geometry>
            <box>
              <size>1.1938 0.02496 0.0508</size>
            </box>
          </geometry>
          <material>
            <ambient>0.4 0.4 0.4 1</ambient>
            <diffuse>0.4 0.4 0.4 1</diffuse>
          </material>
        </visual>
        <visual name='horz_2'>
          <pose>0 0 -0.44926 0 -0 0</pose>
          <geometry>
            <box>
              <size>1.1938 0.02496 0.0508</size>
            </box>
          </geometry>
          <material>
            <ambient>0.4 0.4 0.4 1</ambient>
            <diffuse>0.4 0.4 0.4 1</diffuse>
          </material>
        </visual>
        <visual name='horz_3'>
          <pose>0 0 -0.14517 0 -0 0</pose>
          <geometry>
            <box>
              <size>1.1938 0.02496 0.0508</size>
            </box>
          </geometry>
          <material>
            <ambient>0.4 0.4 0.4 1</ambient>
            <diffuse>0.4 0.4 0.4 1</diffuse>
          </material>
        </visual>
        <visual name='horz_4'>
          <pose>0 0 0.16034 0 -0 0</pose>
          <geometry>
            <box>
              <size>1.1938 0.02496 0.0508</size>
            </box>
          </geometry>
          <material>
            <ambient>0.4 0.4 0.4 1</ambient>
            <diffuse>0.4 0.4 0.4 1</diffuse>
          </material>
        </visual>
        <visual name='horz_5'>
          <pose>0 0 0.46514 0 -0 0</pose>
          <geometry>
            <box>
              <size>1.1938 0.02496 0.0508</size>
            </box>
          </geometry>
          <material>
            <ambient>0.4 0.4 0.4 1</ambient>
            <diffuse>0.4 0.4 0.4 1</diffuse>
          </material>
        </visual>
        <visual name='horz_6'>
          <pose>0 0 0.72994 0 -0 0</pose>
          <geometry>
            <box>
              <size>1.1938 0.02496 0.0508</size>
            </box>
          </geometry>
          <material>
            <ambient>0.4 0.4 0.4 1</ambient>
            <diffuse>0.4 0.4 0.4 1</diffuse>
          </material>
        </visual>
        <visual name='vert_1'>
          <pose>-0.58448 0 0 0 -0 0</pose>
          <geometry>
            <box>
              <size>0.02495 0.02496 1.45732</size>
            </box>
          </geometry>
          <material>
            <ambient>0.4 0.4 0.4 1</ambient>
            <diffuse>0.4 0.4 0.4 1</diffuse>
          </material>
        </visual>
        <visual name='vert_2'>
          <pose>-0.38128 0 0 0 -0 0</pose>
          <geometry>
            <box>
              <size>0.0508 0.02496 1.45732</size>
            </box>
          </geometry>
          <material>
            <ambient>0.4 0.4 0.4 1</ambient>
            <diffuse>0.4 0.4 0.4 1</diffuse>
          </material>
        </visual>
        <visual name='vert_3'>
          <pose>-0.12728 0 0 0 -0 0</pose>
          <geometry>
            <box>
              <size>0.0508 0.02496 1.45732</size>
            </box>
          </geometry>
          <material>
            <ambient>0.4 0.4 0.4 1</ambient>
            <diffuse>0.4 0.4 0.4 1</diffuse>
          </material>
        </visual>
        <visual name='vert_4'>
          <pose>0.12672 0 0 0 -0 0</pose>
          <geometry>
            <box>
              <size>0.0508 0.02496 1.45732</size>
            </box>
          </geometry>
          <material>
            <ambient>0.4 0.4 0.4 1</ambient>
            <diffuse>0.4 0.4 0.4 1</diffuse>
          </material>
        </visual>
        <visual name='vert_5'>
          <pose>0.38072 0 0 0 -0 0</pose>
          <geometry>
            <box>
              <size>0.0508 0.02496 1.45732</size>
            </box>
          </geometry>
          <material>
            <ambient>0.4 0.4 0.4 1</ambient>
            <diffuse>0.4 0.4 0.4 1</diffuse>
          </material>
        </visual>
        <visual name='vert_6'>
          <pose>0.58392 0 0 0 -0 0</pose>
          <geometry>
            <box>
              <size>0.02495 0.02496 1.45732</size>
            </box>
          </geometry>
          <material>
            <ambient>0.4 0.4 0.4 1</ambient>
            <diffuse>0.4 0.4 0.4 1</diffuse>
          </material>
        </visual>
        <velocity_decay>
          <linear>0</linear>
          <angular>0</angular>
        </velocity_decay>
        <self_collide>0</self_collide>
        <kinematic>0</kinematic>
        <gravity>1</gravity>
      </link>
      <joint name='joint' type='prismatic'>
        <parent>base</parent>
        <child>gate</child>
        <axis>
          <xyz>0 0 1</xyz>
          <limit>
            <lower>0</lower>
            <upper>1</upper>
          </limit>
        </axis>
      </joint>
      <pose>-6 -5 0 0 -0 0</pose>
      <static>0</static>
    </model>
    <model name='first_2015_trash_can_1'>
      <link name='link'>
        <inertial>
          <pose>0 0 0.3683 0 -0 0</pose>
          <mass>4.83076</mass>
          <inertia>
            <ixx>0.281534</ixx>
            <ixy>0</ixy>
            <ixz>0</ixz>
            <iyy>0.281534</iyy>
            <iyz>0</iyz>
            <izz>0.126223</izz>
          </inertia>
        </inertial>
        <visual name='visual'>
          <geometry>
            <mesh>
              <uri>model://first_2015_trash_can/meshes/trash_can.dae</uri>
            </mesh>
          </geometry>
        </visual>
        <collision name='collision'>
          <geometry>
            <mesh>
              <uri>model://first_2015_trash_can/meshes/trash_can.dae</uri>
            </mesh>
          </geometry>
          <max_contacts>10</max_contacts>
          <surface>
            <bounce/>
            <friction>
              <ode/>
            </friction>
            <contact>
              <ode/>
            </contact>
          </surface>
        </collision>
        <velocity_decay>
          <linear>0</linear>
          <angular>0</angular>
        </velocity_decay>
        <self_collide>0</self_collide>
        <kinematic>0</kinematic>
        <gravity>1</gravity>
      </link>
      <pose>0 -5 0 0 -0 0</pose>
      <static>0</static>
    </model>
    <model name='first_2015_trash_can_2'>
      <link name='link'>
        <inertial>
          <pose>0 0 0.3683 0 -0 0</pose>
          <mass>4.83076</mass>
          <inertia>
            <ixx>0.281534</ixx>
            <ixy>0</ixy>
            <ixz>0</ixz>
            <iyy>0.281534</iyy>
            <iyz>0</iyz>
            <izz>0.126223</izz>
          </inertia>
        </inertial>
        <visual name='visual'>
          <geometry>
            <mesh>
              <uri>model://first_2015_trash_can/meshes/trash_can.dae</uri>
            </mesh>
          </geometry>
        </visual>
        <collision name='collision'>
          <geometry>
            <mesh>
              <uri>model://first_2015_trash_can/meshes/trash_can.dae</uri>
            </mesh>
          </geometry>
          <max_contacts>10</max_contacts>
          <surface>
            <bounce/>
            <friction>
              <ode/>
            </friction>
            <contact>
              <ode/>
            </contact>
          </surface>
        </collision>
        <velocity_decay>
          <linear>0</linear>
          <angular>0</angular>
        </velocity_decay>
        <self_collide>0</self_collide>
        <kinematic>0</kinematic>
        <gravity>1</gravity>
      </link>
      <pose>3 -7 0 0 -0 0</pose>
      <static>0</static>
    </model>
    <model name='number5'>
      <pose>-3 -7 0.4 0 -0 0</pose>
      <static>1</static>
      <link name='link'>
        <visual name='visual'>
          <geometry>
            <mesh>
              <uri>model://number1/meshes/number.dae</uri>
            </mesh>
          </geometry>
          <material>
            <script>
              <uri>model://number5/materials/scripts</uri>
              <uri>model://number5/materials/textures</uri>
              <name>Number/Five</name>
            </script>
          </material>
        </visual>
        <velocity_decay>
          <linear>0</linear>
          <angular>0</angular>
        </velocity_decay>
        <self_collide>0</self_collide>
        <kinematic>0</kinematic>
        <gravity>1</gravity>
      </link>
    </model>
    <model name='number3'>
      <pose>8 -5 0.4 0 -0 0</pose>
      <static>1</static>
      <link name='link'>
        <visual name='visual'>
          <geometry>
            <mesh>
              <uri>model://number1/meshes/number.dae</uri>
            </mesh>
          </geometry>
          <material>
            <script>
              <uri>model://number3/materials/scripts</uri>
              <uri>model://number3/materials/textures</uri>
              <name>Number/Three</name>
            </script>
          </material>
        </visual>
        <velocity_decay>
          <linear>0</linear>
          <angular>0</angular>
        </velocity_decay>
        <self_collide>0</self_collide>
        <kinematic>0</kinematic>
        <gravity>1</gravity>
      </link>
    </model>
    <model name='number5_0'>
      <pose>3 3 0.4 0 -0 0</pose>
      <static>1</static>
      <link name='link'>
        <visual name='visual'>
          <geometry>
            <mesh>
              <uri>model://number1/meshes/number.dae</uri>
            </mesh>
          </geometry>
          <material>
            <script>
              <uri>model://number5/materials/scripts</uri>
              <uri>model://number5/materials/textures</uri>
              <name>Number/Five</name>
            </script>
          </material>
        </visual>
        <velocity_decay>
          <linear>0</linear>
          <angular>0</angular>
        </velocity_decay>
        <self_collide>0</self_collide>
        <kinematic>0</kinematic>
        <gravity>1</gravity>
      </link>
    </model>
    <model name='number7'>
      <pose>8 -6 0.4 0 -0 0</pose>
      <static>1</static>
      <link name='link'>
        <visual name='visual'>
          <geometry>
            <mesh>
              <uri>model://number1/meshes/number.dae</uri>
            </mesh>
          </geometry>
          <material>
            <script>
              <uri>model://number7/materials/scripts</uri>
              <uri>model://number7/materials/textures</uri>
              <name>Number/Seven</name>
            </script>
          </material>
        </visual>
        <velocity_decay>
          <linear>0</linear>
          <angular>0</angular>
        </velocity_decay>
        <self_collide>0</self_collide>
        <kinematic>0</kinematic>
        <gravity>1</gravity>
      </link>
    </model>
    <model name='number9'>
      <pose>8 -7 0.4 0 -0 0</pose>
      <static>1</static>
      <link name='link'>
        <visual name='visual'>
          <geometry>
            <mesh>
              <uri>model://number1/meshes/number.dae</uri>
            </mesh>
          </geometry>
          <material>
            <script>
              <uri>model://number9/materials/scripts</uri>
              <uri>model://number9/materials/textures</uri>
              <name>Number/Nine</name>
            </script>
          </material>
        </visual>
        <velocity_decay>
          <linear>0</linear>
          <angular>0</angular>
        </velocity_decay>
        <self_collide>0</self_collide>
        <kinematic>0</kinematic>
        <gravity>1</gravity>
      </link>
    </model>
    <model name='wheel_valve_large_wall'>
      <static>0</static>
      <link name='wall::link'>
        <collision name='collision'>
          <pose>0.6096 0.00476 1.2192 0 -0 0</pose>
          <geometry>
            <box>
              <size>1.2192 0.00952 2.4384</size>
            </box>
          </geometry>
          <max_contacts>10</max_contacts>
          <surface>
            <bounce/>
            <friction>
              <ode/>
            </friction>
            <contact>
              <ode/>
            </contact>
          </surface>
        </collision>
        <visual name='visual'>
          <pose>-0.00453619 -0.00357175 0 0 -0 0</pose>
          <geometry>
            <mesh>
              <uri>model://drc_practice_valve_wall/meshes/five_dice_wall.dae</uri>
            </mesh>
          </geometry>
        </visual>
        <velocity_decay>
          <linear>0</linear>
          <angular>0</angular>
        </velocity_decay>
        <pose>0 0 0 0 -0 0</pose>
        <self_collide>0</self_collide>
        <inertial>
          <inertia>
            <ixx>1</ixx>
            <ixy>0</ixy>
            <ixz>0</ixz>
            <iyy>1</iyy>
            <iyz>0</iyz>
            <izz>1</izz>
          </inertia>
          <mass>1</mass>
        </inertial>
        <kinematic>0</kinematic>
        <gravity>1</gravity>
      </link>
      <joint name='wall-joint' type='revolute'>
        <parent>world</parent>
        <child>wall::link</child>
        <axis>
          <xyz>0 0 1</xyz>
          <limit>
            <lower>0</lower>
            <upper>0</upper>
          </limit>
        </axis>
      </joint>
      <link name='valve_0::handle'>
        <pose>0.919587 0.0208 0.285 0 -0 0</pose>
        <inertial>
          <mass>7.8219</mass>
          <pose>0 -0.0615 0 0 -0 0</pose>
          <inertia>
            <ixx>0.0695</ixx>
            <ixy>0</ixy>
            <ixz>0</ixz>
            <iyy>0.1349</iyy>
            <iyz>0</iyz>
            <izz>0.0695</izz>
          </inertia>
        </inertial>
        <collision name='collision'>
          <geometry>
            <mesh>
              <uri>model://drc_practice_wheel_valve_large/meshes/wheel_valve_large.dae</uri>
            </mesh>
          </geometry>
          <surface>
            <bounce>
              <restitution_coefficient>0.01</restitution_coefficient>
              <threshold>5</threshold>
            </bounce>
            <friction>
              <ode>
                <mu>5</mu>
                <mu2>5</mu2>
              </ode>
            </friction>
            <contact>
              <ode>
                <soft_cfm>0.01</soft_cfm>
                <kp>1e+06</kp>
                <kd>100000</kd>
                <max_vel>0.01</max_vel>
                <min_depth>0.001</min_depth>
              </ode>
            </contact>
          </surface>
          <max_contacts>10</max_contacts>
        </collision>
        <visual name='visual'>
          <geometry>
            <mesh>
              <uri>model://drc_practice_wheel_valve_large/meshes/wheel_valve_large.dae</uri>
            </mesh>
          </geometry>
        </visual>
        <velocity_decay>
          <linear>0</linear>
          <angular>0</angular>
        </velocity_decay>
        <self_collide>0</self_collide>
        <kinematic>0</kinematic>
        <gravity>1</gravity>
      </link>
      <joint name='valve_0::joint' type='revolute'>
        <parent>world</parent>
        <child>valve_0::handle</child>
        <axis>
          <xyz>0 1 0</xyz>
          <limit>
            <lower>-12.56</lower>
            <upper>12.56</upper>
          </limit>
          <dynamics>
            <damping>1000</damping>
            <friction>100</friction>
          </dynamics>
        </axis>
        <physics>
          <ode>
            <cfm_damping>1</cfm_damping>
            <limit>
              <cfm>0</cfm>
              <erp>0.2</erp>
            </limit>
          </ode>
        </physics>
      </joint>
      <link name='valve_1::handle'>
        <pose>0.919587 0.0208 0.8954 0 -0 0</pose>
        <inertial>
          <mass>7.8219</mass>
          <pose>0 -0.0615 0 0 -0 0</pose>
          <inertia>
            <ixx>0.0695</ixx>
            <ixy>0</ixy>
            <ixz>0</ixz>
            <iyy>0.1349</iyy>
            <iyz>0</iyz>
            <izz>0.0695</izz>
          </inertia>
        </inertial>
        <collision name='collision'>
          <geometry>
            <mesh>
              <uri>model://drc_practice_wheel_valve_large/meshes/wheel_valve_large.dae</uri>
            </mesh>
          </geometry>
          <surface>
            <bounce>
              <restitution_coefficient>0.01</restitution_coefficient>
              <threshold>5</threshold>
            </bounce>
            <friction>
              <ode>
                <mu>5</mu>
                <mu2>5</mu2>
              </ode>
            </friction>
            <contact>
              <ode>
                <soft_cfm>0.01</soft_cfm>
                <kp>1e+06</kp>
                <kd>100000</kd>
                <max_vel>0.01</max_vel>
                <min_depth>0.001</min_depth>
              </ode>
            </contact>
          </surface>
          <max_contacts>10</max_contacts>
        </collision>
        <visual name='visual'>
          <geometry>
            <mesh>
              <uri>model://drc_practice_wheel_valve_large/meshes/wheel_valve_large.dae</uri>
            </mesh>
          </geometry>
        </visual>
        <velocity_decay>
          <linear>0</linear>
          <angular>0</angular>
        </velocity_decay>
        <self_collide>0</self_collide>
        <kinematic>0</kinematic>
        <gravity>1</gravity>
      </link>
      <joint name='valve_1::joint' type='revolute'>
        <parent>world</parent>
        <child>valve_1::handle</child>
        <axis>
          <xyz>0 1 0</xyz>
          <limit>
            <lower>-12.56</lower>
            <upper>12.56</upper>
          </limit>
          <dynamics>
            <damping>1000</damping>
            <friction>100</friction>
          </dynamics>
        </axis>
        <physics>
          <ode>
            <cfm_damping>1</cfm_damping>
            <limit>
              <cfm>0</cfm>
              <erp>0.2</erp>
            </limit>
          </ode>
        </physics>
      </joint>
      <link name='valve_2::handle'>
        <pose>0.919587 0.0208 1.5058 0 -0 0</pose>
        <inertial>
          <mass>7.8219</mass>
          <pose>0 -0.0615 0 0 -0 0</pose>
          <inertia>
            <ixx>0.0695</ixx>
            <ixy>0</ixy>
            <ixz>0</ixz>
            <iyy>0.1349</iyy>
            <iyz>0</iyz>
            <izz>0.0695</izz>
          </inertia>
        </inertial>
        <collision name='collision'>
          <geometry>
            <mesh>
              <uri>model://drc_practice_wheel_valve_large/meshes/wheel_valve_large.dae</uri>
            </mesh>
          </geometry>
          <surface>
            <bounce>
              <restitution_coefficient>0.01</restitution_coefficient>
              <threshold>5</threshold>
            </bounce>
            <friction>
              <ode>
                <mu>5</mu>
                <mu2>5</mu2>
              </ode>
            </friction>
            <contact>
              <ode>
                <soft_cfm>0.01</soft_cfm>
                <kp>1e+06</kp>
                <kd>100000</kd>
                <max_vel>0.01</max_vel>
                <min_depth>0.001</min_depth>
              </ode>
            </contact>
          </surface>
          <max_contacts>10</max_contacts>
        </collision>
        <visual name='visual'>
          <geometry>
            <mesh>
              <uri>model://drc_practice_wheel_valve_large/meshes/wheel_valve_large.dae</uri>
            </mesh>
          </geometry>
        </visual>
        <velocity_decay>
          <linear>0</linear>
          <angular>0</angular>
        </velocity_decay>
        <self_collide>0</self_collide>
        <kinematic>0</kinematic>
        <gravity>1</gravity>
      </link>
      <joint name='valve_2::joint' type='revolute'>
        <parent>world</parent>
        <child>valve_2::handle</child>
        <axis>
          <xyz>0 1 0</xyz>
          <limit>
            <lower>-12.56</lower>
            <upper>12.56</upper>
          </limit>
          <dynamics>
            <damping>1000</damping>
            <friction>100</friction>
          </dynamics>
        </axis>
        <physics>
          <ode>
            <cfm_damping>1</cfm_damping>
            <limit>
              <cfm>0</cfm>
              <erp>0.2</erp>
            </limit>
          </ode>
        </physics>
      </joint>
      <link name='valve_3::handle'>
        <pose>0.919587 0.0208 2.1162 0 -0 0</pose>
        <inertial>
          <mass>7.8219</mass>
          <pose>0 -0.0615 0 0 -0 0</pose>
          <inertia>
            <ixx>0.0695</ixx>
            <ixy>0</ixy>
            <ixz>0</ixz>
            <iyy>0.1349</iyy>
            <iyz>0</iyz>
            <izz>0.0695</izz>
          </inertia>
        </inertial>
        <collision name='collision'>
          <geometry>
            <mesh>
              <uri>model://drc_practice_wheel_valve_large/meshes/wheel_valve_large.dae</uri>
            </mesh>
          </geometry>
          <surface>
            <bounce>
              <restitution_coefficient>0.01</restitution_coefficient>
              <threshold>5</threshold>
            </bounce>
            <friction>
              <ode>
                <mu>5</mu>
                <mu2>5</mu2>
              </ode>
            </friction>
            <contact>
              <ode>
                <soft_cfm>0.01</soft_cfm>
                <kp>1e+06</kp>
                <kd>100000</kd>
                <max_vel>0.01</max_vel>
                <min_depth>0.001</min_depth>
              </ode>
            </contact>
          </surface>
          <max_contacts>10</max_contacts>
        </collision>
        <visual name='visual'>
          <geometry>
            <mesh>
              <uri>model://drc_practice_wheel_valve_large/meshes/wheel_valve_large.dae</uri>
            </mesh>
          </geometry>
        </visual>
        <velocity_decay>
          <linear>0</linear>
          <angular>0</angular>
        </velocity_decay>
        <self_collide>0</self_collide>
        <kinematic>0</kinematic>
        <gravity>1</gravity>
      </link>
      <joint name='valve_3::joint' type='revolute'>
        <parent>world</parent>
        <child>valve_3::handle</child>
        <axis>
          <xyz>0 1 0</xyz>
          <limit>
            <lower>-12.56</lower>
            <upper>12.56</upper>
          </limit>
          <dynamics>
            <damping>1000</damping>
            <friction>100</friction>
          </dynamics>
        </axis>
        <physics>
          <ode>
            <cfm_damping>1</cfm_damping>
            <limit>
              <cfm>0</cfm>
              <erp>0.2</erp>
            </limit>
          </ode>
        </physics>
      </joint>
      <link name='valve_4::handle'>
        <pose>0.614335 0.0208 0.5896 0 -0 0</pose>
        <inertial>
          <mass>7.8219</mass>
          <pose>0 -0.0615 0 0 -0 0</pose>
          <inertia>
            <ixx>0.0695</ixx>
            <ixy>0</ixy>
            <ixz>0</ixz>
            <iyy>0.1349</iyy>
            <iyz>0</iyz>
            <izz>0.0695</izz>
          </inertia>
        </inertial>
        <collision name='collision'>
          <geometry>
            <mesh>
              <uri>model://drc_practice_wheel_valve_large/meshes/wheel_valve_large.dae</uri>
            </mesh>
          </geometry>
          <surface>
            <bounce>
              <restitution_coefficient>0.01</restitution_coefficient>
              <threshold>5</threshold>
            </bounce>
            <friction>
              <ode>
                <mu>5</mu>
                <mu2>5</mu2>
              </ode>
            </friction>
            <contact>
              <ode>
                <soft_cfm>0.01</soft_cfm>
                <kp>1e+06</kp>
                <kd>100000</kd>
                <max_vel>0.01</max_vel>
                <min_depth>0.001</min_depth>
              </ode>
            </contact>
          </surface>
          <max_contacts>10</max_contacts>
        </collision>
        <visual name='visual'>
          <geometry>
            <mesh>
              <uri>model://drc_practice_wheel_valve_large/meshes/wheel_valve_large.dae</uri>
            </mesh>
          </geometry>
        </visual>
        <velocity_decay>
          <linear>0</linear>
          <angular>0</angular>
        </velocity_decay>
        <self_collide>0</self_collide>
        <kinematic>0</kinematic>
        <gravity>1</gravity>
      </link>
      <joint name='valve_4::joint' type='revolute'>
        <parent>world</parent>
        <child>valve_4::handle</child>
        <axis>
          <xyz>0 1 0</xyz>
          <limit>
            <lower>-12.56</lower>
            <upper>12.56</upper>
          </limit>
          <dynamics>
            <damping>1000</damping>
            <friction>100</friction>
          </dynamics>
        </axis>
        <physics>
          <ode>
            <cfm_damping>1</cfm_damping>
            <limit>
              <cfm>0</cfm>
              <erp>0.2</erp>
            </limit>
          </ode>
        </physics>
      </joint>
      <link name='valve_5::handle'>
        <pose>0.614335 0.0208 1.2 0 -0 0</pose>
        <inertial>
          <mass>7.8219</mass>
          <pose>0 -0.0615 0 0 -0 0</pose>
          <inertia>
            <ixx>0.0695</ixx>
            <ixy>0</ixy>
            <ixz>0</ixz>
            <iyy>0.1349</iyy>
            <iyz>0</iyz>
            <izz>0.0695</izz>
          </inertia>
        </inertial>
        <collision name='collision'>
          <geometry>
            <mesh>
              <uri>model://drc_practice_wheel_valve_large/meshes/wheel_valve_large.dae</uri>
            </mesh>
          </geometry>
          <surface>
            <bounce>
              <restitution_coefficient>0.01</restitution_coefficient>
              <threshold>5</threshold>
            </bounce>
            <friction>
              <ode>
                <mu>5</mu>
                <mu2>5</mu2>
              </ode>
            </friction>
            <contact>
              <ode>
                <soft_cfm>0.01</soft_cfm>
                <kp>1e+06</kp>
                <kd>100000</kd>
                <max_vel>0.01</max_vel>
                <min_depth>0.001</min_depth>
              </ode>
            </contact>
          </surface>
          <max_contacts>10</max_contacts>
        </collision>
        <visual name='visual'>
          <geometry>
            <mesh>
              <uri>model://drc_practice_wheel_valve_large/meshes/wheel_valve_large.dae</uri>
            </mesh>
          </geometry>
        </visual>
        <velocity_decay>
          <linear>0</linear>
          <angular>0</angular>
        </velocity_decay>
        <self_collide>0</self_collide>
        <kinematic>0</kinematic>
        <gravity>1</gravity>
      </link>
      <joint name='valve_5::joint' type='revolute'>
        <parent>world</parent>
        <child>valve_5::handle</child>
        <axis>
          <xyz>0 1 0</xyz>
          <limit>
            <lower>-12.56</lower>
            <upper>12.56</upper>
          </limit>
          <dynamics>
            <damping>1000</damping>
            <friction>100</friction>
          </dynamics>
        </axis>
        <physics>
          <ode>
            <cfm_damping>1</cfm_damping>
            <limit>
              <cfm>0</cfm>
              <erp>0.2</erp>
            </limit>
          </ode>
        </physics>
      </joint>
      <link name='valve_6::handle'>
        <pose>0.614335 0.0208 1.8104 0 -0 0</pose>
        <inertial>
          <mass>7.8219</mass>
          <pose>0 -0.0615 0 0 -0 0</pose>
          <inertia>
            <ixx>0.0695</ixx>
            <ixy>0</ixy>
            <ixz>0</ixz>
            <iyy>0.1349</iyy>
            <iyz>0</iyz>
            <izz>0.0695</izz>
          </inertia>
        </inertial>
        <collision name='collision'>
          <geometry>
            <mesh>
              <uri>model://drc_practice_wheel_valve_large/meshes/wheel_valve_large.dae</uri>
            </mesh>
          </geometry>
          <surface>
            <bounce>
              <restitution_coefficient>0.01</restitution_coefficient>
              <threshold>5</threshold>
            </bounce>
            <friction>
              <ode>
                <mu>5</mu>
                <mu2>5</mu2>
              </ode>
            </friction>
            <contact>
              <ode>
                <soft_cfm>0.01</soft_cfm>
                <kp>1e+06</kp>
                <kd>100000</kd>
                <max_vel>0.01</max_vel>
                <min_depth>0.001</min_depth>
              </ode>
            </contact>
          </surface>
          <max_contacts>10</max_contacts>
        </collision>
        <visual name='visual'>
          <geometry>
            <mesh>
              <uri>model://drc_practice_wheel_valve_large/meshes/wheel_valve_large.dae</uri>
            </mesh>
          </geometry>
        </visual>
        <velocity_decay>
          <linear>0</linear>
          <angular>0</angular>
        </velocity_decay>
        <self_collide>0</self_collide>
        <kinematic>0</kinematic>
        <gravity>1</gravity>
      </link>
      <joint name='valve_6::joint' type='revolute'>
        <parent>world</parent>
        <child>valve_6::handle</child>
        <axis>
          <xyz>0 1 0</xyz>
          <limit>
            <lower>-12.56</lower>
            <upper>12.56</upper>
          </limit>
          <dynamics>
            <damping>1000</damping>
            <friction>100</friction>
          </dynamics>
        </axis>
        <physics>
          <ode>
            <cfm_damping>1</cfm_damping>
            <limit>
              <cfm>0</cfm>
              <erp>0.2</erp>
            </limit>
          </ode>
        </physics>
      </joint>
      <link name='valve_7::handle'>
        <pose>0.309083 0.0208 0.285 0 -0 0</pose>
        <inertial>
          <mass>7.8219</mass>
          <pose>0 -0.0615 0 0 -0 0</pose>
          <inertia>
            <ixx>0.0695</ixx>
            <ixy>0</ixy>
            <ixz>0</ixz>
            <iyy>0.1349</iyy>
            <iyz>0</iyz>
            <izz>0.0695</izz>
          </inertia>
        </inertial>
        <collision name='collision'>
          <geometry>
            <mesh>
              <uri>model://drc_practice_wheel_valve_large/meshes/wheel_valve_large.dae</uri>
            </mesh>
          </geometry>
          <surface>
            <bounce>
              <restitution_coefficient>0.01</restitution_coefficient>
              <threshold>5</threshold>
            </bounce>
            <friction>
              <ode>
                <mu>5</mu>
                <mu2>5</mu2>
              </ode>
            </friction>
            <contact>
              <ode>
                <soft_cfm>0.01</soft_cfm>
                <kp>1e+06</kp>
                <kd>100000</kd>
                <max_vel>0.01</max_vel>
                <min_depth>0.001</min_depth>
              </ode>
            </contact>
          </surface>
          <max_contacts>10</max_contacts>
        </collision>
        <visual name='visual'>
          <geometry>
            <mesh>
              <uri>model://drc_practice_wheel_valve_large/meshes/wheel_valve_large.dae</uri>
            </mesh>
          </geometry>
        </visual>
        <velocity_decay>
          <linear>0</linear>
          <angular>0</angular>
        </velocity_decay>
        <self_collide>0</self_collide>
        <kinematic>0</kinematic>
        <gravity>1</gravity>
      </link>
      <joint name='valve_7::joint' type='revolute'>
        <parent>world</parent>
        <child>valve_7::handle</child>
        <axis>
          <xyz>0 1 0</xyz>
          <limit>
            <lower>-12.56</lower>
            <upper>12.56</upper>
          </limit>
          <dynamics>
            <damping>1000</damping>
            <friction>100</friction>
          </dynamics>
        </axis>
        <physics>
          <ode>
            <cfm_damping>1</cfm_damping>
            <limit>
              <cfm>0</cfm>
              <erp>0.2</erp>
            </limit>
          </ode>
        </physics>
      </joint>
      <link name='valve_8::handle'>
        <pose>0.309083 0.0208 0.8954 0 -0 0</pose>
        <inertial>
          <mass>7.8219</mass>
          <pose>0 -0.0615 0 0 -0 0</pose>
          <inertia>
            <ixx>0.0695</ixx>
            <ixy>0</ixy>
            <ixz>0</ixz>
            <iyy>0.1349</iyy>
            <iyz>0</iyz>
            <izz>0.0695</izz>
          </inertia>
        </inertial>
        <collision name='collision'>
          <geometry>
            <mesh>
              <uri>model://drc_practice_wheel_valve_large/meshes/wheel_valve_large.dae</uri>
            </mesh>
          </geometry>
          <surface>
            <bounce>
              <restitution_coefficient>0.01</restitution_coefficient>
              <threshold>5</threshold>
            </bounce>
            <friction>
              <ode>
                <mu>5</mu>
                <mu2>5</mu2>
              </ode>
            </friction>
            <contact>
              <ode>
                <soft_cfm>0.01</soft_cfm>
                <kp>1e+06</kp>
                <kd>100000</kd>
                <max_vel>0.01</max_vel>
                <min_depth>0.001</min_depth>
              </ode>
            </contact>
          </surface>
          <max_contacts>10</max_contacts>
        </collision>
        <visual name='visual'>
          <geometry>
            <mesh>
              <uri>model://drc_practice_wheel_valve_large/meshes/wheel_valve_large.dae</uri>
            </mesh>
          </geometry>
        </visual>
        <velocity_decay>
          <linear>0</linear>
          <angular>0</angular>
        </velocity_decay>
        <self_collide>0</self_collide>
        <kinematic>0</kinematic>
        <gravity>1</gravity>
      </link>
      <joint name='valve_8::joint' type='revolute'>
        <parent>world</parent>
        <child>valve_8::handle</child>
        <axis>
          <xyz>0 1 0</xyz>
          <limit>
            <lower>-12.56</lower>
            <upper>12.56</upper>
          </limit>
          <dynamics>
            <damping>1000</damping>
            <friction>100</friction>
          </dynamics>
        </axis>
        <physics>
          <ode>
            <cfm_damping>1</cfm_damping>
            <limit>
              <cfm>0</cfm>
              <erp>0.2</erp>
            </limit>
          </ode>
        </physics>
      </joint>
      <link name='valve_9::handle'>
        <pose>0.309083 0.0208 1.5058 0 -0 0</pose>
        <inertial>
          <mass>7.8219</mass>
          <pose>0 -0.0615 0 0 -0 0</pose>
          <inertia>
            <ixx>0.0695</ixx>
            <ixy>0</ixy>
            <ixz>0</ixz>
            <iyy>0.1349</iyy>
            <iyz>0</iyz>
            <izz>0.0695</izz>
          </inertia>
        </inertial>
        <collision name='collision'>
          <geometry>
            <mesh>
              <uri>model://drc_practice_wheel_valve_large/meshes/wheel_valve_large.dae</uri>
            </mesh>
          </geometry>
          <surface>
            <bounce>
              <restitution_coefficient>0.01</restitution_coefficient>
              <threshold>5</threshold>
            </bounce>
            <friction>
              <ode>
                <mu>5</mu>
                <mu2>5</mu2>
              </ode>
            </friction>
            <contact>
              <ode>
                <soft_cfm>0.01</soft_cfm>
                <kp>1e+06</kp>
                <kd>100000</kd>
                <max_vel>0.01</max_vel>
                <min_depth>0.001</min_depth>
              </ode>
            </contact>
          </surface>
          <max_contacts>10</max_contacts>
        </collision>
        <visual name='visual'>
          <geometry>
            <mesh>
              <uri>model://drc_practice_wheel_valve_large/meshes/wheel_valve_large.dae</uri>
            </mesh>
          </geometry>
        </visual>
        <velocity_decay>
          <linear>0</linear>
          <angular>0</angular>
        </velocity_decay>
        <self_collide>0</self_collide>
        <kinematic>0</kinematic>
        <gravity>1</gravity>
      </link>
      <joint name='valve_9::joint' type='revolute'>
        <parent>world</parent>
        <child>valve_9::handle</child>
        <axis>
          <xyz>0 1 0</xyz>
          <limit>
            <lower>-12.56</lower>
            <upper>12.56</upper>
          </limit>
          <dynamics>
            <damping>1000</damping>
            <friction>100</friction>
          </dynamics>
        </axis>
        <physics>
          <ode>
            <cfm_damping>1</cfm_damping>
            <limit>
              <cfm>0</cfm>
              <erp>0.2</erp>
            </limit>
          </ode>
        </physics>
      </joint>
      <link name='valve_10::handle'>
        <pose>0.309083 0.0208 2.1162 0 -0 0</pose>
        <inertial>
          <mass>7.8219</mass>
          <pose>0 -0.0615 0 0 -0 0</pose>
          <inertia>
            <ixx>0.0695</ixx>
            <ixy>0</ixy>
            <ixz>0</ixz>
            <iyy>0.1349</iyy>
            <iyz>0</iyz>
            <izz>0.0695</izz>
          </inertia>
        </inertial>
        <collision name='collision'>
          <geometry>
            <mesh>
              <uri>model://drc_practice_wheel_valve_large/meshes/wheel_valve_large.dae</uri>
            </mesh>
          </geometry>
          <surface>
            <bounce>
              <restitution_coefficient>0.01</restitution_coefficient>
              <threshold>5</threshold>
            </bounce>
            <friction>
              <ode>
                <mu>5</mu>
                <mu2>5</mu2>
              </ode>
            </friction>
            <contact>
              <ode>
                <soft_cfm>0.01</soft_cfm>
                <kp>1e+06</kp>
                <kd>100000</kd>
                <max_vel>0.01</max_vel>
                <min_depth>0.001</min_depth>
              </ode>
            </contact>
          </surface>
          <max_contacts>10</max_contacts>
        </collision>
        <visual name='visual'>
          <geometry>
            <mesh>
              <uri>model://drc_practice_wheel_valve_large/meshes/wheel_valve_large.dae</uri>
            </mesh>
          </geometry>
        </visual>
        <velocity_decay>
          <linear>0</linear>
          <angular>0</angular>
        </velocity_decay>
        <self_collide>0</self_collide>
        <kinematic>0</kinematic>
        <gravity>1</gravity>
      </link>
      <joint name='valve_10::joint' type='revolute'>
        <parent>world</parent>
        <child>valve_10::handle</child>
        <axis>
          <xyz>0 1 0</xyz>
          <limit>
            <lower>-12.56</lower>
            <upper>12.56</upper>
          </limit>
          <dynamics>
            <damping>1000</damping>
            <friction>100</friction>
          </dynamics>
        </axis>
        <physics>
          <ode>
            <cfm_damping>1</cfm_damping>
            <limit>
              <cfm>0</cfm>
              <erp>0.2</erp>
            </limit>
          </ode>
        </physics>
      </joint>
      <pose>1.59014 0 0 0 -0 0</pose>
    </model>
    <model name='drc_practice_white_jersey_barrier'>
      <static>1</static>
      <link name='link'>
        <visual name='visual'>
          <geometry>
            <mesh>
              <uri>model://drc_practice_white_jersey_barrier/meshes/jersey_barrier.dae</uri>
            </mesh>
          </geometry>
        </visual>
        <collision name='collision'>
          <geometry>
            <mesh>
              <uri>model://drc_practice_white_jersey_barrier/meshes/jersey_barrier.dae</uri>
            </mesh>
          </geometry>
          <max_contacts>10</max_contacts>
          <surface>
            <bounce/>
            <friction>
              <ode/>
            </friction>
            <contact>
              <ode/>
            </contact>
          </surface>
        </collision>
        <velocity_decay>
          <linear>0</linear>
          <angular>0</angular>
        </velocity_decay>
        <self_collide>0</self_collide>
        <kinematic>0</kinematic>
        <gravity>1</gravity>
      </link>
      <pose>-6 1 0 0 -0 0</pose>
    </model>
    <model name='unit_box_1'>
      <pose>-7 8.45126 0.5 0 -0 0</pose>
      <link name='link'>
        <inertial>
          <mass>1</mass>
          <inertia>
            <ixx>1</ixx>
            <ixy>0</ixy>
            <ixz>0</ixz>
            <iyy>1</iyy>
            <iyz>0</iyz>
            <izz>1</izz>
          </inertia>
        </inertial>
        <collision name='collision'>
          <geometry>
            <box>
              <size>1 1 1</size>
            </box>
          </geometry>
          <max_contacts>10</max_contacts>
          <surface>
            <bounce/>
            <friction>
              <ode/>
            </friction>
            <contact>
              <ode/>
            </contact>
          </surface>
        </collision>
        <visual name='visual'>
          <geometry>
            <box>
              <size>1 1 1</size>
            </box>
          </geometry>
          <material>
            <script>
              <uri>file://media/materials/scripts/gazebo.material</uri>
              <name>Gazebo/Grey</name>
            </script>
          </material>
        </visual>
        <velocity_decay>
          <linear>0</linear>
          <angular>0</angular>
        </velocity_decay>
        <self_collide>0</self_collide>
        <kinematic>0</kinematic>
        <gravity>1</gravity>
      </link>
      <static>0</static>
    </model>
    <model name='unit_box_2'>
      <pose>4 5 0.5 0 -0 0</pose>
      <link name='link'>
        <inertial>
          <mass>1</mass>
          <inertia>
            <ixx>1</ixx>
            <ixy>0</ixy>
            <ixz>0</ixz>
            <iyy>1</iyy>
            <iyz>0</iyz>
            <izz>1</izz>
          </inertia>
        </inertial>
        <collision name='collision'>
          <geometry>
            <box>
              <size>1 1 1</size>
            </box>
          </geometry>
          <max_contacts>10</max_contacts>
          <surface>
            <bounce/>
            <friction>
              <ode/>
            </friction>
            <contact>
              <ode/>
            </contact>
          </surface>
        </collision>
        <visual name='visual'>
          <geometry>
            <box>
              <size>1 1 1</size>
            </box>
          </geometry>
          <material>
            <script>
              <uri>file://media/materials/scripts/gazebo.material</uri>
              <name>Gazebo/Grey</name>
            </script>
          </material>
        </visual>
        <velocity_decay>
          <linear>0</linear>
          <angular>0</angular>
        </velocity_decay>
        <self_collide>0</self_collide>
        <kinematic>0</kinematic>
        <gravity>1</gravity>
      </link>
      <static>0</static>
    </model>
    <gui fullscreen='0'>
      <camera name='user_camera'>
        <pose>-0.94658 -11.6367 44.3703 0 1.3058 1.56743</pose>
        <view_controller>orbit</view_controller>
      </camera>
    </gui>
  </world>
</sdf>
